Workbook

Sheet 0_안내
A1: 수출입 실적 통합 분석 (2024.01 ~ 2026.07, 31개월) — 월별 분해판
A2: 업로드하신 5개 원본 파일을 한 파일로 모으고, 원본은 수정하지 않은 채 분석 시트를 추가했습니다. 모든 증감 분석은 1~7월 누계가 아니라 각 달을 전년 동월과 비교하는 방식입니다.
A4: 시트 구성
A5: 시트 | B5: 내용 | C5: 비고
A6: 수출입 총괄 외 4개 | B6: 원본 5개 시트 (총괄·품목별·성질별 수출·성질별 수입·신성질별) | C6: 원본 · 수정 없음
A7: 데이터_○○ 5개 | B7: 텍스트 숫자를 VALUE 수식으로 숫자화 + 연도·월·분기 파생 | C7: 전부 수식 · 직접 입력 금지
A8: 분석1_정합성검증 | B8: 총계 vs 합계, 시트 간 교차, 월별 항등식 검증
A9: 분석2_월별추이 | B9: 31개월 추이 · MoM · YoY · 일평균 · 단가 · 12개월 이동합
A10: 분석3_MoM·QoQ·YoY | B10: 월별 MoM/YoY, 분기별 QoQ/YoY, 연도별 비교
A11: 분석4_연도별계절비교 | B11: 1~12월 × 2024/2025/2026 매트릭스 17종 | C11: 오버레이 그래프 원본
A12: 분석4B_월별매트릭스 | B12: HS 97류·부문·성질별 전 항목의 31개월 월별 값 | C12: ★ 월별 분석의 원천
A13: 분석5_반도체vs비반도체 | B13: 월별 금액·YoY·기여도·우위 판정 (정의 3종) | C13: ★ 월별 분해
A14: 분석6_HS부문별 | B14: 21개 부문의 월별 YoY·월별 증감액 + 구성 류 | C14: ★ 월별 분해
A15: 분석7_HS류별상세 | B15: 97개 류의 월별 YoY 7열·월별 증감액 7열 + 자동 해석 | C15: ★ 월별 분해
A16: 분석8_성질별심층 | B16: 성질별 수출·수입, 신성질별의 월별 YoY | C16: ★ 월별 분해
A17: 분석9_물량·가격분해 | B17: 19개 달을 각각 3효과로 분해 + 피셔 지수 | C17: ★ 월별 분해
A18: 분석10_그래프_연도오버레이 | B18: 1~12월 축에 3개 연도를 겹친 그래프 17종
A19: 분석11_그래프_구조분석 | B19: 월별 증감액 분해·반도체·부문·분기 그래프 10종
A20: 분석12_해설 | B20: 월별로 본 해석 · 사용법 · 한계 | C20: 먼저 읽으시면 좋습니다
A21: 분석13_월별변화요약 | B21: 한 행이 한 달 — 그 달의 증감 주도 품목 상위 3개와 몫 | C21: ★ 신규
A23: 이번 판에서 달라진 점
A24: ① 모든 증감 분석을 1~7월 누계에서 월별 비교로 전환 (분석5·6·7·8·9)
A25: ② 분석4B_월별매트릭스 신설 — HS 97류·21개 부문·성질별 전 항목의 31개월 값을 한 곳에 계산
A26: ③ 분석13_월별변화요약 신설 — 한 행이 한 달, 그 달의 증가·감소 상위 3개 품목과 반도체/비반도체 몫
A27: ④ 분석7에 2026년 7개월의 월별 YoY·월별 증감액 열 추가, 해석 문장에 "몇 개월 증가·최대/최소는 몇 월" 자동 반영
A28: ⑤ 분석9를 19개 달 각각의 3효과 분해로 전환, 분석11에 월별 증감액 분해 그래프 추가
A29: ⑥ 누계 수치는 삭제하지 않고 각 시트 뒤쪽에 참고용으로 유지
A31: ※ 모든 분석 셀은 원본을 참조하는 수식입니다. 원본에 다음 달 데이터를 추가하고 정제 시트·분석4B의 범위를 늘리면 분석 전체가 갱신됩니다.

Sheet 수출입 총괄
A1: 수출입 총괄
A3: 검색조건 조회기간: 202401 ~ 202607 , 통계기준: 수리일, 중량단위: 톤
I4: 단위:건, 톤(TON), 천 달러
A5: 기간 | B5: 조업일수 | C5: 수출 건수 | D5: 수출 중량 | E5: 수출 금액 | F5: 수입 건수 | G5: 수입중량 | H5: 수입금액 | I5: 무역수지
A6: 총계 | B6: 695.5 | C6: 34,342,880 | D6: 505,655,916.9 | E6: 1,988,002,368 | F6: 141,143,449 | G6: 1,414,626,020.9 | H6: 1,690,965,721 | I6: 297,036,647
A7: 2024.01 | B7: 24.0 | C7: 1,035,551 | D7: 17,105,790.7 | E7: 54,709,823 | F7: 4,276,442 | G7: 51,377,769.3 | H7: 54,474,611 | I7: 235,213
A8: 2024.02 | B8: 20.5 | C8: 906,528 | D8: 15,678,985.8 | E8: 52,076,390 | F8: 3,659,530 | G8: 45,689,883.8 | H8: 48,221,860 | I8: 3,854,529
A9: 2024.03 | B9: 22.5 | C9: 1,018,882 | D9: 16,805,631.5 | E9: 56,518,309 | F9: 4,614,926 | G9: 44,316,660.0 | H9: 52,112,905 | I9: 4,405,404
A10: 2024.04 | B10: 23.0 | C10: 1,012,749 | D10: 16,491,489.3 | E10: 56,148,299 | F10: 4,396,142 | G10: 47,615,984.8 | H10: 54,821,181 | I10: 1,327,118
A11: 2024.05 | B11: 22.0 | C11: 1,038,452 | D11: 16,793,798.4 | E11: 58,020,557 | F11: 4,430,186 | G11: 45,880,287.0 | H11: 53,132,937 | I11: 4,887,620
A12: 2024.06 | B12: 21.5 | C12: 1,015,654 | D12: 14,641,434.6 | E12: 57,341,634 | F12: 4,008,321 | G12: 42,701,364.6 | H12: 49,090,193 | I12: 8,251,441
A13: 2024.07 | B13: 25.0 | C13: 1,111,979 | D13: 16,697,113.3 | E13: 57,458,788 | F13: 4,361,845 | G13: 45,267,798.7 | H13: 53,838,742 | I13: 3,620,046
A14: 2024.08 | B14: 23.5 | C14: 971,248 | D14: 17,070,040.9 | E14: 57,642,924 | F14: 4,219,404 | G14: 49,665,340.4 | H14: 54,054,894 | I14: 3,588,030
A15: 2024.09 | B15: 20.0 | C15: 1,151,289 | D15: 16,449,775.4 | E15: 58,544,693 | F15: 4,244,016 | G15: 44,145,421.6 | H15: 52,102,925 | I15: 6,441,768
A16: 2024.10 | B16: 22.0 | C16: 1,020,830 | D16: 15,994,863.5 | E16: 57,500,192 | F16: 4,672,638 | G16: 47,452,574.1 | H16: 54,331,589 | I16: 3,168,604
... A37: 2026.07 | B37: 24.0 | C37: 1,111,934 | D37: 17,660,680.7 | E37: 98,959,099 | F37: 5,158,848 | G37: 51,144,176.2 | H37: 68,567,473 | I37: 30,391,625

Sheet 수출입 실적(품목별)
A1: 수출입 실적(품목별)
A3: 검색조건 통계항목 : 품목별, 품목명 : 전체, 하위품목 유무 : 무, 조회기간 : 202401 ~ 202607 , 통계기준 : 수리일, 중량단위 : 톤
H4: 단위:톤(TON), 천 달러
A5: 기간 | B5: HS코드 | C5: 품목명 | D5: 수출 중량 | E5: 수출 금액 | F5: 수입 중량 | G5: 수입 금액 | H5: 무역수지
A6: 총계 | D6: 504,808,074.9 | E6: 1,987,154,630 | F6: 1,413,063,376.6 | G6: 1,690,339,715 | H6: 296,814,915
A7: 2024.01 | B7: 01 | C7: 살아 있는 동물 | D7: 1.9 | E7: 697 | F7: 78.1 | G7: 5,631 | H7: -4,934
A8: 2024.01 | B8: 02 | C8: 육과 식용 설육(屑肉) | D8: 3,806.5 | E8: 5,389 | F8: 154,357.2 | G8: 823,919 | H8: -818,530
A9: 2024.01 | B9: 03 | C9: 어류ㆍ갑각류ㆍ연체동물과 그 밖의 수생(水生) 무척추동물 | D9: 45,908.2 | E9: 128,716 | F9: 119,002.6 | G9: 424,949 | H9: -296,232
A10: 2024.01 | B10: 04 | C10: 낙농품, 새의 알, 천연꿀, 다른 류로 분류되지 않은 식용인 동물성 생산품 | D10: 2,995.9 | E10: 7,500 | F10: 23,072.3 | G10: 93,645 | H10: -86,145
A11: 2024.01 | B11: 05 | C11: 다른 류로 분류되지 않은 동물성 생산품 | D11: 1,211.7 | E11: 3,306 | F11: 5,691.0 | G11: 28,749 | H11: -25,443
A12: 2024.01 | B12: 06 | C12: 살아 있는 수목과 그 밖의 식물, 인경(鱗莖)ㆍ뿌리와 이와 유사한 물품, 절화(切花)와 장식용 잎 | D12: 67.8 | E12: 856 | F12: 8,667.7 | G12: 15,350 | H12: -14,494
A13: 2024.01 | B13: 07 | C13: 식용의 채소ㆍ뿌리ㆍ괴경(塊莖) | D13: 5,191.9 | E13: 10,899 | F13: 103,820.8 | G13: 86,850 | H13: -75,951
A14: 2024.01 | B14: 08 | C14: 식용의 과실과 견과류, 감귤류ㆍ멜론의 껍질 | D14: 2,972.4 | E14: 26,827 | F14: 67,690.2 | G14: 159,724 | H14: -132,897
A15: 2024.01 | B15: 09 | C15: 커피ㆍ차ㆍ마테(maté)ㆍ향신료 | D15: 385.0 | E15: 3,239 | F15: 21,378.1 | G15: 103,751 | H15: -100,511
A16: 2024.01 | B16: 10 | C16: 곡물 | D16: 358.6 | E16: 918 | F16: 1,451,151.7 | G16: 450,755 | H16: -449,837
A17: 2024.01 | B17: 11 | C17: 제분공업의 생산품과 맥아, 전분, 이눌린(inulin), 밀의 글루텐(gluten) | D17: 5,794.3 | E17: 4,158 | F17: 31,887.3 | G17: 28,615 | H17: -24,457
A18: 2024.01 | B18: 12 | C18: 채유(採油)에 적합한 종자와 과실, 각종 종자와 과실, 공업용ㆍ의약용 식물, 짚과 사료용 식물 | D18: 2,659.8 | E18: 46,869 | F18: 265,704.5 | G18: 164,119 | H18: -117,250
... A2988: 2026.07 | B2988: 97 | C2988: 예술품ㆍ수집품ㆍ골동품 | D2988: 17.6 | E2988: 15,110 | F2988: 37.5 | G2988: 20,791 | H2988: -5,681

Sheet 수출입 실적(성질별_수출)
A1: 수출입 실적(성질별)
A3: 검색조건 통계항목 : 성질별, 성질명 : 수출, 전체, 세부성질 유무 : 무, 조회기간 : 202401 ~ 202607 , 통계기준 : 수리일, 중량단위 : 톤
E4: 단위:톤(TON), 천 달러
A5: 기간 | B5: 수출입구분 | C5: 성질명 | D5: 중량 | E5: 금액
A6: 총계 | D6: 505,655,916.9 | E6: 1,988,002,368
A7: 2024.01 | B7: 수출 | C7: 1. 식료 및 직접소비재 | D7: 300,432.1 | E7: 861,851
A8: 2024.01 | B8: 수출 | C8: 2. 원료 및 연료 | D8: 6,905,534.8 | E8: 5,596,612
A9: 2024.01 | B9: 수출 | C9: 3. 경공업품 | D9: 831,132.2 | E9: 2,738,143
A10: 2024.01 | B10: 수출 | C10: 가. 섬유원료 | D10: 63,223.8 | E10: 94,714
A11: 2024.01 | B11: 수출 | C11: 나. 섬유사 | D11: 21,325.1 | E11: 72,562
A12: 2024.01 | B12: 수출 | C12: 다. 직 물 | D12: 30,569.4 | E12: 292,221
A13: 2024.01 | B13: 수출 | C13: 라. 기타 섬유제품 | D13: 21,795.8 | E13: 183,169
A14: 2024.01 | B14: 수출 | C14: 마. 의 류 | D14: 5,866.4 | E14: 166,152
A15: 2024.01 | B15: 수출 | C15: 바. 목제품 | D15: 17,007.4 | E15: 94,566
A16: 2024.01 | B16: 수출 | C16: 사. 가죽, 고무 및 신발류 | D16: 76,231.1 | E16: 432,552
A17: 2024.01 | B17: 수출 | C17: 아. 귀금속 및 보석류 | D17: 323.0 | E17: 196,258
A18: 2024.01 | B18: 수출 | C18: 자. 기타 비금속 광물제품 | D18: 225,540.0 | E18: 220,807
... A657: 2026.07 | B657: 수출 | C657: 바. 기 타 | D657: 89,360.5 | E657: 2,725,433

Sheet 수출입 실적(성질별_수입)
A1: 수출입 실적(성질별)
A3: 검색조건 통계항목 : 성질별, 성질명 : 수입, 전체, 세부성질 유무 : 무, 조회기간 : 202401 ~ 202607 , 통계기준 : 수리일, 중량단위 : 톤
E4: 단위:톤(TON), 천 달러
A5: 기간 | B5: 수출입구분 | C5: 성질명 | D5: 중량 | E5: 금액
A6: 총계 | D6: 1,414,626,020.9 | E6: 1,690,965,721
A7: 2024.01 | B7: 수입 | C7: 1. 소비재 | D7: 3,564,536.2 | E7: 8,746,306
A8: 2024.01 | B8: 수입 | C8: 가. 곡물 | D8: 2,354,636.0 | E8: 832,333
A9: 2024.01 | B9: 수입 | C9: 나. 직접소비재 | D9: 808,352.3 | E9: 2,556,100
A10: 2024.01 | B10: 수입 | C10: 다. 내구소비재 | D10: 268,971.7 | E10: 3,142,554
A11: 2024.01 | B11: 수입 | C11: 라. 비내구 소비재 | D11: 132,080.3 | E11: 2,215,318
A12: 2024.01 | B12: 수입 | C12: 마. 간이세율 적용분 | D12: 495.8 | E12: 0
A13: 2024.01 | B13: 수입 | C13: 2. 원자재 | D13: 47,322,977.6 | E13: 28,106,321
A14: 2024.01 | B14: 수입 | C14: 가. 연 료 | D14: 32,841,379.5 | E14: 15,672,843
A15: 2024.01 | B15: 수입 | C15: 나. 광 물 | D15: 8,377,454.4 | E15: 2,296,169
A16: 2024.01 | B16: 수입 | C16: 다. 경공업 원료 | D16: 1,365,869.8 | E16: 593,012
A17: 2024.01 | B17: 수입 | C17: 라. 유 지 | D17: 99,230.2 | E17: 123,085
A18: 2024.01 | B18: 수입 | C18: 마. 섬유류 | D18: 105,176.4 | E18: 317,721
... A631: 2026.07 | B631: 수입 | C631: 라. 기 타 | D631: 16,454.0 | E631: 246,617

Sheet 수출입 실적(신성질별)
A1: 수출입 실적(신성질별)
A3: 검색조건 통계항목 : 신성질별, 신성질명 : 전체, 세부성질 유무 : 무, 조회기간 : 202401 ~ 202607 , 통계기준 : 수리일, 중량단위 : 톤
F4: 단위:톤(TON), 천 달러
A5: 기간 | B5: 신성질명 | C5: 수출 중량 | D5: 수출 금액 | E5: 수입 중량 | F5: 수입 금액
A6: 총계 | C6: 505,655,916.9 | D6: 1,988,002,368 | E6: 1,414,626,020.9 | F6: 1,690,965,721
A7: 2024.01 | B7: 1.소비재 | C7: 890,383.0 | D7: 8,679,299 | E7: 2,368,995.8 | F7: 7,508,719
A8: 2024.01 | B8: 가.직접소비재 | C8: 245,293.6 | D8: 810,359 | E8: 1,996,413.8 | F8: 3,062,773
A9: 2024.01 | B9: 나.내구소비재 | C9: 490,546.6 | D9: 6,352,080 | E9: 201,838.0 | F9: 1,929,589
A10: 2024.01 | B10: 다.비내구소비재 | C10: 151,038.0 | D10: 1,512,572 | E10: 170,248.2 | F10: 2,516,357
A11: 2024.01 | B11: 라.간이세율적용분 | C11: 3,504.9 | D11: 4,289 | E11: 495.8 | F11: 0
A12: 2024.01 | B12: 2.원자재 | C12: 14,038,084.2 | D12: 17,436,372 | E12: 48,283,050.0 | F12: 27,933,007
A13: 2024.01 | B13: 가.동식물성 연·원료 | C13: 348,452.9 | D13: 435,996 | E13: 2,872,182.6 | F13: 1,428,481
A14: 2024.01 | B14: 나.섬유류 | C14: 130,863.0 | D14: 613,936 | E14: 106,123.8 | F14: 342,160
A15: 2024.01 | B15: 다.광산물 | C15: 6,716,263.2 | D15: 5,478,639 | E15: 41,389,665.4 | F15: 18,384,560
A16: 2024.01 | B16: 라.철강 및 금속제품 | C16: 2,568,224.3 | D16: 3,358,972 | E16: 1,949,849.1 | F16: 2,827,181
A17: 2024.01 | B17: 마.화학공업제품 | C17: 4,270,890.6 | D17: 7,536,310 | E17: 1,961,851.4 | F17: 4,943,661
A18: 2024.01 | B18: 바.기타 원자재 | C18: 3,390.1 | D18: 12,520 | E18: 3,377.7 | F18: 6,963
... A533: 2026.07 | B533: 라.IT부품 | C533: 33,481.3 | D533: 42,761,535 | E533: 33,712.5 | F533: 11,667,986

Sheet 데이터_총괄
A1: 이 시트의 모든 셀은 원본 시트를 참조하는 수식입니다. 원본은 숫자가 텍스트(쉼표 포함)로 저장되어 있어 VALUE/SUBSTITUTE로 숫자화했고, 연도·월·분기 열을 파생시켜 MoM/QoQ/YoY 집계가 가능하도록 했습니다. 직접 입력하지 마세요.
A2: 기간 | B2: 연도 | C2: 월 | D2: 분기 | E2: 조업일수 | F2: 수출 건수 | G2: 수출 중량 | H2: 수출 금액 | I2: 수입 건수 | J2: 수입 중량 | K2: 수입 금액 | L2: 무역수지
A3: =TRIM('수출입 총괄'!A7) -> 2024.01 | B3: =IFERROR(VALUE(LEFT($A3,4)),"") -> 2024 | C3: =IFERROR(VALUE(RIGHT($A3,2)),"") -> 1 | D3: =IFERROR(ROUNDUP($C3/3,0),"") -> 1 | E3: =IFERROR(VALUE(SUBSTITUTE(TRIM('수출입 총괄'!B7),",","")),"") -> 24 | F3: =IFERROR(VALUE(SUBSTITUTE(TRIM('수출입 총괄'!C7),",","")),"") -> 1035551 | G3: =IFERROR(VALUE(SUBSTITUTE(TRIM('수출입 총괄'!D7),",","")),"") -> 17105791 | H3: =IFERROR(VALUE(SUBSTITUTE(TRIM('수출입 총괄'!E7),",","")),"") -> 54709823 | I3: =IFERROR(VALUE(SUBSTITUTE(TRIM('수출입 총괄'!F7),",","")),"") -> 4276442 | J3: =IFERROR(VALUE(SUBSTITUTE(TRIM('수출입 총괄'!G7),",","")),"") -> 51377769 | K3: =IFERROR(VALUE(SUBSTITUTE(TRIM('수출입 총괄'!H7),",","")),"") -> 54474611 | L3: =IFERROR(VALUE(SUBSTITUTE(TRIM('수출입 총괄'!I7),",","")),"") -> 235213
A4: =TRIM('수출입 총괄'!A8) -> 2024.02 | B4: =IFERROR(VALUE(LEFT($A4,4)),"") -> 2024 | C4: =IFERROR(VALUE(RIGHT($A4,2)),"") -> 2 | D4: =IFERROR(ROUNDUP($C4/3,0),"") -> 1 | E4: =IFERROR(VALUE(SUBSTITUTE(TRIM('수출입 총괄'!B8),",","")),"") -> 20.5 | F4: =IFERROR(VALUE(SUBSTITUTE(TRIM('수출입 총괄'!C8),",","")),"") -> 906528 | G4: =IFERROR(VALUE(SUBSTITUTE(TRIM('수출입 총괄'!D8),",","")),"") -> 15678986 | H4: =IFERROR(VALUE(SUBSTITUTE(TRIM('수출입 총괄'!E8),",","")),"") -> 52076390 | I4: =IFERROR(VALUE(SUBSTITUTE(TRIM('수출입 총괄'!F8),",","")),"") -> 3659530 | J4: =IFERROR(VALUE(SUBSTITUTE(TRIM('수출입 총괄'!G8),",","")),"") -> 45689884 | K4: =IFERROR(VALUE(SUBSTITUTE(TRIM('수출입 총괄'!H8),",","")),"") -> 48221860 | L4: =IFERROR(VALUE(SUBSTITUTE(TRIM('수출입 총괄'!I8),",","")),"") -> 3854529
A5: =TRIM('수출입 총괄'!A9) -> 2024.03 | B5: =IFERROR(VALUE(LEFT($A5,4)),"") -> 2024 | C5: =IFERROR(VALUE(RIGHT($A5,2)),"") -> 3 | D5: =IFERROR(ROUNDUP($C5/3,0),"") -> 1 | E5: =IFERROR(VALUE(SUBSTITUTE(TRIM('수출입 총괄'!B9),",","")),"") -> 22.5 | F5: =IFERROR(VALUE(SUBSTITUTE(TRIM('수출입 총괄'!C9),",","")),"") -> 1018882 | G5: =IFERROR(VALUE(SUBSTITUTE(TRIM('수출입 총괄'!D9),",","")),"") -> 16805632 | H5: =IFERROR(VALUE(SUBSTITUTE(TRIM('수출입 총괄'!E9),",","")),"") -> 56518309 | I5: =IFERROR(VALUE(SUBSTITUTE(TRIM('수출입 총괄'!F9),",","")),"") -> 4614926 | J5: =IFERROR(VALUE(SUBSTITUTE(TRIM('수출입 총괄'!G9),",","")),"") -> 44316660 | K5: =IFERROR(VALUE(SUBSTITUTE(TRIM('수출입 총괄'!H9),",","")),"") -> 52112905 | L5: =IFERROR(VALUE(SUBSTITUTE(TRIM('수출입 총괄'!I9),",","")),"") -> 4405404
A6: =TRIM('수출입 총괄'!A10) -> 2024.04 | B6: =IFERROR(VALUE(LEFT($A6,4)),"") -> 2024 | C6: =IFERROR(VALUE(RIGHT($A6,2)),"") -> 4 | D6: =IFERROR(ROUNDUP($C6/3,0),"") -> 2 | E6: =IFERROR(VALUE(SUBSTITUTE(TRIM('수출입 총괄'!B10),",","")),"") -> 23 | F6: =IFERROR(VALUE(SUBSTITUTE(TRIM('수출입 총괄'!C10),",","")),"") -> 1012749 | G6: =IFERROR(VALUE(SUBSTITUTE(TRIM('수출입 총괄'!D10),",","")),"") -> 16491489 | H6: =IFERROR(VALUE(SUBSTITUTE(TRIM('수출입 총괄'!E10),",","")),"") -> 56148299 | I6: =IFERROR(VALUE(SUBSTITUTE(TRIM('수출입 총괄'!F10),",","")),"") -> 4396142 | J6: =IFERROR(VALUE(SUBSTITUTE(TRIM('수출입 총괄'!G10),",","")),"") -> 47615985 | K6: =IFERROR(VALUE(SUBSTITUTE(TRIM('수출입 총괄'!H10),",","")),"") -> 54821181 | L6: =IFERROR(VALUE(SUBSTITUTE(TRIM('수출입 총괄'!I10),",","")),"") -> 1327118
A7: =TRIM('수출입 총괄'!A11) -> 2024.05 | B7: =IFERROR(VALUE(LEFT($A7,4)),"") -> 2024 | C7: =IFERROR(VALUE(RIGHT($A7,2)),"") -> 5 | D7: =IFERROR(ROUNDUP($C7/3,0),"") -> 2 | E7: =IFERROR(VALUE(SUBSTITUTE(TRIM('수출입 총괄'!B11),",","")),"") -> 22 | F7: =IFERROR(VALUE(SUBSTITUTE(TRIM('수출입 총괄'!C11),",","")),"") -> 1038452 | G7: =IFERROR(VALUE(SUBSTITUTE(TRIM('수출입 총괄'!D11),",","")),"") -> 16793798 | H7: =IFERROR(VALUE(SUBSTITUTE(TRIM('수출입 총괄'!E11),",","")),"") -> 58020557 | I7: =IFERROR(VALUE(SUBSTITUTE(TRIM('수출입 총괄'!F11),",","")),"") -> 4430186 | J7: =IFERROR(VALUE(SUBSTITUTE(TRIM('수출입 총괄'!G11),",","")),"") -> 45880287 | K7: =IFERROR(VALUE(SUBSTITUTE(TRIM('수출입 총괄'!H11),",","")),"") -> 53132937 | L7: =IFERROR(VALUE(SUBSTITUTE(TRIM('수출입 총괄'!I11),",","")),"") -> 4887620
A8: =TRIM('수출입 총괄'!A12) -> 2024.06 | B8: =IFERROR(VALUE(LEFT($A8,4)),"") -> 2024 | C8: =IFERROR(VALUE(RIGHT($A8,2)),"") -> 6 | D8: =IFERROR(ROUNDUP($C8/3,0),"") -> 2 | E8: =IFERROR(VALUE(SUBSTITUTE(TRIM('수출입 총괄'!B12),",","")),"") -> 21.5 | F8: =IFERROR(VALUE(SUBSTITUTE(TRIM('수출입 총괄'!C12),",","")),"") -> 1015654 | G8: =IFERROR(VALUE(SUBSTITUTE(TRIM('수출입 총괄'!D12),",","")),"") -> 14641435 | H8: =IFERROR(VALUE(SUBSTITUTE(TRIM('수출입 총괄'!E12),",","")),"") -> 57341634 | I8: =IFERROR(VALUE(SUBSTITUTE(TRIM('수출입 총괄'!F12),",","")),"") -> 4008321 | J8: =IFERROR(VALUE(SUBSTITUTE(TRIM('수출입 총괄'!G12),",","")),"") -> 42701365 | K8: =IFERROR(VALUE(SUBSTITUTE(TRIM('수출입 총괄'!H12),",","")),"") -> 49090193 | L8: =IFERROR(VALUE(SUBSTITUTE(TRIM('수출입 총괄'!I12),",","")),"") -> 8251441
A9: =TRIM('수출입 총괄'!A13) -> 2024.07 | B9: =IFERROR(VALUE(LEFT($A9,4)),"") -> 2024 | C9: =IFERROR(VALUE(RIGHT($A9,2)),"") -> 7 | D9: =IFERROR(ROUNDUP($C9/3,0),"") -> 3 | E9: =IFERROR(VALUE(SUBSTITUTE(TRIM('수출입 총괄'!B13),",","")),"") -> 25 | F9: =IFERROR(VALUE(SUBSTITUTE(TRIM('수출입 총괄'!C13),",","")),"") -> 1111979 | G9: =IFERROR(VALUE(SUBSTITUTE(TRIM('수출입 총괄'!D13),",","")),"") -> 16697113 | H9: =IFERROR(VALUE(SUBSTITUTE(TRIM('수출입 총괄'!E13),",","")),"") -> 57458788 | I9: =IFERROR(VALUE(SUBSTITUTE(TRIM('수출입 총괄'!F13),",","")),"") -> 4361845 | J9: =IFERROR(VALUE(SUBSTITUTE(TRIM('수출입 총괄'!G13),",","")),"") -> 45267799 | K9: =IFERROR(VALUE(SUBSTITUTE(TRIM('수출입 총괄'!H13),",","")),"") -> 53838742 | L9: =IFERROR(VALUE(SUBSTITUTE(TRIM('수출입 총괄'!I13),",","")),"") -> 3620046
A10: =TRIM('수출입 총괄'!A14) -> 2024.08 | B10: =IFERROR(VALUE(LEFT($A10,4)),"") -> 2024 | C10: =IFERROR(VALUE(RIGHT($A10,2)),"") -> 8 | D10: =IFERROR(ROUNDUP($C10/3,0),"") -> 3 | E10: =IFERROR(VALUE(SUBSTITUTE(TRIM('수출입 총괄'!B14),",","")),"") -> 23.5 | F10: =IFERROR(VALUE(SUBSTITUTE(TRIM('수출입 총괄'!C14),",","")),"") -> 971248 | G10: =IFERROR(VALUE(SUBSTITUTE(TRIM('수출입 총괄'!D14),",","")),"") -> 17070041 | H10: =IFERROR(VALUE(SUBSTITUTE(TRIM('수출입 총괄'!E14),",","")),"") -> 57642924 | I10: =IFERROR(VALUE(SUBSTITUTE(TRIM('수출입 총괄'!F14),",","")),"") -> 4219404 | J10: =IFERROR(VALUE(SUBSTITUTE(TRIM('수출입 총괄'!G14),",","")),"") -> 49665340 | K10: =IFERROR(VALUE(SUBSTITUTE(TRIM('수출입 총괄'!H14),",","")),"") -> 54054894 | L10: =IFERROR(VALUE(SUBSTITUTE(TRIM('수출입 총괄'!I14),",","")),"") -> 3588030
A11: =TRIM('수출입 총괄'!A15) -> 2024.09 | B11: =IFERROR(VALUE(LEFT($A11,4)),"") -> 2024 | C11: =IFERROR(VALUE(RIGHT($A11,2)),"") -> 9 | D11: =IFERROR(ROUNDUP($C11/3,0),"") -> 3 | E11: =IFERROR(VALUE(SUBSTITUTE(TRIM('수출입 총괄'!B15),",","")),"") -> 20 | F11: =IFERROR(VALUE(SUBSTITUTE(TRIM('수출입 총괄'!C15),",","")),"") -> 1151289 | G11: =IFERROR(VALUE(SUBSTITUTE(TRIM('수출입 총괄'!D15),",","")),"") -> 16449775 | H11: =IFERROR(VALUE(SUBSTITUTE(TRIM('수출입 총괄'!E15),",","")),"") -> 58544693 | I11: =IFERROR(VALUE(SUBSTITUTE(TRIM('수출입 총괄'!F15),",","")),"") -> 4244016 | J11: =IFERROR(VALUE(SUBSTITUTE(TRIM('수출입 총괄'!G15),",","")),"") -> 44145422 | K11: =IFERROR(VALUE(SUBSTITUTE(TRIM('수출입 총괄'!H15),",","")),"") -> 52102925 | L11: =IFERROR(VALUE(SUBSTITUTE(TRIM('수출입 총괄'!I15),",","")),"") -> 6441768
A12: =TRIM('수출입 총괄'!A16) -> 2024.10 | B12: =IFERROR(VALUE(LEFT($A12,4)),"") -> 2024 | C12: =IFERROR(VALUE(RIGHT($A12,2)),"") -> 10 | D12: =IFERROR(ROUNDUP($C12/3,0),"") -> 4 | E12: =IFERROR(VALUE(SUBSTITUTE(TRIM('수출입 총괄'!B16),",","")),"") -> 22 | F12: =IFERROR(VALUE(SUBSTITUTE(TRIM('수출입 총괄'!C16),",","")),"") -> 1020830 | G12: =IFERROR(VALUE(SUBSTITUTE(TRIM('수출입 총괄'!D16),",","")),"") -> 15994864 | H12: =IFERROR(VALUE(SUBSTITUTE(TRIM('수출입 총괄'!E16),",","")),"") -> 57500192 | I12: =IFERROR(VALUE(SUBSTITUTE(TRIM('수출입 총괄'!F16),",","")),"") -> 4672638 | J12: =IFERROR(VALUE(SUBSTITUTE(TRIM('수출입 총괄'!G16),",","")),"") -> 47452574 | K12: =IFERROR(VALUE(SUBSTITUTE(TRIM('수출입 총괄'!H16),",","")),"") -> 54331589 | L12: =IFERROR(VALUE(SUBSTITUTE(TRIM('수출입 총괄'!I16),",","")),"") -> 3168604
A13: =TRIM('수출입 총괄'!A17) -> 2024.11 | B13: =IFERROR(VALUE(LEFT($A13,4)),"") -> 2024 | C13: =IFERROR(VALUE(RIGHT($A13,2)),"") -> 11 | D13: =IFERROR(ROUNDUP($C13/3,0),"") -> 4 | E13: =IFERROR(VALUE(SUBSTITUTE(TRIM('수출입 총괄'!B17),",","")),"") -> 23.5 | F13: =IFERROR(VALUE(SUBSTITUTE(TRIM('수출입 총괄'!C17),",","")),"") -> 1221469 | G13: =IFERROR(VALUE(SUBSTITUTE(TRIM('수출입 총괄'!D17),",","")),"") -> 15893956 | H13: =IFERROR(VALUE(SUBSTITUTE(TRIM('수출입 총괄'!E17),",","")),"") -> 56288629 | I13: =IFERROR(VALUE(SUBSTITUTE(TRIM('수출입 총괄'!F17),",","")),"") -> 4595519 | J13: =IFERROR(VALUE(SUBSTITUTE(TRIM('수출입 총괄'!G17),",","")),"") -> 44116295 | K13: =IFERROR(VALUE(SUBSTITUTE(TRIM('수출입 총괄'!H17),",","")),"") -> 50718992 | L13: =IFERROR(VALUE(SUBSTITUTE(TRIM('수출입 총괄'!I17),",","")),"") -> 5569637
A14: =TRIM('수출입 총괄'!A18) -> 2024.12 | B14: =IFERROR(VALUE(LEFT($A14,4)),"") -> 2024 | C14: =IFERROR(VALUE(RIGHT($A14,2)),"") -> 12 | D14: =IFERROR(ROUNDUP($C14/3,0),"") -> 4 | E14: =IFERROR(VALUE(SUBSTITUTE(TRIM('수출입 총괄'!B18),",","")),"") -> 23 | F14: =IFERROR(VALUE(SUBSTITUTE(TRIM('수출입 총괄'!C18),",","")),"") -> 1135404 | G14: =IFERROR(VALUE(SUBSTITUTE(TRIM('수출입 총괄'!D18),",","")),"") -> 17620291 | H14: =IFERROR(VALUE(SUBSTITUTE(TRIM('수출입 총괄'!E18),",","")),"") -> 61359250 | I14: =IFERROR(VALUE(SUBSTITUTE(TRIM('수출입 총괄'!F18),",","")),"") -> 4668507 | J14: =IFERROR(VALUE(SUBSTITUTE(TRIM('수출입 총괄'!G18),",","")),"") -> 48014998 | K14: =IFERROR(VALUE(SUBSTITUTE(TRIM('수출입 총괄'!H18),",","")),"") -> 54866380 | L14: =IFERROR(VALUE(SUBSTITUTE(TRIM('수출입 총괄'!I18),",","")),"") -> 6492870
... A33: =TRIM('수출입 총괄'!A37) -> 2026.07 | B33: =IFERROR(VALUE(LEFT($A33,4)),"") -> 2026 | C33: =IFERROR(VALUE(RIGHT($A33,2)),"") -> 7 | D33: =IFERROR(ROUNDUP($C33/3,0),"") -> 3 | E33: =IFERROR(VALUE(SUBSTITUTE(TRIM('수출입 총괄'!B37),",","")),"") -> 24 | F33: =IFERROR(VALUE(SUBSTITUTE(TRIM('수출입 총괄'!C37),",","")),"") -> 1111934 | G33: =IFERROR(VALUE(SUBSTITUTE(TRIM('수출입 총괄'!D37),",","")),"") -> 17660681 | H33: =IFERROR(VALUE(SUBSTITUTE(TRIM('수출입 총괄'!E37),",","")),"") -> 98959099 | I33: =IFERROR(VALUE(SUBSTITUTE(TRIM('수출입 총괄'!F37),",","")),"") -> 5158848 | J33: =IFERROR(VALUE(SUBSTITUTE(TRIM('수출입 총괄'!G37),",","")),"") -> 51144176 | K33: =IFERROR(VALUE(SUBSTITUTE(TRIM('수출입 총괄'!H37),",","")),"") -> 68567473 | L33: =IFERROR(VALUE(SUBSTITUTE(TRIM('수출입 총괄'!I37),",","")),"") -> 30391625

Sheet 데이터_품목별
A1: 이 시트의 모든 셀은 원본 시트를 참조하는 수식입니다. 원본은 숫자가 텍스트(쉼표 포함)로 저장되어 있어 VALUE/SUBSTITUTE로 숫자화했고, 연도·월·분기 열을 파생시켜 MoM/QoQ/YoY 집계가 가능하도록 했습니다. 직접 입력하지 마세요.
A2: 기간 | B2: 연도 | C2: 월 | D2: 분기 | E2: HS코드 | F2: 품목명 | G2: 수출 중량 | H2: 수출 금액 | I2: 수입 중량 | J2: 수입 금액 | K2: 무역수지
A3: =TRIM('수출입 실적(품목별)'!A7) -> 2024.01 | B3: =IFERROR(VALUE(LEFT($A3,4)),"") -> 2024 | C3: =IFERROR(VALUE(RIGHT($A3,2)),"") -> 1 | D3: =IFERROR(ROUNDUP($C3/3,0),"") -> 1 | E3: =TRIM('수출입 실적(품목별)'!B7) -> 01 | F3: =TRIM('수출입 실적(품목별)'!C7) -> 살아 있는 동물 | G3: =IFERROR(VALUE(SUBSTITUTE(TRIM('수출입 실적(품목별)'!D7),",","")),"") -> 1.9 | H3: =IFERROR(VALUE(SUBSTITUTE(TRIM('수출입 실적(품목별)'!E7),",","")),"") -> 697 | I3: =IFERROR(VALUE(SUBSTITUTE(TRIM('수출입 실적(품목별)'!F7),",","")),"") -> 78.1 | J3: =IFERROR(VALUE(SUBSTITUTE(TRIM('수출입 실적(품목별)'!G7),",","")),"") -> 5631 | K3: =IFERROR(VALUE(SUBSTITUTE(TRIM('수출입 실적(품목별)'!H7),",","")),"") -> -4934
A4: =TRIM('수출입 실적(품목별)'!A8) -> 2024.01 | B4: =IFERROR(VALUE(LEFT($A4,4)),"") -> 2024 | C4: =IFERROR(VALUE(RIGHT($A4,2)),"") -> 1 | D4: =IFERROR(ROUNDUP($C4/3,0),"") -> 1 | E4: =TRIM('수출입 실적(품목별)'!B8) -> 02 | F4: =TRIM('수출입 실적(품목별)'!C8) -> 육과 식용 설육(屑肉) | G4: =IFERROR(VALUE(SUBSTITUTE(TRIM('수출입 실적(품목별)'!D8),",","")),"") -> 3806.5 | H4: =IFERROR(VALUE(SUBSTITUTE(TRIM('수출입 실적(품목별)'!E8),",","")),"") -> 5389 | I4: =IFERROR(VALUE(SUBSTITUTE(TRIM('수출입 실적(품목별)'!F8),",","")),"") -> 154357.2 | J4: =IFERROR(VALUE(SUBSTITUTE(TRIM('수출입 실적(품목별)'!G8),",","")),"") -> 823919 | K4: =IFERROR(VALUE(SUBSTITUTE(TRIM('수출입 실적(품목별)'!H8),",","")),"") -> -818530
A5: =TRIM('수출입 실적(품목별)'!A9) -> 2024.01 | B5: =IFERROR(VALUE(LEFT($A5,4)),"") -> 2024 | C5: =IFERROR(VALUE(RIGHT($A5,2)),"") -> 1 | D5: =IFERROR(ROUNDUP($C5/3,0),"") -> 1 | E5: =TRIM('수출입 실적(품목별)'!B9) -> 03 | F5: =TRIM('수출입 실적(품목별)'!C9) -> 어류ㆍ갑각류ㆍ연체동물과 그 밖의 수생(水生) 무척추동물 | G5: =IFERROR(VALUE(SUBSTITUTE(TRIM('수출입 실적(품목별)'!D9),",","")),"") -> 45908.2 | H5: =IFERROR(VALUE(SUBSTITUTE(TRIM('수출입 실적(품목별)'!E9),",","")),"") -> 128716 | I5: =IFERROR(VALUE(SUBSTITUTE(TRIM('수출입 실적(품목별)'!F9),",","")),"") -> 119002.6 | J5: =IFERROR(VALUE(SUBSTITUTE(TRIM('수출입 실적(품목별)'!G9),",","")),"") -> 424949 | K5: =IFERROR(VALUE(SUBSTITUTE(TRIM('수출입 실적(품목별)'!H9),",","")),"") -> -296232
A6: =TRIM('수출입 실적(품목별)'!A10) -> 2024.01 | B6: =IFERROR(VALUE(LEFT($A6,4)),"") -> 2024 | C6: =IFERROR(VALUE(RIGHT($A6,2)),"") -> 1 | D6: =IFERROR(ROUNDUP($C6/3,0),"") -> 1 | E6: =TRIM('수출입 실적(품목별)'!B10) -> 04 | F6: =TRIM('수출입 실적(품목별)'!C10) -> 낙농품, 새의 알, 천연꿀, 다른 류로 분류되지 않은 식용인 동물성 생산품 | G6: =IFERROR(VALUE(SUBSTITUTE(TRIM('수출입 실적(품목별)'!D10),",","")),"") -> 2995.9 | H6: =IFERROR(VALUE(SUBSTITUTE(TRIM('수출입 실적(품목별)'!E10),",","")),"") -> 7500 | I6: =IFERROR(VALUE(SUBSTITUTE(TRIM('수출입 실적(품목별)'!F10),",","")),"") -> 23072.3 | J6: =IFERROR(VALUE(SUBSTITUTE(TRIM('수출입 실적(품목별)'!G10),",","")),"") -> 93645 | K6: =IFERROR(VALUE(SUBSTITUTE(TRIM('수출입 실적(품목별)'!H10),",","")),"") -> -86145
A7: =TRIM('수출입 실적(품목별)'!A11) -> 2024.01 | B7: =IFERROR(VALUE(LEFT($A7,4)),"") -> 2024 | C7: =IFERROR(VALUE(RIGHT($A7,2)),"") -> 1 | D7: =IFERROR(ROUNDUP($C7/3,0),"") -> 1 | E7: =TRIM('수출입 실적(품목별)'!B11) -> 05 | F7: =TRIM('수출입 실적(품목별)'!C11) -> 다른 류로 분류되지 않은 동물성 생산품 | G7: =IFERROR(VALUE(SUBSTITUTE(TRIM('수출입 실적(품목별)'!D11),",","")),"") -> 1211.7 | H7: =IFERROR(VALUE(SUBSTITUTE(TRIM('수출입 실적(품목별)'!E11),",","")),"") -> 3306 | I7: =IFERROR(VALUE(SUBSTITUTE(TRIM('수출입 실적(품목별)'!F11),",","")),"") -> 5691 | J7: =IFERROR(VALUE(SUBSTITUTE(TRIM('수출입 실적(품목별)'!G11),",","")),"") -> 28749 | K7: =IFERROR(VALUE(SUBSTITUTE(TRIM('수출입 실적(품목별)'!H11),",","")),"") -> -25443
A8: =TRIM('수출입 실적(품목별)'!A12) -> 2024.01 | B8: =IFERROR(VALUE(LEFT($A8,4)),"") -> 2024 | C8: =IFERROR(VALUE(RIGHT($A8,2)),"") -> 1 | D8: =IFERROR(ROUNDUP($C8/3,0),"") -> 1 | E8: =TRIM('수출입 실적(품목별)'!B12) -> 06 | F8: =TRIM('수출입 실적(품목별)'!C12) -> 살아 있는 수목과 그 밖의 식물, 인경(鱗莖)ㆍ뿌리와 이와 유사한 물품, 절화(切花)와 장식용 잎 | G8: =IFERROR(VALUE(SUBSTITUTE(TRIM('수출입 실적(품목별)'!D12),",","")),"") -> 67.8 | H8: =IFERROR(VALUE(SUBSTITUTE(TRIM('수출입 실적(품목별)'!E12),",","")),"") -> 856 | I8: =IFERROR(VALUE(SUBSTITUTE(TRIM('수출입 실적(품목별)'!F12),",","")),"") -> 8667.7 | J8: =IFERROR(VALUE(SUBSTITUTE(TRIM('수출입 실적(품목별)'!G12),",","")),"") -> 15350 | K8: =IFERROR(VALUE(SUBSTITUTE(TRIM('수출입 실적(품목별)'!H12),",","")),"") -> -14494
A9: =TRIM('수출입 실적(품목별)'!A13) -> 2024.01 | B9: =IFERROR(VALUE(LEFT($A9,4)),"") -> 2024 | C9: =IFERROR(VALUE(RIGHT($A9,2)),"") -> 1 | D9: =IFERROR(ROUNDUP($C9/3,0),"") -> 1 | E9: =TRIM('수출입 실적(품목별)'!B13) -> 07 | F9: =TRIM('수출입 실적(품목별)'!C13) -> 식용의 채소ㆍ뿌리ㆍ괴경(塊莖) | G9: =IFERROR(VALUE(SUBSTITUTE(TRIM('수출입 실적(품목별)'!D13),",","")),"") -> 5191.9 | H9: =IFERROR(VALUE(SUBSTITUTE(TRIM('수출입 실적(품목별)'!E13),",","")),"") -> 10899 | I9: =IFERROR(VALUE(SUBSTITUTE(TRIM('수출입 실적(품목별)'!F13),",","")),"") -> 103820.8 | J9: =IFERROR(VALUE(SUBSTITUTE(TRIM('수출입 실적(품목별)'!G13),",","")),"") -> 86850 | K9: =IFERROR(VALUE(SUBSTITUTE(TRIM('수출입 실적(품목별)'!H13),",","")),"") -> -75951
A10: =TRIM('수출입 실적(품목별)'!A14) -> 2024.01 | B10: =IFERROR(VALUE(LEFT($A10,4)),"") -> 2024 | C10: =IFERROR(VALUE(RIGHT($A10,2)),"") -> 1 | D10: =IFERROR(ROUNDUP($C10/3,0),"") -> 1 | E10: =TRIM('수출입 실적(품목별)'!B14) -> 08 | F10: =TRIM('수출입 실적(품목별)'!C14) -> 식용의 과실과 견과류, 감귤류ㆍ멜론의 껍질 | G10: =IFERROR(VALUE(SUBSTITUTE(TRIM('수출입 실적(품목별)'!D14),",","")),"") -> 2972.4 | H10: =IFERROR(VALUE(SUBSTITUTE(TRIM('수출입 실적(품목별)'!E14),",","")),"") -> 26827 | I10: =IFERROR(VALUE(SUBSTITUTE(TRIM('수출입 실적(품목별)'!F14),",","")),"") -> 67690.2 | J10: =IFERROR(VALUE(SUBSTITUTE(TRIM('수출입 실적(품목별)'!G14),",","")),"") -> 159724 | K10: =IFERROR(VALUE(SUBSTITUTE(TRIM('수출입 실적(품목별)'!H14),",","")),"") -> -132897
A11: =TRIM('수출입 실적(품목별)'!A15) -> 2024.01 | B11: =IFERROR(VALUE(LEFT($A11,4)),"") -> 2024 | C11: =IFERROR(VALUE(RIGHT($A11,2)),"") -> 1 | D11: =IFERROR(ROUNDUP($C11/3,0),"") -> 1 | E11: =TRIM('수출입 실적(품목별)'!B15) -> 09 | F11: =TRIM('수출입 실적(품목별)'!C15) -> 커피ㆍ차ㆍ마테(maté)ㆍ향신료 | G11: =IFERROR(VALUE(SUBSTITUTE(TRIM('수출입 실적(품목별)'!D15),",","")),"") -> 385 | H11: =IFERROR(VALUE(SUBSTITUTE(TRIM('수출입 실적(품목별)'!E15),",","")),"") -> 3239 | I11: =IFERROR(VALUE(SUBSTITUTE(TRIM('수출입 실적(품목별)'!F15),",","")),"") -> 21378.1 | J11: =IFERROR(VALUE(SUBSTITUTE(TRIM('수출입 실적(품목별)'!G15),",","")),"") -> 103751 | K11: =IFERROR(VALUE(SUBSTITUTE(TRIM('수출입 실적(품목별)'!H15),",","")),"") -> -100511
A12: =TRIM('수출입 실적(품목별)'!A16) -> 2024.01 | B12: =IFERROR(VALUE(LEFT($A12,4)),"") -> 2024 | C12: =IFERROR(VALUE(RIGHT($A12,2)),"") -> 1 | D12: =IFERROR(ROUNDUP($C12/3,0),"") -> 1 | E12: =TRIM('수출입 실적(품목별)'!B16) -> 10 | F12: =TRIM('수출입 실적(품목별)'!C16) -> 곡물 | G12: =IFERROR(VALUE(SUBSTITUTE(TRIM('수출입 실적(품목별)'!D16),",","")),"") -> 358.6 | H12: =IFERROR(VALUE(SUBSTITUTE(TRIM('수출입 실적(품목별)'!E16),",","")),"") -> 918 | I12: =IFERROR(VALUE(SUBSTITUTE(TRIM('수출입 실적(품목별)'!F16),",","")),"") -> 1451151.7 | J12: =IFERROR(VALUE(SUBSTITUTE(TRIM('수출입 실적(품목별)'!G16),",","")),"") -> 450755 | K12: =IFERROR(VALUE(SUBSTITUTE(TRIM('수출입 실적(품목별)'!H16),",","")),"") -> -449837
A13: =TRIM('수출입 실적(품목별)'!A17) -> 2024.01 | B13: =IFERROR(VALUE(LEFT($A13,4)),"") -> 2024 | C13: =IFERROR(VALUE(RIGHT($A13,2)),"") -> 1 | D13: =IFERROR(ROUNDUP($C13/3,0),"") -> 1 | E13: =TRIM('수출입 실적(품목별)'!B17) -> 11 | F13: =TRIM('수출입 실적(품목별)'!C17) -> 제분공업의 생산품과 맥아, 전분, 이눌린(inulin), 밀의 글루텐(gluten) | G13: =IFERROR(VALUE(SUBSTITUTE(TRIM('수출입 실적(품목별)'!D17),",","")),"") -> 5794.3 | H13: =IFERROR(VALUE(SUBSTITUTE(TRIM('수출입 실적(품목별)'!E17),",","")),"") -> 4158 | I13: =IFERROR(VALUE(SUBSTITUTE(TRIM('수출입 실적(품목별)'!F17),",","")),"") -> 31887.3 | J13: =IFERROR(VALUE(SUBSTITUTE(TRIM('수출입 실적(품목별)'!G17),",","")),"") -> 28615 | K13: =IFERROR(VALUE(SUBSTITUTE(TRIM('수출입 실적(품목별)'!H17),",","")),"") -> -24457
A14: =TRIM('수출입 실적(품목별)'!A18) -> 2024.01 | B14: =IFERROR(VALUE(LEFT($A14,4)),"") -> 2024 | C14: =IFERROR(VALUE(RIGHT($A14,2)),"") -> 1 | D14: =IFERROR(ROUNDUP($C14/3,0),"") -> 1 | E14: =TRIM('수출입 실적(품목별)'!B18) -> 12 | F14: =TRIM('수출입 실적(품목별)'!C18) -> 채유(採油)에 적합한 종자와 과실, 각종 종자와 과실, 공업용ㆍ의약용 식물, 짚과 사료용 식물 | G14: =IFERROR(VALUE(SUBSTITUTE(TRIM('수출입 실적(품목별)'!D18),",","")),"") -> 2659.8 | H14: =IFERROR(VALUE(SUBSTITUTE(TRIM('수출입 실적(품목별)'!E18),",","")),"") -> 46869 | I14: =IFERROR(VALUE(SUBSTITUTE(TRIM('수출입 실적(품목별)'!F18),",","")),"") -> 265704.5 | J14: =IFERROR(VALUE(SUBSTITUTE(TRIM('수출입 실적(품목별)'!G18),",","")),"") -> 164119 | K14: =IFERROR(VALUE(SUBSTITUTE(TRIM('수출입 실적(품목별)'!H18),",","")),"") -> -117250
... A2984: =TRIM('수출입 실적(품목별)'!A2988) -> 2026.07 | B2984: =IFERROR(VALUE(LEFT($A2984,4)),"") -> 2026 | C2984: =IFERROR(VALUE(RIGHT($A2984,2)),"") -> 7 | D2984: =IFERROR(ROUNDUP($C2984/3,0),"") -> 3 | E2984: =TRIM('수출입 실적(품목별)'!B2988) -> 97 | F2984: =TRIM('수출입 실적(품목별)'!C2988) -> 예술품ㆍ수집품ㆍ골동품 | G2984: =IFERROR(VALUE(SUBSTITUTE(TRIM('수출입 실적(품목별)'!D2988),",","")),"") -> 17.6 | H2984: =IFERROR(VALUE(SUBSTITUTE(TRIM('수출입 실적(품목별)'!E2988),",","")),"") -> 15110 | I2984: =IFERROR(VALUE(SUBSTITUTE(TRIM('수출입 실적(품목별)'!F2988),",","")),"") -> 37.5 | J2984: =IFERROR(VALUE(SUBSTITUTE(TRIM('수출입 실적(품목별)'!G2988),",","")),"") -> 20791 | K2984: =IFERROR(VALUE(SUBSTITUTE(TRIM('수출입 실적(품목별)'!H2988),",","")),"") -> -5681

Sheet 데이터_성질별수출
A1: 이 시트의 모든 셀은 원본 시트를 참조하는 수식입니다. 원본은 숫자가 텍스트(쉼표 포함)로 저장되어 있어 VALUE/SUBSTITUTE로 숫자화했고, 연도·월·분기 열을 파생시켜 MoM/QoQ/YoY 집계가 가능하도록 했습니다. 직접 입력하지 마세요.
A2: 기간 | B2: 연도 | C2: 월 | D2: 분기 | E2: 성질명 | F2: 수출 중량 | G2: 수출 금액
A3: =TRIM('수출입 실적(성질별_수출)'!A7) -> 2024.01 | B3: =IFERROR(VALUE(LEFT($A3,4)),"") -> 2024 | C3: =IFERROR(VALUE(RIGHT($A3,2)),"") -> 1 | D3: =IFERROR(ROUNDUP($C3/3,0),"") -> 1 | E3: =TRIM('수출입 실적(성질별_수출)'!C7) -> 1. 식료 및 직접소비재 | F3: =IFERROR(VALUE(SUBSTITUTE(TRIM('수출입 실적(성질별_수출)'!D7),",","")),"") -> 300432.1 | G3: =IFERROR(VALUE(SUBSTITUTE(TRIM('수출입 실적(성질별_수출)'!E7),",","")),"") -> 861851
A4: =TRIM('수출입 실적(성질별_수출)'!A8) -> 2024.01 | B4: =IFERROR(VALUE(LEFT($A4,4)),"") -> 2024 | C4: =IFERROR(VALUE(RIGHT($A4,2)),"") -> 1 | D4: =IFERROR(ROUNDUP($C4/3,0),"") -> 1 | E4: =TRIM('수출입 실적(성질별_수출)'!C8) -> 2. 원료 및 연료 | F4: =IFERROR(VALUE(SUBSTITUTE(TRIM('수출입 실적(성질별_수출)'!D8),",","")),"") -> 6905534.8 | G4: =IFERROR(VALUE(SUBSTITUTE(TRIM('수출입 실적(성질별_수출)'!E8),",","")),"") -> 5596612
A5: =TRIM('수출입 실적(성질별_수출)'!A9) -> 2024.01 | B5: =IFERROR(VALUE(LEFT($A5,4)),"") -> 2024 | C5: =IFERROR(VALUE(RIGHT($A5,2)),"") -> 1 | D5: =IFERROR(ROUNDUP($C5/3,0),"") -> 1 | E5: =TRIM('수출입 실적(성질별_수출)'!C9) -> 3. 경공업품 | F5: =IFERROR(VALUE(SUBSTITUTE(TRIM('수출입 실적(성질별_수출)'!D9),",","")),"") -> 831132.2 | G5: =IFERROR(VALUE(SUBSTITUTE(TRIM('수출입 실적(성질별_수출)'!E9),",","")),"") -> 2738143
A6: =TRIM('수출입 실적(성질별_수출)'!A10) -> 2024.01 | B6: =IFERROR(VALUE(LEFT($A6,4)),"") -> 2024 | C6: =IFERROR(VALUE(RIGHT($A6,2)),"") -> 1 | D6: =IFERROR(ROUNDUP($C6/3,0),"") -> 1 | E6: =TRIM('수출입 실적(성질별_수출)'!C10) -> 가. 섬유원료 | F6: =IFERROR(VALUE(SUBSTITUTE(TRIM('수출입 실적(성질별_수출)'!D10),",","")),"") -> 63223.8 | G6: =IFERROR(VALUE(SUBSTITUTE(TRIM('수출입 실적(성질별_수출)'!E10),",","")),"") -> 94714
A7: =TRIM('수출입 실적(성질별_수출)'!A11) -> 2024.01 | B7: =IFERROR(VALUE(LEFT($A7,4)),"") -> 2024 | C7: =IFERROR(VALUE(RIGHT($A7,2)),"") -> 1 | D7: =IFERROR(ROUNDUP($C7/3,0),"") -> 1 | E7: =TRIM('수출입 실적(성질별_수출)'!C11) -> 나. 섬유사 | F7: =IFERROR(VALUE(SUBSTITUTE(TRIM('수출입 실적(성질별_수출)'!D11),",","")),"") -> 21325.1 | G7: =IFERROR(VALUE(SUBSTITUTE(TRIM('수출입 실적(성질별_수출)'!E11),",","")),"") -> 72562
A8: =TRIM('수출입 실적(성질별_수출)'!A12) -> 2024.01 | B8: =IFERROR(VALUE(LEFT($A8,4)),"") -> 2024 | C8: =IFERROR(VALUE(RIGHT($A8,2)),"") -> 1 | D8: =IFERROR(ROUNDUP($C8/3,0),"") -> 1 | E8: =TRIM('수출입 실적(성질별_수출)'!C12) -> 다. 직 물 | F8: =IFERROR(VALUE(SUBSTITUTE(TRIM('수출입 실적(성질별_수출)'!D12),",","")),"") -> 30569.4 | G8: =IFERROR(VALUE(SUBSTITUTE(TRIM('수출입 실적(성질별_수출)'!E12),",","")),"") -> 292221
A9: =TRIM('수출입 실적(성질별_수출)'!A13) -> 2024.01 | B9: =IFERROR(VALUE(LEFT($A9,4)),"") -> 2024 | C9: =IFERROR(VALUE(RIGHT($A9,2)),"") -> 1 | D9: =IFERROR(ROUNDUP($C9/3,0),"") -> 1 | E9: =TRIM('수출입 실적(성질별_수출)'!C13) -> 라. 기타 섬유제품 | F9: =IFERROR(VALUE(SUBSTITUTE(TRIM('수출입 실적(성질별_수출)'!D13),",","")),"") -> 21795.8 | G9: =IFERROR(VALUE(SUBSTITUTE(TRIM('수출입 실적(성질별_수출)'!E13),",","")),"") -> 183169
A10: =TRIM('수출입 실적(성질별_수출)'!A14) -> 2024.01 | B10: =IFERROR(VALUE(LEFT($A10,4)),"") -> 2024 | C10: =IFERROR(VALUE(RIGHT($A10,2)),"") -> 1 | D10: =IFERROR(ROUNDUP($C10/3,0),"") -> 1 | E10: =TRIM('수출입 실적(성질별_수출)'!C14) -> 마. 의 류 | F10: =IFERROR(VALUE(SUBSTITUTE(TRIM('수출입 실적(성질별_수출)'!D14),",","")),"") -> 5866.4 | G10: =IFERROR(VALUE(SUBSTITUTE(TRIM('수출입 실적(성질별_수출)'!E14),",","")),"") -> 166152
A11: =TRIM('수출입 실적(성질별_수출)'!A15) -> 2024.01 | B11: =IFERROR(VALUE(LEFT($A11,4)),"") -> 2024 | C11: =IFERROR(VALUE(RIGHT($A11,2)),"") -> 1 | D11: =IFERROR(ROUNDUP($C11/3,0),"") -> 1 | E11: =TRIM('수출입 실적(성질별_수출)'!C15) -> 바. 목제품 | F11: =IFERROR(VALUE(SUBSTITUTE(TRIM('수출입 실적(성질별_수출)'!D15),",","")),"") -> 17007.4 | G11: =IFERROR(VALUE(SUBSTITUTE(TRIM('수출입 실적(성질별_수출)'!E15),",","")),"") -> 94566
A12: =TRIM('수출입 실적(성질별_수출)'!A16) -> 2024.01 | B12: =IFERROR(VALUE(LEFT($A12,4)),"") -> 2024 | C12: =IFERROR(VALUE(RIGHT($A12,2)),"") -> 1 | D12: =IFERROR(ROUNDUP($C12/3,0),"") -> 1 | E12: =TRIM('수출입 실적(성질별_수출)'!C16) -> 사. 가죽, 고무 및 신발류 | F12: =IFERROR(VALUE(SUBSTITUTE(TRIM('수출입 실적(성질별_수출)'!D16),",","")),"") -> 76231.1 | G12: =IFERROR(VALUE(SUBSTITUTE(TRIM('수출입 실적(성질별_수출)'!E16),",","")),"") -> 432552
A13: =TRIM('수출입 실적(성질별_수출)'!A17) -> 2024.01 | B13: =IFERROR(VALUE(LEFT($A13,4)),"") -> 2024 | C13: =IFERROR(VALUE(RIGHT($A13,2)),"") -> 1 | D13: =IFERROR(ROUNDUP($C13/3,0),"") -> 1 | E13: =TRIM('수출입 실적(성질별_수출)'!C17) -> 아. 귀금속 및 보석류 | F13: =IFERROR(VALUE(SUBSTITUTE(TRIM('수출입 실적(성질별_수출)'!D17),",","")),"") -> 323 | G13: =IFERROR(VALUE(SUBSTITUTE(TRIM('수출입 실적(성질별_수출)'!E17),",","")),"") -> 196258
A14: =TRIM('수출입 실적(성질별_수출)'!A18) -> 2024.01 | B14: =IFERROR(VALUE(LEFT($A14,4)),"") -> 2024 | C14: =IFERROR(VALUE(RIGHT($A14,2)),"") -> 1 | D14: =IFERROR(ROUNDUP($C14/3,0),"") -> 1 | E14: =TRIM('수출입 실적(성질별_수출)'!C18) -> 자. 기타 비금속 광물제품 | F14: =IFERROR(VALUE(SUBSTITUTE(TRIM('수출입 실적(성질별_수출)'!D18),",","")),"") -> 225540 | G14: =IFERROR(VALUE(SUBSTITUTE(TRIM('수출입 실적(성질별_수출)'!E18),",","")),"") -> 220807
... A653: =TRIM('수출입 실적(성질별_수출)'!A657) -> 2026.07 | B653: =IFERROR(VALUE(LEFT($A653,4)),"") -> 2026 | C653: =IFERROR(VALUE(RIGHT($A653,2)),"") -> 7 | D653: =IFERROR(ROUNDUP($C653/3,0),"") -> 3 | E653: =TRIM('수출입 실적(성질별_수출)'!C657) -> 바. 기 타 | F653: =IFERROR(VALUE(SUBSTITUTE(TRIM('수출입 실적(성질별_수출)'!D657),",","")),"") -> 89360.5 | G653: =IFERROR(VALUE(SUBSTITUTE(TRIM('수출입 실적(성질별_수출)'!E657),",","")),"") -> 2725433

Sheet 데이터_성질별수입
A1: 이 시트의 모든 셀은 원본 시트를 참조하는 수식입니다. 원본은 숫자가 텍스트(쉼표 포함)로 저장되어 있어 VALUE/SUBSTITUTE로 숫자화했고, 연도·월·분기 열을 파생시켜 MoM/QoQ/YoY 집계가 가능하도록 했습니다. 직접 입력하지 마세요.
A2: 기간 | B2: 연도 | C2: 월 | D2: 분기 | E2: 성질명 | F2: 수입 중량 | G2: 수입 금액
A3: =TRIM('수출입 실적(성질별_수입)'!A7) -> 2024.01 | B3: =IFERROR(VALUE(LEFT($A3,4)),"") -> 2024 | C3: =IFERROR(VALUE(RIGHT($A3,2)),"") -> 1 | D3: =IFERROR(ROUNDUP($C3/3,0),"") -> 1 | E3: =TRIM('수출입 실적(성질별_수입)'!C7) -> 1. 소비재 | F3: =IFERROR(VALUE(SUBSTITUTE(TRIM('수출입 실적(성질별_수입)'!D7),",","")),"") -> 3564536.2 | G3: =IFERROR(VALUE(SUBSTITUTE(TRIM('수출입 실적(성질별_수입)'!E7),",","")),"") -> 8746306
A4: =TRIM('수출입 실적(성질별_수입)'!A8) -> 2024.01 | B4: =IFERROR(VALUE(LEFT($A4,4)),"") -> 2024 | C4: =IFERROR(VALUE(RIGHT($A4,2)),"") -> 1 | D4: =IFERROR(ROUNDUP($C4/3,0),"") -> 1 | E4: =TRIM('수출입 실적(성질별_수입)'!C8) -> 가. 곡물 | F4: =IFERROR(VALUE(SUBSTITUTE(TRIM('수출입 실적(성질별_수입)'!D8),",","")),"") -> 2354636 | G4: =IFERROR(VALUE(SUBSTITUTE(TRIM('수출입 실적(성질별_수입)'!E8),",","")),"") -> 832333
A5: =TRIM('수출입 실적(성질별_수입)'!A9) -> 2024.01 | B5: =IFERROR(VALUE(LEFT($A5,4)),"") -> 2024 | C5: =IFERROR(VALUE(RIGHT($A5,2)),"") -> 1 | D5: =IFERROR(ROUNDUP($C5/3,0),"") -> 1 | E5: =TRIM('수출입 실적(성질별_수입)'!C9) -> 나. 직접소비재 | F5: =IFERROR(VALUE(SUBSTITUTE(TRIM('수출입 실적(성질별_수입)'!D9),",","")),"") -> 808352.3 | G5: =IFERROR(VALUE(SUBSTITUTE(TRIM('수출입 실적(성질별_수입)'!E9),",","")),"") -> 2556100
A6: =TRIM('수출입 실적(성질별_수입)'!A10) -> 2024.01 | B6: =IFERROR(VALUE(LEFT($A6,4)),"") -> 2024 | C6: =IFERROR(VALUE(RIGHT($A6,2)),"") -> 1 | D6: =IFERROR(ROUNDUP($C6/3,0),"") -> 1 | E6: =TRIM('수출입 실적(성질별_수입)'!C10) -> 다. 내구소비재 | F6: =IFERROR(VALUE(SUBSTITUTE(TRIM('수출입 실적(성질별_수입)'!D10),",","")),"") -> 268971.7 | G6: =IFERROR(VALUE(SUBSTITUTE(TRIM('수출입 실적(성질별_수입)'!E10),",","")),"") -> 3142554
A7: =TRIM('수출입 실적(성질별_수입)'!A11) -> 2024.01 | B7: =IFERROR(VALUE(LEFT($A7,4)),"") -> 2024 | C7: =IFERROR(VALUE(RIGHT($A7,2)),"") -> 1 | D7: =IFERROR(ROUNDUP($C7/3,0),"") -> 1 | E7: =TRIM('수출입 실적(성질별_수입)'!C11) -> 라. 비내구 소비재 | F7: =IFERROR(VALUE(SUBSTITUTE(TRIM('수출입 실적(성질별_수입)'!D11),",","")),"") -> 132080.3 | G7: =IFERROR(VALUE(SUBSTITUTE(TRIM('수출입 실적(성질별_수입)'!E11),",","")),"") -> 2215318
A8: =TRIM('수출입 실적(성질별_수입)'!A12) -> 2024.01 | B8: =IFERROR(VALUE(LEFT($A8,4)),"") -> 2024 | C8: =IFERROR(VALUE(RIGHT($A8,2)),"") -> 1 | D8: =IFERROR(ROUNDUP($C8/3,0),"") -> 1 | E8: =TRIM('수출입 실적(성질별_수입)'!C12) -> 마. 간이세율 적용분 | F8: =IFERROR(VALUE(SUBSTITUTE(TRIM('수출입 실적(성질별_수입)'!D12),",","")),"") -> 495.8 | G8: =IFERROR(VALUE(SUBSTITUTE(TRIM('수출입 실적(성질별_수입)'!E12),",","")),"") -> 0
A9: =TRIM('수출입 실적(성질별_수입)'!A13) -> 2024.01 | B9: =IFERROR(VALUE(LEFT($A9,4)),"") -> 2024 | C9: =IFERROR(VALUE(RIGHT($A9,2)),"") -> 1 | D9: =IFERROR(ROUNDUP($C9/3,0),"") -> 1 | E9: =TRIM('수출입 실적(성질별_수입)'!C13) -> 2. 원자재 | F9: =IFERROR(VALUE(SUBSTITUTE(TRIM('수출입 실적(성질별_수입)'!D13),",","")),"") -> 47322978 | G9: =IFERROR(VALUE(SUBSTITUTE(TRIM('수출입 실적(성질별_수입)'!E13),",","")),"") -> 28106321
A10: =TRIM('수출입 실적(성질별_수입)'!A14) -> 2024.01 | B10: =IFERROR(VALUE(LEFT($A10,4)),"") -> 2024 | C10: =IFERROR(VALUE(RIGHT($A10,2)),"") -> 1 | D10: =IFERROR(ROUNDUP($C10/3,0),"") -> 1 | E10: =TRIM('수출입 실적(성질별_수입)'!C14) -> 가. 연 료 | F10: =IFERROR(VALUE(SUBSTITUTE(TRIM('수출입 실적(성질별_수입)'!D14),",","")),"") -> 32841380 | G10: =IFERROR(VALUE(SUBSTITUTE(TRIM('수출입 실적(성질별_수입)'!E14),",","")),"") -> 15672843
A11: =TRIM('수출입 실적(성질별_수입)'!A15) -> 2024.01 | B11: =IFERROR(VALUE(LEFT($A11,4)),"") -> 2024 | C11: =IFERROR(VALUE(RIGHT($A11,2)),"") -> 1 | D11: =IFERROR(ROUNDUP($C11/3,0),"") -> 1 | E11: =TRIM('수출입 실적(성질별_수입)'!C15) -> 나. 광 물 | F11: =IFERROR(VALUE(SUBSTITUTE(TRIM('수출입 실적(성질별_수입)'!D15),",","")),"") -> 8377454.4 | G11: =IFERROR(VALUE(SUBSTITUTE(TRIM('수출입 실적(성질별_수입)'!E15),",","")),"") -> 2296169
A12: =TRIM('수출입 실적(성질별_수입)'!A16) -> 2024.01 | B12: =IFERROR(VALUE(LEFT($A12,4)),"") -> 2024 | C12: =IFERROR(VALUE(RIGHT($A12,2)),"") -> 1 | D12: =IFERROR(ROUNDUP($C12/3,0),"") -> 1 | E12: =TRIM('수출입 실적(성질별_수입)'!C16) -> 다. 경공업 원료 | F12: =IFERROR(VALUE(SUBSTITUTE(TRIM('수출입 실적(성질별_수입)'!D16),",","")),"") -> 1365869.8 | G12: =IFERROR(VALUE(SUBSTITUTE(TRIM('수출입 실적(성질별_수입)'!E16),",","")),"") -> 593012
A13: =TRIM('수출입 실적(성질별_수입)'!A17) -> 2024.01 | B13: =IFERROR(VALUE(LEFT($A13,4)),"") -> 2024 | C13: =IFERROR(VALUE(RIGHT($A13,2)),"") -> 1 | D13: =IFERROR(ROUNDUP($C13/3,0),"") -> 1 | E13: =TRIM('수출입 실적(성질별_수입)'!C17) -> 라. 유 지 | F13: =IFERROR(VALUE(SUBSTITUTE(TRIM('수출입 실적(성질별_수입)'!D17),",","")),"") -> 99230.2 | G13: =IFERROR(VALUE(SUBSTITUTE(TRIM('수출입 실적(성질별_수입)'!E17),",","")),"") -> 123085
A14: =TRIM('수출입 실적(성질별_수입)'!A18) -> 2024.01 | B14: =IFERROR(VALUE(LEFT($A14,4)),"") -> 2024 | C14: =IFERROR(VALUE(RIGHT($A14,2)),"") -> 1 | D14: =IFERROR(ROUNDUP($C14/3,0),"") -> 1 | E14: =TRIM('수출입 실적(성질별_수입)'!C18) -> 마. 섬유류 | F14: =IFERROR(VALUE(SUBSTITUTE(TRIM('수출입 실적(성질별_수입)'!D18),",","")),"") -> 105176.4 | G14: =IFERROR(VALUE(SUBSTITUTE(TRIM('수출입 실적(성질별_수입)'!E18),",","")),"") -> 317721
... A627: =TRIM('수출입 실적(성질별_수입)'!A631) -> 2026.07 | B627: =IFERROR(VALUE(LEFT($A627,4)),"") -> 2026 | C627: =IFERROR(VALUE(RIGHT($A627,2)),"") -> 7 | D627: =IFERROR(ROUNDUP($C627/3,0),"") -> 3 | E627: =TRIM('수출입 실적(성질별_수입)'!C631) -> 라. 기 타 | F627: =IFERROR(VALUE(SUBSTITUTE(TRIM('수출입 실적(성질별_수입)'!D631),",","")),"") -> 16454 | G627: =IFERROR(VALUE(SUBSTITUTE(TRIM('수출입 실적(성질별_수입)'!E631),",","")),"") -> 246617

Sheet 데이터_신성질별
A1: 이 시트의 모든 셀은 원본 시트를 참조하는 수식입니다. 원본은 숫자가 텍스트(쉼표 포함)로 저장되어 있어 VALUE/SUBSTITUTE로 숫자화했고, 연도·월·분기 열을 파생시켜 MoM/QoQ/YoY 집계가 가능하도록 했습니다. 직접 입력하지 마세요.
A2: 기간 | B2: 연도 | C2: 월 | D2: 분기 | E2: 신성질명 | F2: 수출 중량 | G2: 수출 금액 | H2: 수입 중량 | I2: 수입 금액
A3: =TRIM('수출입 실적(신성질별)'!A7) -> 2024.01 | B3: =IFERROR(VALUE(LEFT($A3,4)),"") -> 2024 | C3: =IFERROR(VALUE(RIGHT($A3,2)),"") -> 1 | D3: =IFERROR(ROUNDUP($C3/3,0),"") -> 1 | E3: =TRIM('수출입 실적(신성질별)'!B7) -> 1.소비재 | F3: =IFERROR(VALUE(SUBSTITUTE(TRIM('수출입 실적(신성질별)'!C7),",","")),"") -> 890383 | G3: =IFERROR(VALUE(SUBSTITUTE(TRIM('수출입 실적(신성질별)'!D7),",","")),"") -> 8679299 | H3: =IFERROR(VALUE(SUBSTITUTE(TRIM('수출입 실적(신성질별)'!E7),",","")),"") -> 2368995.8 | I3: =IFERROR(VALUE(SUBSTITUTE(TRIM('수출입 실적(신성질별)'!F7),",","")),"") -> 7508719
A4: =TRIM('수출입 실적(신성질별)'!A8) -> 2024.01 | B4: =IFERROR(VALUE(LEFT($A4,4)),"") -> 2024 | C4: =IFERROR(VALUE(RIGHT($A4,2)),"") -> 1 | D4: =IFERROR(ROUNDUP($C4/3,0),"") -> 1 | E4: =TRIM('수출입 실적(신성질별)'!B8) -> 가.직접소비재 | F4: =IFERROR(VALUE(SUBSTITUTE(TRIM('수출입 실적(신성질별)'!C8),",","")),"") -> 245293.6 | G4: =IFERROR(VALUE(SUBSTITUTE(TRIM('수출입 실적(신성질별)'!D8),",","")),"") -> 810359 | H4: =IFERROR(VALUE(SUBSTITUTE(TRIM('수출입 실적(신성질별)'!E8),",","")),"") -> 1996413.8 | I4: =IFERROR(VALUE(SUBSTITUTE(TRIM('수출입 실적(신성질별)'!F8),",","")),"") -> 3062773
A5: =TRIM('수출입 실적(신성질별)'!A9) -> 2024.01 | B5: =IFERROR(VALUE(LEFT($A5,4)),"") -> 2024 | C5: =IFERROR(VALUE(RIGHT($A5,2)),"") -> 1 | D5: =IFERROR(ROUNDUP($C5/3,0),"") -> 1 | E5: =TRIM('수출입 실적(신성질별)'!B9) -> 나.내구소비재 | F5: =IFERROR(VALUE(SUBSTITUTE(TRIM('수출입 실적(신성질별)'!C9),",","")),"") -> 490546.6 | G5: =IFERROR(VALUE(SUBSTITUTE(TRIM('수출입 실적(신성질별)'!D9),",","")),"") -> 6352080 | H5: =IFERROR(VALUE(SUBSTITUTE(TRIM('수출입 실적(신성질별)'!E9),",","")),"") -> 201838 | I5: =IFERROR(VALUE(SUBSTITUTE(TRIM('수출입 실적(신성질별)'!F9),",","")),"") -> 1929589
A6: =TRIM('수출입 실적(신성질별)'!A10) -> 2024.01 | B6: =IFERROR(VALUE(LEFT($A6,4)),"") -> 2024 | C6: =IFERROR(VALUE(RIGHT($A6,2)),"") -> 1 | D6: =IFERROR(ROUNDUP($C6/3,0),"") -> 1 | E6: =TRIM('수출입 실적(신성질별)'!B10) -> 다.비내구소비재 | F6: =IFERROR(VALUE(SUBSTITUTE(TRIM('수출입 실적(신성질별)'!C10),",","")),"") -> 151038 | G6: =IFERROR(VALUE(SUBSTITUTE(TRIM('수출입 실적(신성질별)'!D10),",","")),"") -> 1512572 | H6: =IFERROR(VALUE(SUBSTITUTE(TRIM('수출입 실적(신성질별)'!E10),",","")),"") -> 170248.2 | I6: =IFERROR(VALUE(SUBSTITUTE(TRIM('수출입 실적(신성질별)'!F10),",","")),"") -> 2516357
A7: =TRIM('수출입 실적(신성질별)'!A11) -> 2024.01 | B7: =IFERROR(VALUE(LEFT($A7,4)),"") -> 2024 | C7: =IFERROR(VALUE(RIGHT($A7,2)),"") -> 1 | D7: =IFERROR(ROUNDUP($C7/3,0),"") -> 1 | E7: =TRIM('수출입 실적(신성질별)'!B11) -> 라.간이세율적용분 | F7: =IFERROR(VALUE(SUBSTITUTE(TRIM('수출입 실적(신성질별)'!C11),",","")),"") -> 3504.9 | G7: =IFERROR(VALUE(SUBSTITUTE(TRIM('수출입 실적(신성질별)'!D11),",","")),"") -> 4289 | H7: =IFERROR(VALUE(SUBSTITUTE(TRIM('수출입 실적(신성질별)'!E11),",","")),"") -> 495.8 | I7: =IFERROR(VALUE(SUBSTITUTE(TRIM('수출입 실적(신성질별)'!F11),",","")),"") -> 0
A8: =TRIM('수출입 실적(신성질별)'!A12) -> 2024.01 | B8: =IFERROR(VALUE(LEFT($A8,4)),"") -> 2024 | C8: =IFERROR(VALUE(RIGHT($A8,2)),"") -> 1 | D8: =IFERROR(ROUNDUP($C8/3,0),"") -> 1 | E8: =TRIM('수출입 실적(신성질별)'!B12) -> 2.원자재 | F8: =IFERROR(VALUE(SUBSTITUTE(TRIM('수출입 실적(신성질별)'!C12),",","")),"") -> 14038084 | G8: =IFERROR(VALUE(SUBSTITUTE(TRIM('수출입 실적(신성질별)'!D12),",","")),"") -> 17436372 | H8: =IFERROR(VALUE(SUBSTITUTE(TRIM('수출입 실적(신성질별)'!E12),",","")),"") -> 48283050 | I8: =IFERROR(VALUE(SUBSTITUTE(TRIM('수출입 실적(신성질별)'!F12),",","")),"") -> 27933007
A9: =TRIM('수출입 실적(신성질별)'!A13) -> 2024.01 | B9: =IFERROR(VALUE(LEFT($A9,4)),"") -> 2024 | C9: =IFERROR(VALUE(RIGHT($A9,2)),"") -> 1 | D9: =IFERROR(ROUNDUP($C9/3,0),"") -> 1 | E9: =TRIM('수출입 실적(신성질별)'!B13) -> 가.동식물성 연·원료 | F9: =IFERROR(VALUE(SUBSTITUTE(TRIM('수출입 실적(신성질별)'!C13),",","")),"") -> 348452.9 | G9: =IFERROR(VALUE(SUBSTITUTE(TRIM('수출입 실적(신성질별)'!D13),",","")),"") -> 435996 | H9: =IFERROR(VALUE(SUBSTITUTE(TRIM('수출입 실적(신성질별)'!E13),",","")),"") -> 2872182.6 | I9: =IFERROR(VALUE(SUBSTITUTE(TRIM('수출입 실적(신성질별)'!F13),",","")),"") -> 1428481
A10: =TRIM('수출입 실적(신성질별)'!A14) -> 2024.01 | B10: =IFERROR(VALUE(LEFT($A10,4)),"") -> 2024 | C10: =IFERROR(VALUE(RIGHT($A10,2)),"") -> 1 | D10: =IFERROR(ROUNDUP($C10/3,0),"") -> 1 | E10: =TRIM('수출입 실적(신성질별)'!B14) -> 나.섬유류 | F10: =IFERROR(VALUE(SUBSTITUTE(TRIM('수출입 실적(신성질별)'!C14),",","")),"") -> 130863 | G10: =IFERROR(VALUE(SUBSTITUTE(TRIM('수출입 실적(신성질별)'!D14),",","")),"") -> 613936 | H10: =IFERROR(VALUE(SUBSTITUTE(TRIM('수출입 실적(신성질별)'!E14),",","")),"") -> 106123.8 | I10: =IFERROR(VALUE(SUBSTITUTE(TRIM('수출입 실적(신성질별)'!F14),",","")),"") -> 342160
A11: =TRIM('수출입 실적(신성질별)'!A15) -> 2024.01 | B11: =IFERROR(VALUE(LEFT($A11,4)),"") -> 2024 | C11: =IFERROR(VALUE(RIGHT($A11,2)),"") -> 1 | D11: =IFERROR(ROUNDUP($C11/3,0),"") -> 1 | E11: =TRIM('수출입 실적(신성질별)'!B15) -> 다.광산물 | F11: =IFERROR(VALUE(SUBSTITUTE(TRIM('수출입 실적(신성질별)'!C15),",","")),"") -> 6716263.2 | G11: =IFERROR(VALUE(SUBSTITUTE(TRIM('수출입 실적(신성질별)'!D15),",","")),"") -> 5478639 | H11: =IFERROR(VALUE(SUBSTITUTE(TRIM('수출입 실적(신성질별)'!E15),",","")),"") -> 41389665 | I11: =IFERROR(VALUE(SUBSTITUTE(TRIM('수출입 실적(신성질별)'!F15),",","")),"") -> 18384560
A12: =TRIM('수출입 실적(신성질별)'!A16) -> 2024.01 | B12: =IFERROR(VALUE(LEFT($A12,4)),"") -> 2024 | C12: =IFERROR(VALUE(RIGHT($A12,2)),"") -> 1 | D12: =IFERROR(ROUNDUP($C12/3,0),"") -> 1 | E12: =TRIM('수출입 실적(신성질별)'!B16) -> 라.철강 및 금속제품 | F12: =IFERROR(VALUE(SUBSTITUTE(TRIM('수출입 실적(신성질별)'!C16),",","")),"") -> 2568224.3 | G12: =IFERROR(VALUE(SUBSTITUTE(TRIM('수출입 실적(신성질별)'!D16),",","")),"") -> 3358972 | H12: =IFERROR(VALUE(SUBSTITUTE(TRIM('수출입 실적(신성질별)'!E16),",","")),"") -> 1949849.1 | I12: =IFERROR(VALUE(SUBSTITUTE(TRIM('수출입 실적(신성질별)'!F16),",","")),"") -> 2827181
A13: =TRIM('수출입 실적(신성질별)'!A17) -> 2024.01 | B13: =IFERROR(VALUE(LEFT($A13,4)),"") -> 2024 | C13: =IFERROR(VALUE(RIGHT($A13,2)),"") -> 1 | D13: =IFERROR(ROUNDUP($C13/3,0),"") -> 1 | E13: =TRIM('수출입 실적(신성질별)'!B17) -> 마.화학공업제품 | F13: =IFERROR(VALUE(SUBSTITUTE(TRIM('수출입 실적(신성질별)'!C17),",","")),"") -> 4270890.6 | G13: =IFERROR(VALUE(SUBSTITUTE(TRIM('수출입 실적(신성질별)'!D17),",","")),"") -> 7536310 | H13: =IFERROR(VALUE(SUBSTITUTE(TRIM('수출입 실적(신성질별)'!E17),",","")),"") -> 1961851.4 | I13: =IFERROR(VALUE(SUBSTITUTE(TRIM('수출입 실적(신성질별)'!F17),",","")),"") -> 4943661
A14: =TRIM('수출입 실적(신성질별)'!A18) -> 2024.01 | B14: =IFERROR(VALUE(LEFT($A14,4)),"") -> 2024 | C14: =IFERROR(VALUE(RIGHT($A14,2)),"") -> 1 | D14: =IFERROR(ROUNDUP($C14/3,0),"") -> 1 | E14: =TRIM('수출입 실적(신성질별)'!B18) -> 바.기타 원자재 | F14: =IFERROR(VALUE(SUBSTITUTE(TRIM('수출입 실적(신성질별)'!C18),",","")),"") -> 3390.1 | G14: =IFERROR(VALUE(SUBSTITUTE(TRIM('수출입 실적(신성질별)'!D18),",","")),"") -> 12520 | H14: =IFERROR(VALUE(SUBSTITUTE(TRIM('수출입 실적(신성질별)'!E18),",","")),"") -> 3377.7 | I14: =IFERROR(VALUE(SUBSTITUTE(TRIM('수출입 실적(신성질별)'!F18),",","")),"") -> 6963
... A529: =TRIM('수출입 실적(신성질별)'!A533) -> 2026.07 | B529: =IFERROR(VALUE(LEFT($A529,4)),"") -> 2026 | C529: =IFERROR(VALUE(RIGHT($A529,2)),"") -> 7 | D529: =IFERROR(ROUNDUP($C529/3,0),"") -> 3 | E529: =TRIM('수출입 실적(신성질별)'!B533) -> 라.IT부품 | F529: =IFERROR(VALUE(SUBSTITUTE(TRIM('수출입 실적(신성질별)'!C533),",","")),"") -> 33481.3 | G529: =IFERROR(VALUE(SUBSTITUTE(TRIM('수출입 실적(신성질별)'!D533),",","")),"") -> 42761535 | H529: =IFERROR(VALUE(SUBSTITUTE(TRIM('수출입 실적(신성질별)'!E533),",","")),"") -> 33712.5 | I529: =IFERROR(VALUE(SUBSTITUTE(TRIM('수출입 실적(신성질별)'!F533),",","")),"") -> 11667986

Sheet 분석1_정합성검증
A1: ① 합계 정합성 검증 — 개별항목의 합 vs 총합 (5개 원본 시트 교차)
A2: 원본은 숫자가 텍스트로 저장되어 있어 「데이터_○○」 정제 시트(수식)를 거쳐 검증합니다. 원본 시트는 수정하지 않았습니다. 기간 : 2024.01~2026.07(31개월).
A3: 허용오차(중량, 톤) | B3: 1 | C3: 허용오차(금액, 천달러) | D3: 50 | E3: 품목별 허용오차 | F3: 500
A5: [검증 1] 「수출입 총괄」 총계행 vs 31개월 합계
A6: 항목 | B6: 총계행(원본) | C6: 월별 합계 | D6: 차이 | E6: 판정
A7: 조업일수 | B7: =IFERROR(VALUE(SUBSTITUTE(TRIM('수출입 총괄'!B6),",","")),"") -> 695.5 | C7: =SUM(데이터_총괄!$E$3:$E$33) -> 695.5 | D7: =B7-C7 -> 0 | E7: =IF(ABS(D7)<=$B$3,"일치(반올림오차 이내)","불일치") -> 일치(반올림오차 이내)
A8: 수출 건수 | B8: =IFERROR(VALUE(SUBSTITUTE(TRIM('수출입 총괄'!C6),",","")),"") -> 34342880 | C8: =SUM(데이터_총괄!$F$3:$F$33) -> 34342880 | D8: =B8-C8 -> 0 | E8: =IF(ABS(D8)<=$D$3,"일치(반올림오차 이내)","불일치") -> 일치(반올림오차 이내)
A9: 수출 중량(톤) | B9: =IFERROR(VALUE(SUBSTITUTE(TRIM('수출입 총괄'!D6),",","")),"") -> 5.0565592e+08 | C9: =SUM(데이터_총괄!$G$3:$G$33) -> 5.0565592e+08 | D9: =B9-C9 -> -0.30000001 | E9: =IF(ABS(D9)<=$B$3,"일치(반올림오차 이내)","불일치") -> 일치(반올림오차 이내)
A10: 수출 금액(천$) | B10: =IFERROR(VALUE(SUBSTITUTE(TRIM('수출입 총괄'!E6),",","")),"") -> 1988002368 | C10: =SUM(데이터_총괄!$H$3:$H$33) -> 1988002368 | D10: =B10-C10 -> 0 | E10: =IF(ABS(D10)<=$D$3,"일치(반올림오차 이내)","불일치") -> 일치(반올림오차 이내)
A11: 수입 건수 | B11: =IFERROR(VALUE(SUBSTITUTE(TRIM('수출입 총괄'!F6),",","")),"") -> 141143449 | C11: =SUM(데이터_총괄!$I$3:$I$33) -> 141143449 | D11: =B11-C11 -> 0 | E11: =IF(ABS(D11)<=$D$3,"일치(반올림오차 이내)","불일치") -> 일치(반올림오차 이내)
A12: 수입 중량(톤) | B12: =IFERROR(VALUE(SUBSTITUTE(TRIM('수출입 총괄'!G6),",","")),"") -> 1.414626e+09 | C12: =SUM(데이터_총괄!$J$3:$J$33) -> 1414626021 | D12: =B12-C12 -> -0.099999905 | E12: =IF(ABS(D12)<=$B$3,"일치(반올림오차 이내)","불일치") -> 일치(반올림오차 이내)
A13: 수입 금액(천$) | B13: =IFERROR(VALUE(SUBSTITUTE(TRIM('수출입 총괄'!H6),",","")),"") -> 1690965721 | C13: =SUM(데이터_총괄!$K$3:$K$33) -> 1690965722 | D13: =B13-C13 -> -1 | E13: =IF(ABS(D13)<=$D$3,"일치(반올림오차 이내)","불일치") -> 일치(반올림오차 이내)
A14: 무역수지(천$) | B14: =IFERROR(VALUE(SUBSTITUTE(TRIM('수출입 총괄'!I6),",","")),"") -> 297036647 | C14: =SUM(데이터_총괄!$L$3:$L$33) -> 297036646 | D14: =B14-C14 -> 1 | E14: =IF(ABS(D14)<=$D$3,"일치(반올림오차 이내)","불일치") -> 일치(반올림오차 이내)
A16: [검증 2] 무역수지 항등식 및 시트 간 교차검증 (31개월 총계)
A17: 구분 | B17: 수출 금액 | C17: 수입 금액 | D17: 무역수지 | E17: 수출 중량 | F17: 비고
A18: 수출입 총괄 | B18: =SUM(데이터_총괄!$H$3:$H$33) -> 1988002368 | C18: =SUM(데이터_총괄!$K$3:$K$33) -> 1690965722 | D18: =B18-C18 -> 297036646 | E18: =SUM(데이터_총괄!$G$3:$G$33) -> 5.0565592e+08 | F18: 기준값
A19: 성질별(수출) | B19: =SUMIFS(데이터_성질별수출!$G$3:$G$653,데이터_성질별수출!$E$3:$E$653,"1. 식료 및 직접소비재")+SUMIFS(데이터_성질별수출!$G$3:$G$653,데이터_성질별수출!$E$3:$E$653,"2. 원료 및 연료")+SUMIFS(데이터_성질별수출!$G$3:$G$653,데이터_성질별수출!$E$3:$E$653,"3. 경공업품")+SUMIFS(데이터_성질별수출!$G$3:$G$653,데이터_성질별수출!$E$3:$E$653,"4. 중화학 공업품") -> 1988002371 | C19: - | D19: - | E19: =SUMIFS(데이터_성질별수출!$F$3:$F$653,데이터_성질별수출!$E$3:$E$653,"1. 식료 및 직접소비재")+SUMIFS(데이터_성질별수출!$F$3:$F$653,데이터_성질별수출!$E$3:$E$653,"2. 원료 및 연료")+SUMIFS(데이터_성질별수출!$F$3:$F$653,데이터_성질별수출!$E$3:$E$653,"3. 경공업품")+SUMIFS(데이터_성질별수출!$F$3:$F$653,데이터_성질별수출!$E$3:$E$653,"4. 중화학 공업품") -> 5.0565592e+08 | F19: 대분류 4개 합계
A20: 성질별(수입) | B20: - | C20: =SUMIFS(데이터_성질별수입!$G$3:$G$627,데이터_성질별수입!$E$3:$E$627,"1. 소비재")+SUMIFS(데이터_성질별수입!$G$3:$G$627,데이터_성질별수입!$E$3:$E$627,"2. 원자재")+SUMIFS(데이터_성질별수입!$G$3:$G$627,데이터_성질별수입!$E$3:$E$627,"3. 자본재") -> 1690965721 | D20: - | E20: - | F20: 대분류 3개 합계
A21: 신성질별 | B21: =SUMIFS(데이터_신성질별!$G$3:$G$529,데이터_신성질별!$E$3:$E$529,"1.소비재")+SUMIFS(데이터_신성질별!$G$3:$G$529,데이터_신성질별!$E$3:$E$529,"2.원자재")+SUMIFS(데이터_신성질별!$G$3:$G$529,데이터_신성질별!$E$3:$E$529,"3.자본재") -> 1988002373 | C21: =SUMIFS(데이터_신성질별!$I$3:$I$529,데이터_신성질별!$E$3:$E$529,"1.소비재")+SUMIFS(데이터_신성질별!$I$3:$I$529,데이터_신성질별!$E$3:$E$529,"2.원자재")+SUMIFS(데이터_신성질별!$I$3:$I$529,데이터_신성질별!$E$3:$E$529,"3.자본재") -> 1690965721 | D21: =B21-C21 -> 297036652 | E21: =SUMIFS(데이터_신성질별!$F$3:$F$529,데이터_신성질별!$E$3:$E$529,"1.소비재")+SUMIFS(데이터_신성질별!$F$3:$F$529,데이터_신성질별!$E$3:$E$529,"2.원자재")+SUMIFS(데이터_신성질별!$F$3:$F$529,데이터_신성질별!$E$3:$E$529,"3.자본재") -> 5.0565592e+08 | F21: 대분류 3개 합계
A22: 품목별(HS) | B22: =SUM(데이터_품목별!$H$3:$H$2984) -> 1987154609 | C22: =SUM(데이터_품목별!$J$3:$J$2984) -> 1690339727 | D22: =B22-C22 -> 296814882 | E22: =SUM(데이터_품목별!$G$3:$G$2984) -> 5.0480808e+08 | F22: HS 01~97·99류만 → 과소
A23: 총괄 대비 최대 차이 | B23: =MAX(ABS(B19-B18),ABS(B21-B18)) -> 5 | C23: =MAX(ABS(C20-C18),ABS(C21-C18)) -> 1 | D23: =ABS(D21-D18) -> 6 | E23: =MAX(ABS(E19-E18),ABS(E21-E18)) -> 0.5 | F23: 품목별 제외 기준
A24: 판정 | B24: =IF(B23<=$D$3,"일치","불일치") -> 일치 | C24: =IF(C23<=$D$3,"일치","불일치") -> 일치 | D24: =IF(D23<=$D$3,"일치","불일치") -> 일치 | E24: =IF(E23<=$B$3,"일치","불일치") -> 일치
A26: [검증 3] 「품목별(HS)」 합 vs 「총괄」 — 연도별 차이
A27: 연도 | B27: 품목별 수출 합 | C27: 총괄 수출금액 | D27: 차이 | E27: 차이 비율 | F27: 품목별 수입 합 | G27: 총괄 수입금액 | H27: 차이 | I27: 차이 비율
A28: 2024 | B28: =SUMIFS(데이터_품목별!$H$3:$H$2984,데이터_품목별!$B$3:$B$2984,$A28) -> 683261188 | C28: =SUMIFS(데이터_총괄!$H$3:$H$33,데이터_총괄!$B$3:$B$33,$A28) -> 683609488 | D28: =B28-C28 -> -348300 | E28: =D28/C28 -> -0.00050950141 | F28: =SUMIFS(데이터_품목별!$J$3:$J$2984,데이터_품목별!$B$3:$B$2984,$A28) -> 631525501 | G28: =SUMIFS(데이터_총괄!$K$3:$K$33,데이터_총괄!$B$3:$B$33,$A28) -> 631767209 | H28: =F28-G28 -> -241708 | I28: =H28/G28 -> -0.00038259029
A29: 2025 | B29: =SUMIFS(데이터_품목별!$H$3:$H$2984,데이터_품목별!$B$3:$B$2984,$A29) -> 709033003 | C29: =SUMIFS(데이터_총괄!$H$3:$H$33,데이터_총괄!$B$3:$B$33,$A29) -> 709330044 | D29: =B29-C29 -> -297041 | E29: =D29/C29 -> -0.00041876275 | F29: =SUMIFS(데이터_품목별!$J$3:$J$2984,데이터_품목별!$B$3:$B$2984,$A29) -> 631700945 | G29: =SUMIFS(데이터_총괄!$K$3:$K$33,데이터_총괄!$B$3:$B$33,$A29) -> 631895368 | H29: =F29-G29 -> -194423 | I29: =H29/G29 -> -0.00030768227
A30: 2026 | B30: =SUMIFS(데이터_품목별!$H$3:$H$2984,데이터_품목별!$B$3:$B$2984,$A30) -> 594860418 | C30: =SUMIFS(데이터_총괄!$H$3:$H$33,데이터_총괄!$B$3:$B$33,$A30) -> 595062836 | D30: =B30-C30 -> -202418 | E30: =D30/C30 -> -0.0003401624 | F30: =SUMIFS(데이터_품목별!$J$3:$J$2984,데이터_품목별!$B$3:$B$2984,$A30) -> 427113281 | G30: =SUMIFS(데이터_총괄!$K$3:$K$33,데이터_총괄!$B$3:$B$33,$A30) -> 427303145 | H30: =F30-G30 -> -189864 | I30: =H30/G30 -> -0.00044433092
A31: ★ 품목별 시트는 총괄보다 매년 0.03~0.05% 작습니다. 이 시트에 실제로 존재하는 HS류는 01~97류 중 96개(77류는 HS 결번)와 값이 대부분 0인 99류뿐이고, 98류(특수분류 — 여행자 휴대품·별송품·소액물품 등)가 통째로 빠져 있습니다. 품목 간 비교·순위 분석에는 영향이 없으나 총액 인용 시에는 총괄 시트를 쓰십시오.
A33: [검증 4] 월별 항등식 (수출−수입=수지) 및 성질별 대분류 합 검증
A34: 기간 | B34: 수출−수입 | C34: 원본 수지 | D34: 차이 | E34: 성질별(수출) 대분류합 | F34: 총괄 수출 | G34: 차이 | H34: 신성질별 수입 합 | I34: 총괄 수입 | J34: 차이
A35: =데이터_총괄!A3 -> 2024.01 | B35: =데이터_총괄!H3-데이터_총괄!K3 -> 235212 | C35: =데이터_총괄!L3 -> 235213 | D35: =B35-C35 -> -1 | E35: =SUMIFS(데이터_성질별수출!$G$3:$G$653,데이터_성질별수출!$E$3:$E$653,"1. 식료 및 직접소비재",데이터_성질별수출!$A$3:$A$653,$A35)+SUMIFS(데이터_성질별수출!$G$3:$G$653,데이터_성질별수출!$E$3:$E$653,"2. 원료 및 연료",데이터_성질별수출!$A$3:$A$653,$A35)+SUMIFS(데이터_성질별수출!$G$3:$G$653,데이터_성질별수출!$E$3:$E$653,"3. 경공업품",데이터_성질별수출!$A$3:$A$653,$A35)+SUMIFS(데이터_성질별수출!$G$3:$G$653,데이터_성질별수출!$E$3:$E$653,"4. 중화학 공업품",데이터_성질별수출!$A$3:$A$653,$A35) -> 54709824 | F35: =데이터_총괄!H3 -> 54709823 | G35: =E35-F35 -> 1 | H35: =SUMIFS(데이터_신성질별!$I$3:$I$529,데이터_신성질별!$E$3:$E$529,"1.소비재",데이터_신성질별!$A$3:$A$529,$A35)+SUMIFS(데이터_신성질별!$I$3:$I$529,데이터_신성질별!$E$3:$E$529,"2.원자재",데이터_신성질별!$A$3:$A$529,$A35)+SUMIFS(데이터_신성질별!$I$3:$I$529,데이터_신성질별!$E$3:$E$529,"3.자본재",데이터_신성질별!$A$3:$A$529,$A35) -> 54474611 | I35: =데이터_총괄!K3 -> 54474611 | J35: =H35-I35 -> 0
A36: =데이터_총괄!A4 -> 2024.02 | B36: =데이터_총괄!H4-데이터_총괄!K4 -> 3854530 | C36: =데이터_총괄!L4 -> 3854529 | D36: =B36-C36 -> 1 | E36: =SUMIFS(데이터_성질별수출!$G$3:$G$653,데이터_성질별수출!$E$3:$E$653,"1. 식료 및 직접소비재",데이터_성질별수출!$A$3:$A$653,$A36)+SUMIFS(데이터_성질별수출!$G$3:$G$653,데이터_성질별수출!$E$3:$E$653,"2. 원료 및 연료",데이터_성질별수출!$A$3:$A$653,$A36)+SUMIFS(데이터_성질별수출!$G$3:$G$653,데이터_성질별수출!$E$3:$E$653,"3. 경공업품",데이터_성질별수출!$A$3:$A$653,$A36)+SUMIFS(데이터_성질별수출!$G$3:$G$653,데이터_성질별수출!$E$3:$E$653,"4. 중화학 공업품",데이터_성질별수출!$A$3:$A$653,$A36) -> 52076390 | F36: =데이터_총괄!H4 -> 52076390 | G36: =E36-F36 -> 0 | H36: =SUMIFS(데이터_신성질별!$I$3:$I$529,데이터_신성질별!$E$3:$E$529,"1.소비재",데이터_신성질별!$A$3:$A$529,$A36)+SUMIFS(데이터_신성질별!$I$3:$I$529,데이터_신성질별!$E$3:$E$529,"2.원자재",데이터_신성질별!$A$3:$A$529,$A36)+SUMIFS(데이터_신성질별!$I$3:$I$529,데이터_신성질별!$E$3:$E$529,"3.자본재",데이터_신성질별!$A$3:$A$529,$A36) -> 48221861 | I36: =데이터_총괄!K4 -> 48221860 | J36: =H36-I36 -> 1
A37: =데이터_총괄!A5 -> 2024.03 | B37: =데이터_총괄!H5-데이터_총괄!K5 -> 4405404 | C37: =데이터_총괄!L5 -> 4405404 | D37: =B37-C37 -> 0 | E37: =SUMIFS(데이터_성질별수출!$G$3:$G$653,데이터_성질별수출!$E$3:$E$653,"1. 식료 및 직접소비재",데이터_성질별수출!$A$3:$A$653,$A37)+SUMIFS(데이터_성질별수출!$G$3:$G$653,데이터_성질별수출!$E$3:$E$653,"2. 원료 및 연료",데이터_성질별수출!$A$3:$A$653,$A37)+SUMIFS(데이터_성질별수출!$G$3:$G$653,데이터_성질별수출!$E$3:$E$653,"3. 경공업품",데이터_성질별수출!$A$3:$A$653,$A37)+SUMIFS(데이터_성질별수출!$G$3:$G$653,데이터_성질별수출!$E$3:$E$653,"4. 중화학 공업품",데이터_성질별수출!$A$3:$A$653,$A37) -> 56518309 | F37: =데이터_총괄!H5 -> 56518309 | G37: =E37-F37 -> 0 | H37: =SUMIFS(데이터_신성질별!$I$3:$I$529,데이터_신성질별!$E$3:$E$529,"1.소비재",데이터_신성질별!$A$3:$A$529,$A37)+SUMIFS(데이터_신성질별!$I$3:$I$529,데이터_신성질별!$E$3:$E$529,"2.원자재",데이터_신성질별!$A$3:$A$529,$A37)+SUMIFS(데이터_신성질별!$I$3:$I$529,데이터_신성질별!$E$3:$E$529,"3.자본재",데이터_신성질별!$A$3:$A$529,$A37) -> 52112905 | I37: =데이터_총괄!K5 -> 52112905 | J37: =H37-I37 -> 0
A38: =데이터_총괄!A6 -> 2024.04 | B38: =데이터_총괄!H6-데이터_총괄!K6 -> 1327118 | C38: =데이터_총괄!L6 -> 1327118 | D38: =B38-C38 -> 0 | E38: =SUMIFS(데이터_성질별수출!$G$3:$G$653,데이터_성질별수출!$E$3:$E$653,"1. 식료 및 직접소비재",데이터_성질별수출!$A$3:$A$653,$A38)+SUMIFS(데이터_성질별수출!$G$3:$G$653,데이터_성질별수출!$E$3:$E$653,"2. 원료 및 연료",데이터_성질별수출!$A$3:$A$653,$A38)+SUMIFS(데이터_성질별수출!$G$3:$G$653,데이터_성질별수출!$E$3:$E$653,"3. 경공업품",데이터_성질별수출!$A$3:$A$653,$A38)+SUMIFS(데이터_성질별수출!$G$3:$G$653,데이터_성질별수출!$E$3:$E$653,"4. 중화학 공업품",데이터_성질별수출!$A$3:$A$653,$A38) -> 56148300 | F38: =데이터_총괄!H6 -> 56148299 | G38: =E38-F38 -> 1 | H38: =SUMIFS(데이터_신성질별!$I$3:$I$529,데이터_신성질별!$E$3:$E$529,"1.소비재",데이터_신성질별!$A$3:$A$529,$A38)+SUMIFS(데이터_신성질별!$I$3:$I$529,데이터_신성질별!$E$3:$E$529,"2.원자재",데이터_신성질별!$A$3:$A$529,$A38)+SUMIFS(데이터_신성질별!$I$3:$I$529,데이터_신성질별!$E$3:$E$529,"3.자본재",데이터_신성질별!$A$3:$A$529,$A38) -> 54821181 | I38: =데이터_총괄!K6 -> 54821181 | J38: =H38-I38 -> 0
A39: =데이터_총괄!A7 -> 2024.05 | B39: =데이터_총괄!H7-데이터_총괄!K7 -> 4887620 | C39: =데이터_총괄!L7 -> 4887620 | D39: =B39-C39 -> 0 | E39: =SUMIFS(데이터_성질별수출!$G$3:$G$653,데이터_성질별수출!$E$3:$E$653,"1. 식료 및 직접소비재",데이터_성질별수출!$A$3:$A$653,$A39)+SUMIFS(데이터_성질별수출!$G$3:$G$653,데이터_성질별수출!$E$3:$E$653,"2. 원료 및 연료",데이터_성질별수출!$A$3:$A$653,$A39)+SUMIFS(데이터_성질별수출!$G$3:$G$653,데이터_성질별수출!$E$3:$E$653,"3. 경공업품",데이터_성질별수출!$A$3:$A$653,$A39)+SUMIFS(데이터_성질별수출!$G$3:$G$653,데이터_성질별수출!$E$3:$E$653,"4. 중화학 공업품",데이터_성질별수출!$A$3:$A$653,$A39) -> 58020557 | F39: =데이터_총괄!H7 -> 58020557 | G39: =E39-F39 -> 0 | H39: =SUMIFS(데이터_신성질별!$I$3:$I$529,데이터_신성질별!$E$3:$E$529,"1.소비재",데이터_신성질별!$A$3:$A$529,$A39)+SUMIFS(데이터_신성질별!$I$3:$I$529,데이터_신성질별!$E$3:$E$529,"2.원자재",데이터_신성질별!$A$3:$A$529,$A39)+SUMIFS(데이터_신성질별!$I$3:$I$529,데이터_신성질별!$E$3:$E$529,"3.자본재",데이터_신성질별!$A$3:$A$529,$A39) -> 53132937 | I39: =데이터_총괄!K7 -> 53132937 | J39: =H39-I39 -> 0
A40: =데이터_총괄!A8 -> 2024.06 | B40: =데이터_총괄!H8-데이터_총괄!K8 -> 8251441 | C40: =데이터_총괄!L8 -> 8251441 | D40: =B40-C40 -> 0 | E40: =SUMIFS(데이터_성질별수출!$G$3:$G$653,데이터_성질별수출!$E$3:$E$653,"1. 식료 및 직접소비재",데이터_성질별수출!$A$3:$A$653,$A40)+SUMIFS(데이터_성질별수출!$G$3:$G$653,데이터_성질별수출!$E$3:$E$653,"2. 원료 및 연료",데이터_성질별수출!$A$3:$A$653,$A40)+SUMIFS(데이터_성질별수출!$G$3:$G$653,데이터_성질별수출!$E$3:$E$653,"3. 경공업품",데이터_성질별수출!$A$3:$A$653,$A40)+SUMIFS(데이터_성질별수출!$G$3:$G$653,데이터_성질별수출!$E$3:$E$653,"4. 중화학 공업품",데이터_성질별수출!$A$3:$A$653,$A40) -> 57341635 | F40: =데이터_총괄!H8 -> 57341634 | G40: =E40-F40 -> 1 | H40: =SUMIFS(데이터_신성질별!$I$3:$I$529,데이터_신성질별!$E$3:$E$529,"1.소비재",데이터_신성질별!$A$3:$A$529,$A40)+SUMIFS(데이터_신성질별!$I$3:$I$529,데이터_신성질별!$E$3:$E$529,"2.원자재",데이터_신성질별!$A$3:$A$529,$A40)+SUMIFS(데이터_신성질별!$I$3:$I$529,데이터_신성질별!$E$3:$E$529,"3.자본재",데이터_신성질별!$A$3:$A$529,$A40) -> 49090194 | I40: =데이터_총괄!K8 -> 49090193 | J40: =H40-I40 -> 1
A41: =데이터_총괄!A9 -> 2024.07 | B41: =데이터_총괄!H9-데이터_총괄!K9 -> 3620046 | C41: =데이터_총괄!L9 -> 3620046 | D41: =B41-C41 -> 0 | E41: =SUMIFS(데이터_성질별수출!$G$3:$G$653,데이터_성질별수출!$E$3:$E$653,"1. 식료 및 직접소비재",데이터_성질별수출!$A$3:$A$653,$A41)+SUMIFS(데이터_성질별수출!$G$3:$G$653,데이터_성질별수출!$E$3:$E$653,"2. 원료 및 연료",데이터_성질별수출!$A$3:$A$653,$A41)+SUMIFS(데이터_성질별수출!$G$3:$G$653,데이터_성질별수출!$E$3:$E$653,"3. 경공업품",데이터_성질별수출!$A$3:$A$653,$A41)+SUMIFS(데이터_성질별수출!$G$3:$G$653,데이터_성질별수출!$E$3:$E$653,"4. 중화학 공업품",데이터_성질별수출!$A$3:$A$653,$A41) -> 57458788 | F41: =데이터_총괄!H9 -> 57458788 | G41: =E41-F41 -> 0 | H41: =SUMIFS(데이터_신성질별!$I$3:$I$529,데이터_신성질별!$E$3:$E$529,"1.소비재",데이터_신성질별!$A$3:$A$529,$A41)+SUMIFS(데이터_신성질별!$I$3:$I$529,데이터_신성질별!$E$3:$E$529,"2.원자재",데이터_신성질별!$A$3:$A$529,$A41)+SUMIFS(데이터_신성질별!$I$3:$I$529,데이터_신성질별!$E$3:$E$529,"3.자본재",데이터_신성질별!$A$3:$A$529,$A41) -> 53838742 | I41: =데이터_총괄!K9 -> 53838742 | J41: =H41-I41 -> 0
