Workbook

Sheet 0_안내
A1: 수출입 실적 통합 분석 (2025.01 ~ 2026.07)
A2: 업로드하신 5개 원본 파일(총괄·품목별·성질별·신성질별·국가별)을 한 파일로 모으고, 원본은 수정하지 않은 채 분석 시트를 추가했습니다.
A4: 시트 구성
A5: 시트 | B5: 내용 | C5: 비고
A6: 수출입 총괄 | B6: 2025.01~2026.07 월별 총괄 (원본 그대로) | C6: 원본 · 수정 없음
A7: 수출입 실적(품목별) | B7: HS 2단위 품목별 수출입 (원본 그대로) | C7: 원본 · 수정 없음
A8: 수출입 실적(성질별) | B8: 성질별 수출 (원본 그대로) | C8: 원본 · 수정 없음
A9: 수출입 실적(신성질별) | B9: 신성질별 수출입 (원본 그대로) | C9: 원본 · 수정 없음
A10: 수출입 실적(국가별) | B10: 국가별 수출입 (원본 그대로) | C10: 원본 · 수정 없음
A11: 데이터_총괄 외 4개 | B11: 원본의 텍스트 숫자를 VALUE 수식으로 숫자화한 정제 시트 | C11: 전부 수식 · 직접 입력 금지
A12: 분석1_정합성검증 | B12: 개별항목 합 vs 총합 9종 검증 | C12: 품목별 시트의 체계적 차이 확인
A13: 분석2_월별추이 | B13: 19개월 추이 · 전월비 · 전년동월비 · 일평균 · 단가 · 12개월 이동합
A14: 분석3_전년동기비교 | B14: 2026.1~7 vs 2025.1~7 (총괄 · 성질별 · 신성질별 수출입)
A15: 분석4_품목별(HS) | B15: HS류별 동기 비교 · 기여도 · 무역수지 | C15: 상위 8개 월별 표 포함
A16: 분석5_국가별 | B16: 상위 40개국 + 기타 · 점유율 · 무역수지 | C16: 집중도 추이 포함
A17: 분석6_그래프 | B17: 그래프 13종 + 보조표
A18: 분석7_해설 | B18: 핵심 수치표와 해석 · 한계 | C18: 먼저 읽으시면 좋습니다
A20: 읽는 순서 제안
A21: ① 분석7_해설 — 무엇이 어떻게 변했는지 먼저 확인
A22: ② 분석1_정합성검증 — 숫자를 믿어도 되는지 확인 (품목별 시트 주의사항 포함)
A23: ③ 분석2 → 분석3 → 분석4·5 — 총량에서 품목·국가로 좁혀 가며 확인
A24: ④ 분석6_그래프 — 그림으로 확인
A26: ※ 모든 분석 셀은 원본을 참조하는 수식입니다. 원본 시트에 다음 달 데이터를 같은 형식으로 추가하고 정제 시트의 참조 범위를 늘리면 분석 전체가 그대로 갱신됩니다.

Sheet 수출입 총괄
A1: 수출입 총괄
A3: 검색조건 조회기간: 202501 ~ 202607 , 통계기준: 수리일, 중량단위: 톤
I4: 단위:건, 톤(TON), 천 달러
A5: 기간 | B5: 조업일수 | C5: 수출 건수 | D5: 수출 중량 | E5: 수출 금액 | F5: 수입 건수 | G5: 수입중량 | H5: 수입금액 | I5: 무역수지
A6: 총계 | B6: 425.0 | C6: 21,702,845 | D6: 308,412,746.2 | E6: 1,304,392,880 | F6: 88,995,973 | G6: 858,381,643.6 | H6: 1,059,198,512 | I6: 245,194,368
A7: 2025.01 | B7: 20.0 | C7: 924,441 | D7: 14,986,301.7 | E7: 49,176,984 | F7: 3,847,092 | G7: 47,927,337.6 | H7: 51,172,292 | I7: -1,995,308
A8: 2025.02 | B8: 22.0 | C8: 1,014,431 | D8: 16,151,895.1 | E8: 52,292,301 | F8: 3,982,365 | G8: 41,535,200.5 | H8: 48,328,741 | I8: 3,963,560
A9: 2025.03 | B9: 22.0 | C9: 1,236,266 | D9: 15,702,059.6 | E9: 58,064,562 | F9: 4,558,238 | G9: 41,960,252.6 | H9: 53,341,032 | I9: 4,723,530
A10: 2025.04 | B10: 24.0 | C10: 1,088,160 | D10: 17,527,804.9 | E10: 58,035,745 | F10: 4,601,632 | G10: 45,256,630.0 | H10: 53,232,716 | I10: 4,803,029
A11: 2025.05 | B11: 21.5 | C11: 1,034,785 | D11: 16,573,462.9 | E11: 57,261,063 | F11: 4,586,252 | G11: 43,030,473.8 | H11: 50,345,116 | I11: 6,915,946
A12: 2025.06 | B12: 21.0 | C12: 1,328,545 | D12: 16,221,157.0 | E12: 59,833,797 | F12: 4,272,361 | G12: 42,728,885.3 | H12: 50,825,746 | I12: 9,008,051
A13: 2025.07 | B13: 25.0 | C13: 1,177,196 | D13: 17,580,838.3 | E13: 60,724,322 | F13: 4,754,616 | G13: 47,540,216.0 | H13: 54,210,371 | I13: 6,513,951
A14: 2025.08 | B14: 22.5 | C14: 1,058,881 | D14: 17,118,673.9 | E14: 58,259,332 | F14: 4,524,180 | G14: 48,641,920.6 | H14: 51,856,624 | I14: 6,402,708
A15: 2025.09 | B15: 24.0 | C15: 1,451,822 | D15: 18,076,703.2 | E15: 65,904,118 | F15: 4,986,893 | G15: 47,278,338.2 | H15: 56,419,614 | I15: 9,484,504
A16: 2025.10 | B16: 20.0 | C16: 1,040,165 | D16: 16,017,317.9 | E16: 59,511,578 | F16: 4,655,160 | G16: 47,575,893.6 | H16: 53,510,827 | I16: 6,000,751
... A25: 2026.07 | B25: 24.0 | C25: 1,111,934 | D25: 17,660,680.7 | E25: 98,959,099 | F25: 5,158,848 | G25: 51,144,176.2 | H25: 68,567,473 | I25: 30,391,625

Sheet 수출입 실적(품목별)
A1: 수출입 실적(품목별)
A3: 검색조건 통계항목 : 품목별, 품목명 : 전체, 하위품목 유무 : 무, 조회기간 : 202501 ~ 202607 , 통계기준 : 수리일, 중량단위 : 톤
H4: 단위:톤(TON), 천 달러
A5: 기간 | B5: HS코드 | C5: 품목명 | D5: 수출 중량 | E5: 수출 금액 | F5: 수입 중량 | G5: 수입 금액 | H5: 무역수지
A6: 총계 | D6: 307,894,107.1 | E6: 1,303,893,423 | F6: 857,408,459.5 | G6: 1,058,814,212 | H6: 245,079,211
A7: 2025.01 | B7: 01 | C7: 살아 있는 동물 | D7: 3.4 | E7: 511 | F7: 44.7 | G7: 4,460 | H7: -3,948
A8: 2025.01 | B8: 02 | C8: 육과 식용 설육(屑肉) | D8: 4,211.3 | E8: 5,868 | F8: 128,765.3 | G8: 728,984 | H8: -723,116
A9: 2025.01 | B9: 03 | C9: 어류ㆍ갑각류ㆍ연체동물과 그 밖의 수생(水生) 무척추동물 | D9: 32,173.3 | E9: 98,077 | F9: 100,376.1 | G9: 406,964 | H9: -308,888
A10: 2025.01 | B10: 04 | C10: 낙농품, 새의 알, 천연꿀, 다른 류로 분류되지 않은 식용인 동물성 생산품 | D10: 3,019.3 | E10: 6,510 | F10: 26,697.6 | G10: 110,511 | H10: -104,002
A11: 2025.01 | B11: 05 | C11: 다른 류로 분류되지 않은 동물성 생산품 | D11: 1,109.0 | E11: 2,877 | F11: 4,815.5 | G11: 20,120 | H11: -17,243
A12: 2025.01 | B12: 06 | C12: 살아 있는 수목과 그 밖의 식물, 인경(鱗莖)ㆍ뿌리와 이와 유사한 물품, 절화(切花)와 장식용 잎 | D12: 126.8 | E12: 418 | F12: 6,543.0 | G12: 13,617 | H12: -13,199
A13: 2025.01 | B13: 07 | C13: 식용의 채소ㆍ뿌리ㆍ괴경(塊莖) | D13: 3,458.9 | E13: 9,802 | F13: 92,844.8 | G13: 75,650 | H13: -65,848
A14: 2025.01 | B14: 08 | C14: 식용의 과실과 견과류, 감귤류ㆍ멜론의 껍질 | D14: 2,811.1 | E14: 26,837 | F14: 61,028.0 | G14: 144,994 | H14: -118,157
A15: 2025.01 | B15: 09 | C15: 커피ㆍ차ㆍ마테(maté)ㆍ향신료 | D15: 367.7 | E15: 2,706 | F15: 16,153.9 | G15: 109,715 | H15: -107,009
A16: 2025.01 | B16: 10 | C16: 곡물 | D16: 1,786.8 | E16: 3,159 | F16: 1,324,476.1 | G16: 363,115 | H16: -359,956
A17: 2025.01 | B17: 11 | C17: 제분공업의 생산품과 맥아, 전분, 이눌린(inulin), 밀의 글루텐(gluten) | D17: 4,838.7 | E17: 3,474 | F17: 27,034.5 | G17: 23,263 | H17: -19,789
A18: 2025.01 | B18: 12 | C18: 채유(採油)에 적합한 종자와 과실, 각종 종자와 과실, 공업용ㆍ의약용 식물, 짚과 사료용 식물 | D18: 2,129.8 | E18: 53,582 | F18: 255,381.1 | G18: 141,767 | H18: -88,185
... A1832: 2026.07 | B1832: 97 | C1832: 예술품ㆍ수집품ㆍ골동품 | D1832: 17.6 | E1832: 15,110 | F1832: 37.5 | G1832: 20,791 | H1832: -5,681

Sheet 수출입 실적(성질별)
A1: 수출입 실적(성질별)
A3: 검색조건 통계항목 : 성질별, 성질명 : 수출, 전체, 세부성질 유무 : 무, 조회기간 : 202501 ~ 202607 , 통계기준 : 수리일, 중량단위 : 톤
E4: 단위:톤(TON), 천 달러
A5: 기간 | B5: 수출입구분 | C5: 성질명 | D5: 중량 | E5: 금액
A6: 총계 | D6: 308,412,746.2 | E6: 1,304,392,880
A7: 2025.01 | B7: 수출 | C7: 1. 식료 및 직접소비재 | D7: 291,911.0 | E7: 845,494
A8: 2025.01 | B8: 수출 | C8: 2. 원료 및 연료 | D8: 5,564,057.8 | E8: 4,217,118
A9: 2025.01 | B9: 수출 | C9: 3. 경공업품 | D9: 850,551.9 | E9: 2,443,890
A10: 2025.01 | B10: 수출 | C10: 가. 섬유원료 | D10: 51,662.0 | E10: 77,004
A11: 2025.01 | B11: 수출 | C11: 나. 섬유사 | D11: 17,074.6 | E11: 58,470
A12: 2025.01 | B12: 수출 | C12: 다. 직 물 | D12: 27,683.3 | E12: 259,146
A13: 2025.01 | B13: 수출 | C13: 라. 기타 섬유제품 | D13: 19,915.9 | E13: 158,212
A14: 2025.01 | B14: 수출 | C14: 마. 의 류 | D14: 4,976.6 | E14: 125,396
A15: 2025.01 | B15: 수출 | C15: 바. 목제품 | D15: 14,907.5 | E15: 81,070
A16: 2025.01 | B16: 수출 | C16: 사. 가죽, 고무 및 신발류 | D16: 70,212.9 | E16: 381,884
A17: 2025.01 | B17: 수출 | C17: 아. 귀금속 및 보석류 | D17: 388.5 | E17: 267,386
A18: 2025.01 | B18: 수출 | C18: 자. 기타 비금속 광물제품 | D18: 312,313.3 | E18: 192,040
... A405: 2026.07 | B405: 수출 | C405: 바. 기 타 | D405: 89,360.5 | E405: 2,725,433

Sheet 수출입 실적(신성질별)
A1: 수출입 실적(신성질별)
A3: 검색조건 통계항목 : 신성질별, 신성질명 : 전체, 세부성질 유무 : 무, 조회기간 : 202501 ~ 202607 , 통계기준 : 수리일, 중량단위 : 톤
F4: 단위:톤(TON), 천 달러
A5: 기간 | B5: 신성질명 | C5: 수출 중량 | D5: 수출 금액 | E5: 수입 중량 | F5: 수입 금액
A6: 총계 | C6: 308,412,746.2 | D6: 1,304,392,880 | E6: 858,381,643.6 | F6: 1,059,198,512
A7: 2025.01 | B7: 1.소비재 | C7: 775,717.7 | D7: 6,837,296 | E7: 2,095,799.4 | F7: 6,754,074
A8: 2025.01 | B8: 가.직접소비재 | C8: 218,831.1 | D8: 769,987 | E8: 1,737,509.5 | F8: 2,716,917
A9: 2025.01 | B9: 나.내구소비재 | C9: 416,256.9 | D9: 4,694,972 | E9: 202,111.2 | F9: 1,801,934
A10: 2025.01 | B10: 다.비내구소비재 | C10: 137,978.4 | D10: 1,369,159 | E10: 156,178.8 | F10: 2,235,223
A11: 2025.01 | B11: 라.간이세율적용분 | C11: 2,651.3 | D11: 3,178 | E11: 0.0 | F11: 0
A12: 2025.01 | B12: 2.원자재 | C12: 12,560,803.9 | D12: 14,770,147 | E12: 45,022,913.6 | F12: 25,300,265
A13: 2025.01 | B13: 가.동식물성 연·원료 | C13: 339,279.8 | D13: 419,822 | E13: 2,705,305.3 | F13: 1,396,963
A14: 2025.01 | B14: 나.섬유류 | C14: 110,571.4 | D14: 522,157 | E14: 98,221.0 | F14: 300,209
A15: 2025.01 | B15: 다.광산물 | C15: 5,415,324.4 | D15: 4,080,925 | E15: 38,763,299.2 | F15: 16,767,335
A16: 2025.01 | B16: 라.철강 및 금속제품 | C16: 2,638,368.0 | D16: 3,130,056 | E16: 1,571,574.4 | F16: 2,485,479
A17: 2025.01 | B17: 마.화학공업제품 | C17: 4,054,430.2 | D17: 6,605,881 | E17: 1,881,480.5 | F17: 4,343,104
A18: 2025.01 | B18: 바.기타 원자재 | C18: 2,830.1 | D18: 11,305 | E18: 3,033.2 | F18: 7,176
... A329: 2026.07 | B329: 라.IT부품 | C329: 33,481.3 | D329: 42,761,535 | E329: 33,712.5 | F329: 11,667,986

Sheet 수출입 실적(국가별)
A1: 수출입 실적(국가별)
A3: 검색조건 통계항목 : 국가별, 국가명 : 전체, 조회기간 : 202501 ~ 202607 , 통계기준 : 수리일
G4: 단위:건, 천 달러
A5: 기간 | B5: 국가 | C5: 수출 건수 | D5: 수출 금액 | E5: 수입 건수 | F5: 수입 금액 | G5: 무역수지
A6: 총계 | C6: 21,702,845 | D6: 1,304,392,880 | E6: 88,995,973 | F6: 1,059,198,512 | G6: 245,194,368
A7: 2025.01 | B7: 미국 | C7: 193,178 | D7: 9,282,567 | E7: 1,416,582 | F7: 5,839,341 | G7: 3,443,226
A8: 2025.01 | B8: 중국 | C8: 91,388 | D8: 9,204,172 | E8: 1,225,173 | F8: 11,208,793 | G8: -2,004,621
A9: 2025.01 | B9: 베트남 | C9: 57,209 | D9: 4,356,972 | E9: 145,132 | F9: 2,564,727 | G9: 1,792,245
A10: 2025.01 | B10: 대만 | C10: 34,078 | D10: 2,438,188 | E10: 20,022 | F10: 2,227,887 | G10: 210,301
A11: 2025.01 | B11: 일본 | C11: 146,929 | D11: 2,363,797 | E11: 344,783 | F11: 3,587,345 | G11: -1,223,548
A12: 2025.01 | B12: 홍콩 | C12: 18,142 | D12: 1,685,484 | E12: 145,075 | F12: 183,373 | G12: 1,502,111
A13: 2025.01 | B13: 인도 | C13: 18,165 | D13: 1,463,921 | E13: 10,408 | F13: 535,824 | G13: 928,097
A14: 2025.01 | B14: 싱가포르 | C14: 42,253 | D14: 1,162,020 | E14: 18,404 | F14: 1,027,832 | G14: 134,187
A15: 2025.01 | B15: 멕시코 | C15: 15,031 | D15: 947,164 | E15: 6,035 | F15: 767,989 | G15: 179,176
A16: 2025.01 | B16: 말레이시아 | C16: 26,784 | D16: 921,582 | E16: 10,823 | F16: 1,350,979 | G16: -429,397
A17: 2025.01 | B17: 호주 | C17: 15,080 | D17: 909,427 | E17: 46,098 | F17: 2,906,682 | G17: -1,997,255
A18: 2025.01 | B18: 필리핀 | C18: 25,805 | D18: 880,737 | E18: 5,154 | F18: 229,072 | G18: 651,665
... A4481: 2026.07 | B4481: 세인트 헬레나 | C4481: 0 | D4481: 0 | E4481: 1 | F4481: 13 | G4481: -13

Sheet 데이터_총괄
A1: 이 시트의 모든 셀은 원본 시트를 참조하는 수식입니다. 원본은 숫자가 텍스트(쉼표 포함)로 저장되어 있어 VALUE/SUBSTITUTE로 숫자화했습니다. 직접 입력하지 마세요.
A2: 기간 | B2: 연도 | C2: 월 | D2: 조업일수 | E2: 수출 건수 | F2: 수출 중량 | G2: 수출 금액 | H2: 수입 건수 | I2: 수입 중량 | J2: 수입 금액 | K2: 무역수지
A3: =TRIM('수출입 총괄'!A7) -> 2025.01 | B3: =IFERROR(VALUE(LEFT(A3,4)),"") -> 2025 | C3: =IFERROR(VALUE(RIGHT(A3,2)),"") -> 1 | D3: =IFERROR(VALUE(SUBSTITUTE(TRIM('수출입 총괄'!B7),",","")),"") -> 20 | E3: =IFERROR(VALUE(SUBSTITUTE(TRIM('수출입 총괄'!C7),",","")),"") -> 924441 | F3: =IFERROR(VALUE(SUBSTITUTE(TRIM('수출입 총괄'!D7),",","")),"") -> 14986302 | G3: =IFERROR(VALUE(SUBSTITUTE(TRIM('수출입 총괄'!E7),",","")),"") -> 49176984 | H3: =IFERROR(VALUE(SUBSTITUTE(TRIM('수출입 총괄'!F7),",","")),"") -> 3847092 | I3: =IFERROR(VALUE(SUBSTITUTE(TRIM('수출입 총괄'!G7),",","")),"") -> 47927338 | J3: =IFERROR(VALUE(SUBSTITUTE(TRIM('수출입 총괄'!H7),",","")),"") -> 51172292 | K3: =IFERROR(VALUE(SUBSTITUTE(TRIM('수출입 총괄'!I7),",","")),"") -> -1995308
A4: =TRIM('수출입 총괄'!A8) -> 2025.02 | B4: =IFERROR(VALUE(LEFT(A4,4)),"") -> 2025 | C4: =IFERROR(VALUE(RIGHT(A4,2)),"") -> 2 | D4: =IFERROR(VALUE(SUBSTITUTE(TRIM('수출입 총괄'!B8),",","")),"") -> 22 | E4: =IFERROR(VALUE(SUBSTITUTE(TRIM('수출입 총괄'!C8),",","")),"") -> 1014431 | F4: =IFERROR(VALUE(SUBSTITUTE(TRIM('수출입 총괄'!D8),",","")),"") -> 16151895 | G4: =IFERROR(VALUE(SUBSTITUTE(TRIM('수출입 총괄'!E8),",","")),"") -> 52292301 | H4: =IFERROR(VALUE(SUBSTITUTE(TRIM('수출입 총괄'!F8),",","")),"") -> 3982365 | I4: =IFERROR(VALUE(SUBSTITUTE(TRIM('수출입 총괄'!G8),",","")),"") -> 41535200 | J4: =IFERROR(VALUE(SUBSTITUTE(TRIM('수출입 총괄'!H8),",","")),"") -> 48328741 | K4: =IFERROR(VALUE(SUBSTITUTE(TRIM('수출입 총괄'!I8),",","")),"") -> 3963560
A5: =TRIM('수출입 총괄'!A9) -> 2025.03 | B5: =IFERROR(VALUE(LEFT(A5,4)),"") -> 2025 | C5: =IFERROR(VALUE(RIGHT(A5,2)),"") -> 3 | D5: =IFERROR(VALUE(SUBSTITUTE(TRIM('수출입 총괄'!B9),",","")),"") -> 22 | E5: =IFERROR(VALUE(SUBSTITUTE(TRIM('수출입 총괄'!C9),",","")),"") -> 1236266 | F5: =IFERROR(VALUE(SUBSTITUTE(TRIM('수출입 총괄'!D9),",","")),"") -> 15702060 | G5: =IFERROR(VALUE(SUBSTITUTE(TRIM('수출입 총괄'!E9),",","")),"") -> 58064562 | H5: =IFERROR(VALUE(SUBSTITUTE(TRIM('수출입 총괄'!F9),",","")),"") -> 4558238 | I5: =IFERROR(VALUE(SUBSTITUTE(TRIM('수출입 총괄'!G9),",","")),"") -> 41960253 | J5: =IFERROR(VALUE(SUBSTITUTE(TRIM('수출입 총괄'!H9),",","")),"") -> 53341032 | K5: =IFERROR(VALUE(SUBSTITUTE(TRIM('수출입 총괄'!I9),",","")),"") -> 4723530
A6: =TRIM('수출입 총괄'!A10) -> 2025.04 | B6: =IFERROR(VALUE(LEFT(A6,4)),"") -> 2025 | C6: =IFERROR(VALUE(RIGHT(A6,2)),"") -> 4 | D6: =IFERROR(VALUE(SUBSTITUTE(TRIM('수출입 총괄'!B10),",","")),"") -> 24 | E6: =IFERROR(VALUE(SUBSTITUTE(TRIM('수출입 총괄'!C10),",","")),"") -> 1088160 | F6: =IFERROR(VALUE(SUBSTITUTE(TRIM('수출입 총괄'!D10),",","")),"") -> 17527805 | G6: =IFERROR(VALUE(SUBSTITUTE(TRIM('수출입 총괄'!E10),",","")),"") -> 58035745 | H6: =IFERROR(VALUE(SUBSTITUTE(TRIM('수출입 총괄'!F10),",","")),"") -> 4601632 | I6: =IFERROR(VALUE(SUBSTITUTE(TRIM('수출입 총괄'!G10),",","")),"") -> 45256630 | J6: =IFERROR(VALUE(SUBSTITUTE(TRIM('수출입 총괄'!H10),",","")),"") -> 53232716 | K6: =IFERROR(VALUE(SUBSTITUTE(TRIM('수출입 총괄'!I10),",","")),"") -> 4803029
A7: =TRIM('수출입 총괄'!A11) -> 2025.05 | B7: =IFERROR(VALUE(LEFT(A7,4)),"") -> 2025 | C7: =IFERROR(VALUE(RIGHT(A7,2)),"") -> 5 | D7: =IFERROR(VALUE(SUBSTITUTE(TRIM('수출입 총괄'!B11),",","")),"") -> 21.5 | E7: =IFERROR(VALUE(SUBSTITUTE(TRIM('수출입 총괄'!C11),",","")),"") -> 1034785 | F7: =IFERROR(VALUE(SUBSTITUTE(TRIM('수출입 총괄'!D11),",","")),"") -> 16573463 | G7: =IFERROR(VALUE(SUBSTITUTE(TRIM('수출입 총괄'!E11),",","")),"") -> 57261063 | H7: =IFERROR(VALUE(SUBSTITUTE(TRIM('수출입 총괄'!F11),",","")),"") -> 4586252 | I7: =IFERROR(VALUE(SUBSTITUTE(TRIM('수출입 총괄'!G11),",","")),"") -> 43030474 | J7: =IFERROR(VALUE(SUBSTITUTE(TRIM('수출입 총괄'!H11),",","")),"") -> 50345116 | K7: =IFERROR(VALUE(SUBSTITUTE(TRIM('수출입 총괄'!I11),",","")),"") -> 6915946
A8: =TRIM('수출입 총괄'!A12) -> 2025.06 | B8: =IFERROR(VALUE(LEFT(A8,4)),"") -> 2025 | C8: =IFERROR(VALUE(RIGHT(A8,2)),"") -> 6 | D8: =IFERROR(VALUE(SUBSTITUTE(TRIM('수출입 총괄'!B12),",","")),"") -> 21 | E8: =IFERROR(VALUE(SUBSTITUTE(TRIM('수출입 총괄'!C12),",","")),"") -> 1328545 | F8: =IFERROR(VALUE(SUBSTITUTE(TRIM('수출입 총괄'!D12),",","")),"") -> 16221157 | G8: =IFERROR(VALUE(SUBSTITUTE(TRIM('수출입 총괄'!E12),",","")),"") -> 59833797 | H8: =IFERROR(VALUE(SUBSTITUTE(TRIM('수출입 총괄'!F12),",","")),"") -> 4272361 | I8: =IFERROR(VALUE(SUBSTITUTE(TRIM('수출입 총괄'!G12),",","")),"") -> 42728885 | J8: =IFERROR(VALUE(SUBSTITUTE(TRIM('수출입 총괄'!H12),",","")),"") -> 50825746 | K8: =IFERROR(VALUE(SUBSTITUTE(TRIM('수출입 총괄'!I12),",","")),"") -> 9008051
A9: =TRIM('수출입 총괄'!A13) -> 2025.07 | B9: =IFERROR(VALUE(LEFT(A9,4)),"") -> 2025 | C9: =IFERROR(VALUE(RIGHT(A9,2)),"") -> 7 | D9: =IFERROR(VALUE(SUBSTITUTE(TRIM('수출입 총괄'!B13),",","")),"") -> 25 | E9: =IFERROR(VALUE(SUBSTITUTE(TRIM('수출입 총괄'!C13),",","")),"") -> 1177196 | F9: =IFERROR(VALUE(SUBSTITUTE(TRIM('수출입 총괄'!D13),",","")),"") -> 17580838 | G9: =IFERROR(VALUE(SUBSTITUTE(TRIM('수출입 총괄'!E13),",","")),"") -> 60724322 | H9: =IFERROR(VALUE(SUBSTITUTE(TRIM('수출입 총괄'!F13),",","")),"") -> 4754616 | I9: =IFERROR(VALUE(SUBSTITUTE(TRIM('수출입 총괄'!G13),",","")),"") -> 47540216 | J9: =IFERROR(VALUE(SUBSTITUTE(TRIM('수출입 총괄'!H13),",","")),"") -> 54210371 | K9: =IFERROR(VALUE(SUBSTITUTE(TRIM('수출입 총괄'!I13),",","")),"") -> 6513951
A10: =TRIM('수출입 총괄'!A14) -> 2025.08 | B10: =IFERROR(VALUE(LEFT(A10,4)),"") -> 2025 | C10: =IFERROR(VALUE(RIGHT(A10,2)),"") -> 8 | D10: =IFERROR(VALUE(SUBSTITUTE(TRIM('수출입 총괄'!B14),",","")),"") -> 22.5 | E10: =IFERROR(VALUE(SUBSTITUTE(TRIM('수출입 총괄'!C14),",","")),"") -> 1058881 | F10: =IFERROR(VALUE(SUBSTITUTE(TRIM('수출입 총괄'!D14),",","")),"") -> 17118674 | G10: =IFERROR(VALUE(SUBSTITUTE(TRIM('수출입 총괄'!E14),",","")),"") -> 58259332 | H10: =IFERROR(VALUE(SUBSTITUTE(TRIM('수출입 총괄'!F14),",","")),"") -> 4524180 | I10: =IFERROR(VALUE(SUBSTITUTE(TRIM('수출입 총괄'!G14),",","")),"") -> 48641921 | J10: =IFERROR(VALUE(SUBSTITUTE(TRIM('수출입 총괄'!H14),",","")),"") -> 51856624 | K10: =IFERROR(VALUE(SUBSTITUTE(TRIM('수출입 총괄'!I14),",","")),"") -> 6402708
A11: =TRIM('수출입 총괄'!A15) -> 2025.09 | B11: =IFERROR(VALUE(LEFT(A11,4)),"") -> 2025 | C11: =IFERROR(VALUE(RIGHT(A11,2)),"") -> 9 | D11: =IFERROR(VALUE(SUBSTITUTE(TRIM('수출입 총괄'!B15),",","")),"") -> 24 | E11: =IFERROR(VALUE(SUBSTITUTE(TRIM('수출입 총괄'!C15),",","")),"") -> 1451822 | F11: =IFERROR(VALUE(SUBSTITUTE(TRIM('수출입 총괄'!D15),",","")),"") -> 18076703 | G11: =IFERROR(VALUE(SUBSTITUTE(TRIM('수출입 총괄'!E15),",","")),"") -> 65904118 | H11: =IFERROR(VALUE(SUBSTITUTE(TRIM('수출입 총괄'!F15),",","")),"") -> 4986893 | I11: =IFERROR(VALUE(SUBSTITUTE(TRIM('수출입 총괄'!G15),",","")),"") -> 47278338 | J11: =IFERROR(VALUE(SUBSTITUTE(TRIM('수출입 총괄'!H15),",","")),"") -> 56419614 | K11: =IFERROR(VALUE(SUBSTITUTE(TRIM('수출입 총괄'!I15),",","")),"") -> 9484504
A12: =TRIM('수출입 총괄'!A16) -> 2025.10 | B12: =IFERROR(VALUE(LEFT(A12,4)),"") -> 2025 | C12: =IFERROR(VALUE(RIGHT(A12,2)),"") -> 10 | D12: =IFERROR(VALUE(SUBSTITUTE(TRIM('수출입 총괄'!B16),",","")),"") -> 20 | E12: =IFERROR(VALUE(SUBSTITUTE(TRIM('수출입 총괄'!C16),",","")),"") -> 1040165 | F12: =IFERROR(VALUE(SUBSTITUTE(TRIM('수출입 총괄'!D16),",","")),"") -> 16017318 | G12: =IFERROR(VALUE(SUBSTITUTE(TRIM('수출입 총괄'!E16),",","")),"") -> 59511578 | H12: =IFERROR(VALUE(SUBSTITUTE(TRIM('수출입 총괄'!F16),",","")),"") -> 4655160 | I12: =IFERROR(VALUE(SUBSTITUTE(TRIM('수출입 총괄'!G16),",","")),"") -> 47575894 | J12: =IFERROR(VALUE(SUBSTITUTE(TRIM('수출입 총괄'!H16),",","")),"") -> 53510827 | K12: =IFERROR(VALUE(SUBSTITUTE(TRIM('수출입 총괄'!I16),",","")),"") -> 6000751
A13: =TRIM('수출입 총괄'!A17) -> 2025.11 | B13: =IFERROR(VALUE(LEFT(A13,4)),"") -> 2025 | C13: =IFERROR(VALUE(RIGHT(A13,2)),"") -> 11 | D13: =IFERROR(VALUE(SUBSTITUTE(TRIM('수출입 총괄'!B17),",","")),"") -> 22.5 | E13: =IFERROR(VALUE(SUBSTITUTE(TRIM('수출입 총괄'!C17),",","")),"") -> 1152460 | F13: =IFERROR(VALUE(SUBSTITUTE(TRIM('수출입 총괄'!D17),",","")),"") -> 14605096 | G13: =IFERROR(VALUE(SUBSTITUTE(TRIM('수출입 총괄'!E17),",","")),"") -> 60752618 | H13: =IFERROR(VALUE(SUBSTITUTE(TRIM('수출입 총괄'!F17),",","")),"") -> 4883281 | I13: =IFERROR(VALUE(SUBSTITUTE(TRIM('수출입 총괄'!G17),",","")),"") -> 43553039 | J13: =IFERROR(VALUE(SUBSTITUTE(TRIM('수출입 총괄'!H17),",","")),"") -> 51284605 | K13: =IFERROR(VALUE(SUBSTITUTE(TRIM('수출입 총괄'!I17),",","")),"") -> 9468013
A14: =TRIM('수출입 총괄'!A18) -> 2025.12 | B14: =IFERROR(VALUE(LEFT(A14,4)),"") -> 2025 | C14: =IFERROR(VALUE(RIGHT(A14,2)),"") -> 12 | D14: =IFERROR(VALUE(SUBSTITUTE(TRIM('수출입 총괄'!B18),",","")),"") -> 24 | E14: =IFERROR(VALUE(SUBSTITUTE(TRIM('수출입 총괄'!C18),",","")),"") -> 1275309 | F14: =IFERROR(VALUE(SUBSTITUTE(TRIM('수출입 총괄'!D18),",","")),"") -> 17977896 | G14: =IFERROR(VALUE(SUBSTITUTE(TRIM('수출입 총괄'!E18),",","")),"") -> 69513624 | H14: =IFERROR(VALUE(SUBSTITUTE(TRIM('수출입 총괄'!F18),",","")),"") -> 4883706 | I14: =IFERROR(VALUE(SUBSTITUTE(TRIM('수출입 총괄'!G18),",","")),"") -> 47510406 | J14: =IFERROR(VALUE(SUBSTITUTE(TRIM('수출입 총괄'!H18),",","")),"") -> 57367684 | K14: =IFERROR(VALUE(SUBSTITUTE(TRIM('수출입 총괄'!I18),",","")),"") -> 12145941
... A21: =TRIM('수출입 총괄'!A25) -> 2026.07 | B21: =IFERROR(VALUE(LEFT(A21,4)),"") -> 2026 | C21: =IFERROR(VALUE(RIGHT(A21,2)),"") -> 7 | D21: =IFERROR(VALUE(SUBSTITUTE(TRIM('수출입 총괄'!B25),",","")),"") -> 24 | E21: =IFERROR(VALUE(SUBSTITUTE(TRIM('수출입 총괄'!C25),",","")),"") -> 1111934 | F21: =IFERROR(VALUE(SUBSTITUTE(TRIM('수출입 총괄'!D25),",","")),"") -> 17660681 | G21: =IFERROR(VALUE(SUBSTITUTE(TRIM('수출입 총괄'!E25),",","")),"") -> 98959099 | H21: =IFERROR(VALUE(SUBSTITUTE(TRIM('수출입 총괄'!F25),",","")),"") -> 5158848 | I21: =IFERROR(VALUE(SUBSTITUTE(TRIM('수출입 총괄'!G25),",","")),"") -> 51144176 | J21: =IFERROR(VALUE(SUBSTITUTE(TRIM('수출입 총괄'!H25),",","")),"") -> 68567473 | K21: =IFERROR(VALUE(SUBSTITUTE(TRIM('수출입 총괄'!I25),",","")),"") -> 30391625

Sheet 데이터_성질별
A1: 이 시트의 모든 셀은 원본 시트를 참조하는 수식입니다. 원본은 숫자가 텍스트(쉼표 포함)로 저장되어 있어 VALUE/SUBSTITUTE로 숫자화했습니다. 직접 입력하지 마세요.
A2: 기간 | B2: 연도 | C2: 월 | D2: 성질명 | E2: 수출 중량 | F2: 수출 금액
A3: =TRIM('수출입 실적(성질별)'!A7) -> 2025.01 | B3: =IFERROR(VALUE(LEFT(A3,4)),"") -> 2025 | C3: =IFERROR(VALUE(RIGHT(A3,2)),"") -> 1 | D3: =TRIM('수출입 실적(성질별)'!C7) -> 1. 식료 및 직접소비재 | E3: =IFERROR(VALUE(SUBSTITUTE(TRIM('수출입 실적(성질별)'!D7),",","")),"") -> 291911 | F3: =IFERROR(VALUE(SUBSTITUTE(TRIM('수출입 실적(성질별)'!E7),",","")),"") -> 845494
A4: =TRIM('수출입 실적(성질별)'!A8) -> 2025.01 | B4: =IFERROR(VALUE(LEFT(A4,4)),"") -> 2025 | C4: =IFERROR(VALUE(RIGHT(A4,2)),"") -> 1 | D4: =TRIM('수출입 실적(성질별)'!C8) -> 2. 원료 및 연료 | E4: =IFERROR(VALUE(SUBSTITUTE(TRIM('수출입 실적(성질별)'!D8),",","")),"") -> 5564057.8 | F4: =IFERROR(VALUE(SUBSTITUTE(TRIM('수출입 실적(성질별)'!E8),",","")),"") -> 4217118
A5: =TRIM('수출입 실적(성질별)'!A9) -> 2025.01 | B5: =IFERROR(VALUE(LEFT(A5,4)),"") -> 2025 | C5: =IFERROR(VALUE(RIGHT(A5,2)),"") -> 1 | D5: =TRIM('수출입 실적(성질별)'!C9) -> 3. 경공업품 | E5: =IFERROR(VALUE(SUBSTITUTE(TRIM('수출입 실적(성질별)'!D9),",","")),"") -> 850551.9 | F5: =IFERROR(VALUE(SUBSTITUTE(TRIM('수출입 실적(성질별)'!E9),",","")),"") -> 2443890
A6: =TRIM('수출입 실적(성질별)'!A10) -> 2025.01 | B6: =IFERROR(VALUE(LEFT(A6,4)),"") -> 2025 | C6: =IFERROR(VALUE(RIGHT(A6,2)),"") -> 1 | D6: =TRIM('수출입 실적(성질별)'!C10) -> 가. 섬유원료 | E6: =IFERROR(VALUE(SUBSTITUTE(TRIM('수출입 실적(성질별)'!D10),",","")),"") -> 51662 | F6: =IFERROR(VALUE(SUBSTITUTE(TRIM('수출입 실적(성질별)'!E10),",","")),"") -> 77004
A7: =TRIM('수출입 실적(성질별)'!A11) -> 2025.01 | B7: =IFERROR(VALUE(LEFT(A7,4)),"") -> 2025 | C7: =IFERROR(VALUE(RIGHT(A7,2)),"") -> 1 | D7: =TRIM('수출입 실적(성질별)'!C11) -> 나. 섬유사 | E7: =IFERROR(VALUE(SUBSTITUTE(TRIM('수출입 실적(성질별)'!D11),",","")),"") -> 17074.6 | F7: =IFERROR(VALUE(SUBSTITUTE(TRIM('수출입 실적(성질별)'!E11),",","")),"") -> 58470
A8: =TRIM('수출입 실적(성질별)'!A12) -> 2025.01 | B8: =IFERROR(VALUE(LEFT(A8,4)),"") -> 2025 | C8: =IFERROR(VALUE(RIGHT(A8,2)),"") -> 1 | D8: =TRIM('수출입 실적(성질별)'!C12) -> 다. 직 물 | E8: =IFERROR(VALUE(SUBSTITUTE(TRIM('수출입 실적(성질별)'!D12),",","")),"") -> 27683.3 | F8: =IFERROR(VALUE(SUBSTITUTE(TRIM('수출입 실적(성질별)'!E12),",","")),"") -> 259146
A9: =TRIM('수출입 실적(성질별)'!A13) -> 2025.01 | B9: =IFERROR(VALUE(LEFT(A9,4)),"") -> 2025 | C9: =IFERROR(VALUE(RIGHT(A9,2)),"") -> 1 | D9: =TRIM('수출입 실적(성질별)'!C13) -> 라. 기타 섬유제품 | E9: =IFERROR(VALUE(SUBSTITUTE(TRIM('수출입 실적(성질별)'!D13),",","")),"") -> 19915.9 | F9: =IFERROR(VALUE(SUBSTITUTE(TRIM('수출입 실적(성질별)'!E13),",","")),"") -> 158212
A10: =TRIM('수출입 실적(성질별)'!A14) -> 2025.01 | B10: =IFERROR(VALUE(LEFT(A10,4)),"") -> 2025 | C10: =IFERROR(VALUE(RIGHT(A10,2)),"") -> 1 | D10: =TRIM('수출입 실적(성질별)'!C14) -> 마. 의 류 | E10: =IFERROR(VALUE(SUBSTITUTE(TRIM('수출입 실적(성질별)'!D14),",","")),"") -> 4976.6 | F10: =IFERROR(VALUE(SUBSTITUTE(TRIM('수출입 실적(성질별)'!E14),",","")),"") -> 125396
A11: =TRIM('수출입 실적(성질별)'!A15) -> 2025.01 | B11: =IFERROR(VALUE(LEFT(A11,4)),"") -> 2025 | C11: =IFERROR(VALUE(RIGHT(A11,2)),"") -> 1 | D11: =TRIM('수출입 실적(성질별)'!C15) -> 바. 목제품 | E11: =IFERROR(VALUE(SUBSTITUTE(TRIM('수출입 실적(성질별)'!D15),",","")),"") -> 14907.5 | F11: =IFERROR(VALUE(SUBSTITUTE(TRIM('수출입 실적(성질별)'!E15),",","")),"") -> 81070
A12: =TRIM('수출입 실적(성질별)'!A16) -> 2025.01 | B12: =IFERROR(VALUE(LEFT(A12,4)),"") -> 2025 | C12: =IFERROR(VALUE(RIGHT(A12,2)),"") -> 1 | D12: =TRIM('수출입 실적(성질별)'!C16) -> 사. 가죽, 고무 및 신발류 | E12: =IFERROR(VALUE(SUBSTITUTE(TRIM('수출입 실적(성질별)'!D16),",","")),"") -> 70212.9 | F12: =IFERROR(VALUE(SUBSTITUTE(TRIM('수출입 실적(성질별)'!E16),",","")),"") -> 381884
A13: =TRIM('수출입 실적(성질별)'!A17) -> 2025.01 | B13: =IFERROR(VALUE(LEFT(A13,4)),"") -> 2025 | C13: =IFERROR(VALUE(RIGHT(A13,2)),"") -> 1 | D13: =TRIM('수출입 실적(성질별)'!C17) -> 아. 귀금속 및 보석류 | E13: =IFERROR(VALUE(SUBSTITUTE(TRIM('수출입 실적(성질별)'!D17),",","")),"") -> 388.5 | F13: =IFERROR(VALUE(SUBSTITUTE(TRIM('수출입 실적(성질별)'!E17),",","")),"") -> 267386
A14: =TRIM('수출입 실적(성질별)'!A18) -> 2025.01 | B14: =IFERROR(VALUE(LEFT(A14,4)),"") -> 2025 | C14: =IFERROR(VALUE(RIGHT(A14,2)),"") -> 1 | D14: =TRIM('수출입 실적(성질별)'!C18) -> 자. 기타 비금속 광물제품 | E14: =IFERROR(VALUE(SUBSTITUTE(TRIM('수출입 실적(성질별)'!D18),",","")),"") -> 312313.3 | F14: =IFERROR(VALUE(SUBSTITUTE(TRIM('수출입 실적(성질별)'!E18),",","")),"") -> 192040
... A401: =TRIM('수출입 실적(성질별)'!A405) -> 2026.07 | B401: =IFERROR(VALUE(LEFT(A401,4)),"") -> 2026 | C401: =IFERROR(VALUE(RIGHT(A401,2)),"") -> 7 | D401: =TRIM('수출입 실적(성질별)'!C405) -> 바. 기 타 | E401: =IFERROR(VALUE(SUBSTITUTE(TRIM('수출입 실적(성질별)'!D405),",","")),"") -> 89360.5 | F401: =IFERROR(VALUE(SUBSTITUTE(TRIM('수출입 실적(성질별)'!E405),",","")),"") -> 2725433

Sheet 데이터_신성질별
A1: 이 시트의 모든 셀은 원본 시트를 참조하는 수식입니다. 원본은 숫자가 텍스트(쉼표 포함)로 저장되어 있어 VALUE/SUBSTITUTE로 숫자화했습니다. 직접 입력하지 마세요.
A2: 기간 | B2: 연도 | C2: 월 | D2: 신성질명 | E2: 수출 중량 | F2: 수출 금액 | G2: 수입 중량 | H2: 수입 금액
A3: =TRIM('수출입 실적(신성질별)'!A7) -> 2025.01 | B3: =IFERROR(VALUE(LEFT(A3,4)),"") -> 2025 | C3: =IFERROR(VALUE(RIGHT(A3,2)),"") -> 1 | D3: =TRIM('수출입 실적(신성질별)'!B7) -> 1.소비재 | E3: =IFERROR(VALUE(SUBSTITUTE(TRIM('수출입 실적(신성질별)'!C7),",","")),"") -> 775717.7 | F3: =IFERROR(VALUE(SUBSTITUTE(TRIM('수출입 실적(신성질별)'!D7),",","")),"") -> 6837296 | G3: =IFERROR(VALUE(SUBSTITUTE(TRIM('수출입 실적(신성질별)'!E7),",","")),"") -> 2095799.4 | H3: =IFERROR(VALUE(SUBSTITUTE(TRIM('수출입 실적(신성질별)'!F7),",","")),"") -> 6754074
A4: =TRIM('수출입 실적(신성질별)'!A8) -> 2025.01 | B4: =IFERROR(VALUE(LEFT(A4,4)),"") -> 2025 | C4: =IFERROR(VALUE(RIGHT(A4,2)),"") -> 1 | D4: =TRIM('수출입 실적(신성질별)'!B8) -> 가.직접소비재 | E4: =IFERROR(VALUE(SUBSTITUTE(TRIM('수출입 실적(신성질별)'!C8),",","")),"") -> 218831.1 | F4: =IFERROR(VALUE(SUBSTITUTE(TRIM('수출입 실적(신성질별)'!D8),",","")),"") -> 769987 | G4: =IFERROR(VALUE(SUBSTITUTE(TRIM('수출입 실적(신성질별)'!E8),",","")),"") -> 1737509.5 | H4: =IFERROR(VALUE(SUBSTITUTE(TRIM('수출입 실적(신성질별)'!F8),",","")),"") -> 2716917
A5: =TRIM('수출입 실적(신성질별)'!A9) -> 2025.01 | B5: =IFERROR(VALUE(LEFT(A5,4)),"") -> 2025 | C5: =IFERROR(VALUE(RIGHT(A5,2)),"") -> 1 | D5: =TRIM('수출입 실적(신성질별)'!B9) -> 나.내구소비재 | E5: =IFERROR(VALUE(SUBSTITUTE(TRIM('수출입 실적(신성질별)'!C9),",","")),"") -> 416256.9 | F5: =IFERROR(VALUE(SUBSTITUTE(TRIM('수출입 실적(신성질별)'!D9),",","")),"") -> 4694972 | G5: =IFERROR(VALUE(SUBSTITUTE(TRIM('수출입 실적(신성질별)'!E9),",","")),"") -> 202111.2 | H5: =IFERROR(VALUE(SUBSTITUTE(TRIM('수출입 실적(신성질별)'!F9),",","")),"") -> 1801934
A6: =TRIM('수출입 실적(신성질별)'!A10) -> 2025.01 | B6: =IFERROR(VALUE(LEFT(A6,4)),"") -> 2025 | C6: =IFERROR(VALUE(RIGHT(A6,2)),"") -> 1 | D6: =TRIM('수출입 실적(신성질별)'!B10) -> 다.비내구소비재 | E6: =IFERROR(VALUE(SUBSTITUTE(TRIM('수출입 실적(신성질별)'!C10),",","")),"") -> 137978.4 | F6: =IFERROR(VALUE(SUBSTITUTE(TRIM('수출입 실적(신성질별)'!D10),",","")),"") -> 1369159 | G6: =IFERROR(VALUE(SUBSTITUTE(TRIM('수출입 실적(신성질별)'!E10),",","")),"") -> 156178.8 | H6: =IFERROR(VALUE(SUBSTITUTE(TRIM('수출입 실적(신성질별)'!F10),",","")),"") -> 2235223
A7: =TRIM('수출입 실적(신성질별)'!A11) -> 2025.01 | B7: =IFERROR(VALUE(LEFT(A7,4)),"") -> 2025 | C7: =IFERROR(VALUE(RIGHT(A7,2)),"") -> 1 | D7: =TRIM('수출입 실적(신성질별)'!B11) -> 라.간이세율적용분 | E7: =IFERROR(VALUE(SUBSTITUTE(TRIM('수출입 실적(신성질별)'!C11),",","")),"") -> 2651.3 | F7: =IFERROR(VALUE(SUBSTITUTE(TRIM('수출입 실적(신성질별)'!D11),",","")),"") -> 3178 | G7: =IFERROR(VALUE(SUBSTITUTE(TRIM('수출입 실적(신성질별)'!E11),",","")),"") -> 0 | H7: =IFERROR(VALUE(SUBSTITUTE(TRIM('수출입 실적(신성질별)'!F11),",","")),"") -> 0
A8: =TRIM('수출입 실적(신성질별)'!A12) -> 2025.01 | B8: =IFERROR(VALUE(LEFT(A8,4)),"") -> 2025 | C8: =IFERROR(VALUE(RIGHT(A8,2)),"") -> 1 | D8: =TRIM('수출입 실적(신성질별)'!B12) -> 2.원자재 | E8: =IFERROR(VALUE(SUBSTITUTE(TRIM('수출입 실적(신성질별)'!C12),",","")),"") -> 12560804 | F8: =IFERROR(VALUE(SUBSTITUTE(TRIM('수출입 실적(신성질별)'!D12),",","")),"") -> 14770147 | G8: =IFERROR(VALUE(SUBSTITUTE(TRIM('수출입 실적(신성질별)'!E12),",","")),"") -> 45022914 | H8: =IFERROR(VALUE(SUBSTITUTE(TRIM('수출입 실적(신성질별)'!F12),",","")),"") -> 25300265
A9: =TRIM('수출입 실적(신성질별)'!A13) -> 2025.01 | B9: =IFERROR(VALUE(LEFT(A9,4)),"") -> 2025 | C9: =IFERROR(VALUE(RIGHT(A9,2)),"") -> 1 | D9: =TRIM('수출입 실적(신성질별)'!B13) -> 가.동식물성 연·원료 | E9: =IFERROR(VALUE(SUBSTITUTE(TRIM('수출입 실적(신성질별)'!C13),",","")),"") -> 339279.8 | F9: =IFERROR(VALUE(SUBSTITUTE(TRIM('수출입 실적(신성질별)'!D13),",","")),"") -> 419822 | G9: =IFERROR(VALUE(SUBSTITUTE(TRIM('수출입 실적(신성질별)'!E13),",","")),"") -> 2705305.3 | H9: =IFERROR(VALUE(SUBSTITUTE(TRIM('수출입 실적(신성질별)'!F13),",","")),"") -> 1396963
A10: =TRIM('수출입 실적(신성질별)'!A14) -> 2025.01 | B10: =IFERROR(VALUE(LEFT(A10,4)),"") -> 2025 | C10: =IFERROR(VALUE(RIGHT(A10,2)),"") -> 1 | D10: =TRIM('수출입 실적(신성질별)'!B14) -> 나.섬유류 | E10: =IFERROR(VALUE(SUBSTITUTE(TRIM('수출입 실적(신성질별)'!C14),",","")),"") -> 110571.4 | F10: =IFERROR(VALUE(SUBSTITUTE(TRIM('수출입 실적(신성질별)'!D14),",","")),"") -> 522157 | G10: =IFERROR(VALUE(SUBSTITUTE(TRIM('수출입 실적(신성질별)'!E14),",","")),"") -> 98221 | H10: =IFERROR(VALUE(SUBSTITUTE(TRIM('수출입 실적(신성질별)'!F14),",","")),"") -> 300209
A11: =TRIM('수출입 실적(신성질별)'!A15) -> 2025.01 | B11: =IFERROR(VALUE(LEFT(A11,4)),"") -> 2025 | C11: =IFERROR(VALUE(RIGHT(A11,2)),"") -> 1 | D11: =TRIM('수출입 실적(신성질별)'!B15) -> 다.광산물 | E11: =IFERROR(VALUE(SUBSTITUTE(TRIM('수출입 실적(신성질별)'!C15),",","")),"") -> 5415324.4 | F11: =IFERROR(VALUE(SUBSTITUTE(TRIM('수출입 실적(신성질별)'!D15),",","")),"") -> 4080925 | G11: =IFERROR(VALUE(SUBSTITUTE(TRIM('수출입 실적(신성질별)'!E15),",","")),"") -> 38763299 | H11: =IFERROR(VALUE(SUBSTITUTE(TRIM('수출입 실적(신성질별)'!F15),",","")),"") -> 16767335
A12: =TRIM('수출입 실적(신성질별)'!A16) -> 2025.01 | B12: =IFERROR(VALUE(LEFT(A12,4)),"") -> 2025 | C12: =IFERROR(VALUE(RIGHT(A12,2)),"") -> 1 | D12: =TRIM('수출입 실적(신성질별)'!B16) -> 라.철강 및 금속제품 | E12: =IFERROR(VALUE(SUBSTITUTE(TRIM('수출입 실적(신성질별)'!C16),",","")),"") -> 2638368 | F12: =IFERROR(VALUE(SUBSTITUTE(TRIM('수출입 실적(신성질별)'!D16),",","")),"") -> 3130056 | G12: =IFERROR(VALUE(SUBSTITUTE(TRIM('수출입 실적(신성질별)'!E16),",","")),"") -> 1571574.4 | H12: =IFERROR(VALUE(SUBSTITUTE(TRIM('수출입 실적(신성질별)'!F16),",","")),"") -> 2485479
A13: =TRIM('수출입 실적(신성질별)'!A17) -> 2025.01 | B13: =IFERROR(VALUE(LEFT(A13,4)),"") -> 2025 | C13: =IFERROR(VALUE(RIGHT(A13,2)),"") -> 1 | D13: =TRIM('수출입 실적(신성질별)'!B17) -> 마.화학공업제품 | E13: =IFERROR(VALUE(SUBSTITUTE(TRIM('수출입 실적(신성질별)'!C17),",","")),"") -> 4054430.2 | F13: =IFERROR(VALUE(SUBSTITUTE(TRIM('수출입 실적(신성질별)'!D17),",","")),"") -> 6605881 | G13: =IFERROR(VALUE(SUBSTITUTE(TRIM('수출입 실적(신성질별)'!E17),",","")),"") -> 1881480.5 | H13: =IFERROR(VALUE(SUBSTITUTE(TRIM('수출입 실적(신성질별)'!F17),",","")),"") -> 4343104
A14: =TRIM('수출입 실적(신성질별)'!A18) -> 2025.01 | B14: =IFERROR(VALUE(LEFT(A14,4)),"") -> 2025 | C14: =IFERROR(VALUE(RIGHT(A14,2)),"") -> 1 | D14: =TRIM('수출입 실적(신성질별)'!B18) -> 바.기타 원자재 | E14: =IFERROR(VALUE(SUBSTITUTE(TRIM('수출입 실적(신성질별)'!C18),",","")),"") -> 2830.1 | F14: =IFERROR(VALUE(SUBSTITUTE(TRIM('수출입 실적(신성질별)'!D18),",","")),"") -> 11305 | G14: =IFERROR(VALUE(SUBSTITUTE(TRIM('수출입 실적(신성질별)'!E18),",","")),"") -> 3033.2 | H14: =IFERROR(VALUE(SUBSTITUTE(TRIM('수출입 실적(신성질별)'!F18),",","")),"") -> 7176
... A325: =TRIM('수출입 실적(신성질별)'!A329) -> 2026.07 | B325: =IFERROR(VALUE(LEFT(A325,4)),"") -> 2026 | C325: =IFERROR(VALUE(RIGHT(A325,2)),"") -> 7 | D325: =TRIM('수출입 실적(신성질별)'!B329) -> 라.IT부품 | E325: =IFERROR(VALUE(SUBSTITUTE(TRIM('수출입 실적(신성질별)'!C329),",","")),"") -> 33481.3 | F325: =IFERROR(VALUE(SUBSTITUTE(TRIM('수출입 실적(신성질별)'!D329),",","")),"") -> 42761535 | G325: =IFERROR(VALUE(SUBSTITUTE(TRIM('수출입 실적(신성질별)'!E329),",","")),"") -> 33712.5 | H325: =IFERROR(VALUE(SUBSTITUTE(TRIM('수출입 실적(신성질별)'!F329),",","")),"") -> 11667986

Sheet 데이터_품목별
A1: 이 시트의 모든 셀은 원본 시트를 참조하는 수식입니다. 원본은 숫자가 텍스트(쉼표 포함)로 저장되어 있어 VALUE/SUBSTITUTE로 숫자화했습니다. 직접 입력하지 마세요.
A2: 기간 | B2: 연도 | C2: 월 | D2: HS코드 | E2: 품목명 | F2: 수출 금액 | G2: 수입 금액 | H2: 무역수지
A3: =TRIM('수출입 실적(품목별)'!A7) -> 2025.01 | B3: =IFERROR(VALUE(LEFT(A3,4)),"") -> 2025 | C3: =IFERROR(VALUE(RIGHT(A3,2)),"") -> 1 | D3: =TRIM('수출입 실적(품목별)'!B7) -> 01 | E3: =TRIM('수출입 실적(품목별)'!C7) -> 살아 있는 동물 | F3: =IFERROR(VALUE(SUBSTITUTE(TRIM('수출입 실적(품목별)'!E7),",","")),"") -> 511 | G3: =IFERROR(VALUE(SUBSTITUTE(TRIM('수출입 실적(품목별)'!G7),",","")),"") -> 4460 | H3: =IFERROR(VALUE(SUBSTITUTE(TRIM('수출입 실적(품목별)'!H7),",","")),"") -> -3948
A4: =TRIM('수출입 실적(품목별)'!A8) -> 2025.01 | B4: =IFERROR(VALUE(LEFT(A4,4)),"") -> 2025 | C4: =IFERROR(VALUE(RIGHT(A4,2)),"") -> 1 | D4: =TRIM('수출입 실적(품목별)'!B8) -> 02 | E4: =TRIM('수출입 실적(품목별)'!C8) -> 육과 식용 설육(屑肉) | F4: =IFERROR(VALUE(SUBSTITUTE(TRIM('수출입 실적(품목별)'!E8),",","")),"") -> 5868 | G4: =IFERROR(VALUE(SUBSTITUTE(TRIM('수출입 실적(품목별)'!G8),",","")),"") -> 728984 | H4: =IFERROR(VALUE(SUBSTITUTE(TRIM('수출입 실적(품목별)'!H8),",","")),"") -> -723116
A5: =TRIM('수출입 실적(품목별)'!A9) -> 2025.01 | B5: =IFERROR(VALUE(LEFT(A5,4)),"") -> 2025 | C5: =IFERROR(VALUE(RIGHT(A5,2)),"") -> 1 | D5: =TRIM('수출입 실적(품목별)'!B9) -> 03 | E5: =TRIM('수출입 실적(품목별)'!C9) -> 어류ㆍ갑각류ㆍ연체동물과 그 밖의 수생(水生) 무척추동물 | F5: =IFERROR(VALUE(SUBSTITUTE(TRIM('수출입 실적(품목별)'!E9),",","")),"") -> 98077 | G5: =IFERROR(VALUE(SUBSTITUTE(TRIM('수출입 실적(품목별)'!G9),",","")),"") -> 406964 | H5: =IFERROR(VALUE(SUBSTITUTE(TRIM('수출입 실적(품목별)'!H9),",","")),"") -> -308888
A6: =TRIM('수출입 실적(품목별)'!A10) -> 2025.01 | B6: =IFERROR(VALUE(LEFT(A6,4)),"") -> 2025 | C6: =IFERROR(VALUE(RIGHT(A6,2)),"") -> 1 | D6: =TRIM('수출입 실적(품목별)'!B10) -> 04 | E6: =TRIM('수출입 실적(품목별)'!C10) -> 낙농품, 새의 알, 천연꿀, 다른 류로 분류되지 않은 식용인 동물성 생산품 | F6: =IFERROR(VALUE(SUBSTITUTE(TRIM('수출입 실적(품목별)'!E10),",","")),"") -> 6510 | G6: =IFERROR(VALUE(SUBSTITUTE(TRIM('수출입 실적(품목별)'!G10),",","")),"") -> 110511 | H6: =IFERROR(VALUE(SUBSTITUTE(TRIM('수출입 실적(품목별)'!H10),",","")),"") -> -104002
A7: =TRIM('수출입 실적(품목별)'!A11) -> 2025.01 | B7: =IFERROR(VALUE(LEFT(A7,4)),"") -> 2025 | C7: =IFERROR(VALUE(RIGHT(A7,2)),"") -> 1 | D7: =TRIM('수출입 실적(품목별)'!B11) -> 05 | E7: =TRIM('수출입 실적(품목별)'!C11) -> 다른 류로 분류되지 않은 동물성 생산품 | F7: =IFERROR(VALUE(SUBSTITUTE(TRIM('수출입 실적(품목별)'!E11),",","")),"") -> 2877 | G7: =IFERROR(VALUE(SUBSTITUTE(TRIM('수출입 실적(품목별)'!G11),",","")),"") -> 20120 | H7: =IFERROR(VALUE(SUBSTITUTE(TRIM('수출입 실적(품목별)'!H11),",","")),"") -> -17243
A8: =TRIM('수출입 실적(품목별)'!A12) -> 2025.01 | B8: =IFERROR(VALUE(LEFT(A8,4)),"") -> 2025 | C8: =IFERROR(VALUE(RIGHT(A8,2)),"") -> 1 | D8: =TRIM('수출입 실적(품목별)'!B12) -> 06 | E8: =TRIM('수출입 실적(품목별)'!C12) -> 살아 있는 수목과 그 밖의 식물, 인경(鱗莖)ㆍ뿌리와 이와 유사한 물품, 절화(切花)와 장식용 잎 | F8: =IFERROR(VALUE(SUBSTITUTE(TRIM('수출입 실적(품목별)'!E12),",","")),"") -> 418 | G8: =IFERROR(VALUE(SUBSTITUTE(TRIM('수출입 실적(품목별)'!G12),",","")),"") -> 13617 | H8: =IFERROR(VALUE(SUBSTITUTE(TRIM('수출입 실적(품목별)'!H12),",","")),"") -> -13199
A9: =TRIM('수출입 실적(품목별)'!A13) -> 2025.01 | B9: =IFERROR(VALUE(LEFT(A9,4)),"") -> 2025 | C9: =IFERROR(VALUE(RIGHT(A9,2)),"") -> 1 | D9: =TRIM('수출입 실적(품목별)'!B13) -> 07 | E9: =TRIM('수출입 실적(품목별)'!C13) -> 식용의 채소ㆍ뿌리ㆍ괴경(塊莖) | F9: =IFERROR(VALUE(SUBSTITUTE(TRIM('수출입 실적(품목별)'!E13),",","")),"") -> 9802 | G9: =IFERROR(VALUE(SUBSTITUTE(TRIM('수출입 실적(품목별)'!G13),",","")),"") -> 75650 | H9: =IFERROR(VALUE(SUBSTITUTE(TRIM('수출입 실적(품목별)'!H13),",","")),"") -> -65848
A10: =TRIM('수출입 실적(품목별)'!A14) -> 2025.01 | B10: =IFERROR(VALUE(LEFT(A10,4)),"") -> 2025 | C10: =IFERROR(VALUE(RIGHT(A10,2)),"") -> 1 | D10: =TRIM('수출입 실적(품목별)'!B14) -> 08 | E10: =TRIM('수출입 실적(품목별)'!C14) -> 식용의 과실과 견과류, 감귤류ㆍ멜론의 껍질 | F10: =IFERROR(VALUE(SUBSTITUTE(TRIM('수출입 실적(품목별)'!E14),",","")),"") -> 26837 | G10: =IFERROR(VALUE(SUBSTITUTE(TRIM('수출입 실적(품목별)'!G14),",","")),"") -> 144994 | H10: =IFERROR(VALUE(SUBSTITUTE(TRIM('수출입 실적(품목별)'!H14),",","")),"") -> -118157
A11: =TRIM('수출입 실적(품목별)'!A15) -> 2025.01 | B11: =IFERROR(VALUE(LEFT(A11,4)),"") -> 2025 | C11: =IFERROR(VALUE(RIGHT(A11,2)),"") -> 1 | D11: =TRIM('수출입 실적(품목별)'!B15) -> 09 | E11: =TRIM('수출입 실적(품목별)'!C15) -> 커피ㆍ차ㆍ마테(maté)ㆍ향신료 | F11: =IFERROR(VALUE(SUBSTITUTE(TRIM('수출입 실적(품목별)'!E15),",","")),"") -> 2706 | G11: =IFERROR(VALUE(SUBSTITUTE(TRIM('수출입 실적(품목별)'!G15),",","")),"") -> 109715 | H11: =IFERROR(VALUE(SUBSTITUTE(TRIM('수출입 실적(품목별)'!H15),",","")),"") -> -107009
A12: =TRIM('수출입 실적(품목별)'!A16) -> 2025.01 | B12: =IFERROR(VALUE(LEFT(A12,4)),"") -> 2025 | C12: =IFERROR(VALUE(RIGHT(A12,2)),"") -> 1 | D12: =TRIM('수출입 실적(품목별)'!B16) -> 10 | E12: =TRIM('수출입 실적(품목별)'!C16) -> 곡물 | F12: =IFERROR(VALUE(SUBSTITUTE(TRIM('수출입 실적(품목별)'!E16),",","")),"") -> 3159 | G12: =IFERROR(VALUE(SUBSTITUTE(TRIM('수출입 실적(품목별)'!G16),",","")),"") -> 363115 | H12: =IFERROR(VALUE(SUBSTITUTE(TRIM('수출입 실적(품목별)'!H16),",","")),"") -> -359956
A13: =TRIM('수출입 실적(품목별)'!A17) -> 2025.01 | B13: =IFERROR(VALUE(LEFT(A13,4)),"") -> 2025 | C13: =IFERROR(VALUE(RIGHT(A13,2)),"") -> 1 | D13: =TRIM('수출입 실적(품목별)'!B17) -> 11 | E13: =TRIM('수출입 실적(품목별)'!C17) -> 제분공업의 생산품과 맥아, 전분, 이눌린(inulin), 밀의 글루텐(gluten) | F13: =IFERROR(VALUE(SUBSTITUTE(TRIM('수출입 실적(품목별)'!E17),",","")),"") -> 3474 | G13: =IFERROR(VALUE(SUBSTITUTE(TRIM('수출입 실적(품목별)'!G17),",","")),"") -> 23263 | H13: =IFERROR(VALUE(SUBSTITUTE(TRIM('수출입 실적(품목별)'!H17),",","")),"") -> -19789
A14: =TRIM('수출입 실적(품목별)'!A18) -> 2025.01 | B14: =IFERROR(VALUE(LEFT(A14,4)),"") -> 2025 | C14: =IFERROR(VALUE(RIGHT(A14,2)),"") -> 1 | D14: =TRIM('수출입 실적(품목별)'!B18) -> 12 | E14: =TRIM('수출입 실적(품목별)'!C18) -> 채유(採油)에 적합한 종자와 과실, 각종 종자와 과실, 공업용ㆍ의약용 식물, 짚과 사료용 식물 | F14: =IFERROR(VALUE(SUBSTITUTE(TRIM('수출입 실적(품목별)'!E18),",","")),"") -> 53582 | G14: =IFERROR(VALUE(SUBSTITUTE(TRIM('수출입 실적(품목별)'!G18),",","")),"") -> 141767 | H14: =IFERROR(VALUE(SUBSTITUTE(TRIM('수출입 실적(품목별)'!H18),",","")),"") -> -88185
... A1828: =TRIM('수출입 실적(품목별)'!A1832) -> 2026.07 | B1828: =IFERROR(VALUE(LEFT(A1828,4)),"") -> 2026 | C1828: =IFERROR(VALUE(RIGHT(A1828,2)),"") -> 7 | D1828: =TRIM('수출입 실적(품목별)'!B1832) -> 97 | E1828: =TRIM('수출입 실적(품목별)'!C1832) -> 예술품ㆍ수집품ㆍ골동품 | F1828: =IFERROR(VALUE(SUBSTITUTE(TRIM('수출입 실적(품목별)'!E1832),",","")),"") -> 15110 | G1828: =IFERROR(VALUE(SUBSTITUTE(TRIM('수출입 실적(품목별)'!G1832),",","")),"") -> 20791 | H1828: =IFERROR(VALUE(SUBSTITUTE(TRIM('수출입 실적(품목별)'!H1832),",","")),"") -> -5681

Sheet 데이터_국가별
A1: 이 시트의 모든 셀은 원본 시트를 참조하는 수식입니다. 원본은 숫자가 텍스트(쉼표 포함)로 저장되어 있어 VALUE/SUBSTITUTE로 숫자화했습니다. 직접 입력하지 마세요.
A2: 기간 | B2: 연도 | C2: 월 | D2: 국가 | E2: 수출 금액 | F2: 수입 금액 | G2: 무역수지
A3: =TRIM('수출입 실적(국가별)'!A7) -> 2025.01 | B3: =IFERROR(VALUE(LEFT(A3,4)),"") -> 2025 | C3: =IFERROR(VALUE(RIGHT(A3,2)),"") -> 1 | D3: =TRIM('수출입 실적(국가별)'!B7) -> 미국 | E3: =IFERROR(VALUE(SUBSTITUTE(TRIM('수출입 실적(국가별)'!D7),",","")),"") -> 9282567 | F3: =IFERROR(VALUE(SUBSTITUTE(TRIM('수출입 실적(국가별)'!F7),",","")),"") -> 5839341 | G3: =IFERROR(VALUE(SUBSTITUTE(TRIM('수출입 실적(국가별)'!G7),",","")),"") -> 3443226
A4: =TRIM('수출입 실적(국가별)'!A8) -> 2025.01 | B4: =IFERROR(VALUE(LEFT(A4,4)),"") -> 2025 | C4: =IFERROR(VALUE(RIGHT(A4,2)),"") -> 1 | D4: =TRIM('수출입 실적(국가별)'!B8) -> 중국 | E4: =IFERROR(VALUE(SUBSTITUTE(TRIM('수출입 실적(국가별)'!D8),",","")),"") -> 9204172 | F4: =IFERROR(VALUE(SUBSTITUTE(TRIM('수출입 실적(국가별)'!F8),",","")),"") -> 11208793 | G4: =IFERROR(VALUE(SUBSTITUTE(TRIM('수출입 실적(국가별)'!G8),",","")),"") -> -2004621
A5: =TRIM('수출입 실적(국가별)'!A9) -> 2025.01 | B5: =IFERROR(VALUE(LEFT(A5,4)),"") -> 2025 | C5: =IFERROR(VALUE(RIGHT(A5,2)),"") -> 1 | D5: =TRIM('수출입 실적(국가별)'!B9) -> 베트남 | E5: =IFERROR(VALUE(SUBSTITUTE(TRIM('수출입 실적(국가별)'!D9),",","")),"") -> 4356972 | F5: =IFERROR(VALUE(SUBSTITUTE(TRIM('수출입 실적(국가별)'!F9),",","")),"") -> 2564727 | G5: =IFERROR(VALUE(SUBSTITUTE(TRIM('수출입 실적(국가별)'!G9),",","")),"") -> 1792245
A6: =TRIM('수출입 실적(국가별)'!A10) -> 2025.01 | B6: =IFERROR(VALUE(LEFT(A6,4)),"") -> 2025 | C6: =IFERROR(VALUE(RIGHT(A6,2)),"") -> 1 | D6: =TRIM('수출입 실적(국가별)'!B10) -> 대만 | E6: =IFERROR(VALUE(SUBSTITUTE(TRIM('수출입 실적(국가별)'!D10),",","")),"") -> 2438188 | F6: =IFERROR(VALUE(SUBSTITUTE(TRIM('수출입 실적(국가별)'!F10),",","")),"") -> 2227887 | G6: =IFERROR(VALUE(SUBSTITUTE(TRIM('수출입 실적(국가별)'!G10),",","")),"") -> 210301
A7: =TRIM('수출입 실적(국가별)'!A11) -> 2025.01 | B7: =IFERROR(VALUE(LEFT(A7,4)),"") -> 2025 | C7: =IFERROR(VALUE(RIGHT(A7,2)),"") -> 1 | D7: =TRIM('수출입 실적(국가별)'!B11) -> 일본 | E7: =IFERROR(VALUE(SUBSTITUTE(TRIM('수출입 실적(국가별)'!D11),",","")),"") -> 2363797 | F7: =IFERROR(VALUE(SUBSTITUTE(TRIM('수출입 실적(국가별)'!F11),",","")),"") -> 3587345 | G7: =IFERROR(VALUE(SUBSTITUTE(TRIM('수출입 실적(국가별)'!G11),",","")),"") -> -1223548
A8: =TRIM('수출입 실적(국가별)'!A12) -> 2025.01 | B8: =IFERROR(VALUE(LEFT(A8,4)),"") -> 2025 | C8: =IFERROR(VALUE(RIGHT(A8,2)),"") -> 1 | D8: =TRIM('수출입 실적(국가별)'!B12) -> 홍콩 | E8: =IFERROR(VALUE(SUBSTITUTE(TRIM('수출입 실적(국가별)'!D12),",","")),"") -> 1685484 | F8: =IFERROR(VALUE(SUBSTITUTE(TRIM('수출입 실적(국가별)'!F12),",","")),"") -> 183373 | G8: =IFERROR(VALUE(SUBSTITUTE(TRIM('수출입 실적(국가별)'!G12),",","")),"") -> 1502111
A9: =TRIM('수출입 실적(국가별)'!A13) -> 2025.01 | B9: =IFERROR(VALUE(LEFT(A9,4)),"") -> 2025 | C9: =IFERROR(VALUE(RIGHT(A9,2)),"") -> 1 | D9: =TRIM('수출입 실적(국가별)'!B13) -> 인도 | E9: =IFERROR(VALUE(SUBSTITUTE(TRIM('수출입 실적(국가별)'!D13),",","")),"") -> 1463921 | F9: =IFERROR(VALUE(SUBSTITUTE(TRIM('수출입 실적(국가별)'!F13),",","")),"") -> 535824 | G9: =IFERROR(VALUE(SUBSTITUTE(TRIM('수출입 실적(국가별)'!G13),",","")),"") -> 928097
A10: =TRIM('수출입 실적(국가별)'!A14) -> 2025.01 | B10: =IFERROR(VALUE(LEFT(A10,4)),"") -> 2025 | C10: =IFERROR(VALUE(RIGHT(A10,2)),"") -> 1 | D10: =TRIM('수출입 실적(국가별)'!B14) -> 싱가포르 | E10: =IFERROR(VALUE(SUBSTITUTE(TRIM('수출입 실적(국가별)'!D14),",","")),"") -> 1162020 | F10: =IFERROR(VALUE(SUBSTITUTE(TRIM('수출입 실적(국가별)'!F14),",","")),"") -> 1027832 | G10: =IFERROR(VALUE(SUBSTITUTE(TRIM('수출입 실적(국가별)'!G14),",","")),"") -> 134187
A11: =TRIM('수출입 실적(국가별)'!A15) -> 2025.01 | B11: =IFERROR(VALUE(LEFT(A11,4)),"") -> 2025 | C11: =IFERROR(VALUE(RIGHT(A11,2)),"") -> 1 | D11: =TRIM('수출입 실적(국가별)'!B15) -> 멕시코 | E11: =IFERROR(VALUE(SUBSTITUTE(TRIM('수출입 실적(국가별)'!D15),",","")),"") -> 947164 | F11: =IFERROR(VALUE(SUBSTITUTE(TRIM('수출입 실적(국가별)'!F15),",","")),"") -> 767989 | G11: =IFERROR(VALUE(SUBSTITUTE(TRIM('수출입 실적(국가별)'!G15),",","")),"") -> 179176
A12: =TRIM('수출입 실적(국가별)'!A16) -> 2025.01 | B12: =IFERROR(VALUE(LEFT(A12,4)),"") -> 2025 | C12: =IFERROR(VALUE(RIGHT(A12,2)),"") -> 1 | D12: =TRIM('수출입 실적(국가별)'!B16) -> 말레이시아 | E12: =IFERROR(VALUE(SUBSTITUTE(TRIM('수출입 실적(국가별)'!D16),",","")),"") -> 921582 | F12: =IFERROR(VALUE(SUBSTITUTE(TRIM('수출입 실적(국가별)'!F16),",","")),"") -> 1350979 | G12: =IFERROR(VALUE(SUBSTITUTE(TRIM('수출입 실적(국가별)'!G16),",","")),"") -> -429397
A13: =TRIM('수출입 실적(국가별)'!A17) -> 2025.01 | B13: =IFERROR(VALUE(LEFT(A13,4)),"") -> 2025 | C13: =IFERROR(VALUE(RIGHT(A13,2)),"") -> 1 | D13: =TRIM('수출입 실적(국가별)'!B17) -> 호주 | E13: =IFERROR(VALUE(SUBSTITUTE(TRIM('수출입 실적(국가별)'!D17),",","")),"") -> 909427 | F13: =IFERROR(VALUE(SUBSTITUTE(TRIM('수출입 실적(국가별)'!F17),",","")),"") -> 2906682 | G13: =IFERROR(VALUE(SUBSTITUTE(TRIM('수출입 실적(국가별)'!G17),",","")),"") -> -1997255
A14: =TRIM('수출입 실적(국가별)'!A18) -> 2025.01 | B14: =IFERROR(VALUE(LEFT(A14,4)),"") -> 2025 | C14: =IFERROR(VALUE(RIGHT(A14,2)),"") -> 1 | D14: =TRIM('수출입 실적(국가별)'!B18) -> 필리핀 | E14: =IFERROR(VALUE(SUBSTITUTE(TRIM('수출입 실적(국가별)'!D18),",","")),"") -> 880737 | F14: =IFERROR(VALUE(SUBSTITUTE(TRIM('수출입 실적(국가별)'!F18),",","")),"") -> 229072 | G14: =IFERROR(VALUE(SUBSTITUTE(TRIM('수출입 실적(국가별)'!G18),",","")),"") -> 651665
... A4477: =TRIM('수출입 실적(국가별)'!A4481) -> 2026.07 | B4477: =IFERROR(VALUE(LEFT(A4477,4)),"") -> 2026 | C4477: =IFERROR(VALUE(RIGHT(A4477,2)),"") -> 7 | D4477: =TRIM('수출입 실적(국가별)'!B4481) -> 세인트 헬레나 | E4477: =IFERROR(VALUE(SUBSTITUTE(TRIM('수출입 실적(국가별)'!D4481),",","")),"") -> 0 | F4477: =IFERROR(VALUE(SUBSTITUTE(TRIM('수출입 실적(국가별)'!F4481),",","")),"") -> 13 | G4477: =IFERROR(VALUE(SUBSTITUTE(TRIM('수출입 실적(국가별)'!G4481),",","")),"") -> -13

Sheet 분석1_정합성검증
A1: ① 합계 정합성 검증 — 개별항목의 합 vs 총합 (5개 원본 시트 교차)
A2: 원본 5개 시트는 숫자가 텍스트로 저장되어 있어 「데이터_○○」 정제 시트(수식)를 거쳐 검증합니다. 원본 시트는 수정하지 않았습니다.
A3: 허용오차 : 원본이 반올림 제공되므로 아래 값 이내의 차이는 반올림 오차로 판정합니다. (노란색 = 입력 셀)
A4: 허용오차(중량, 톤) | B4: 1 | C4: 허용오차(금액, 천달러) | D4: 50 | E4: 국가별·품목별 허용오차 | F4: 500 | G4: 행 수가 많은 시트(국가별 4,475행·품목별 1,826행)는 반올림 누적이 커서 별도 허용오차를 둡니다.
A6: [검증 1] 「수출입 총괄」 총계행 vs 19개월(2025.01~2026.07) 합계
A7: 항목 | B7: 총계행(원본) | C7: 월별 합계 | D7: 차이 | E7: 판정
A8: 조업일수 | B8: =IFERROR(VALUE(SUBSTITUTE(TRIM('수출입 총괄'!B6),",","")),"") -> 425 | C8: =SUM(데이터_총괄!D3:D21) -> 425 | D8: =B8-C8 -> 0 | E8: =IF(ABS(D8)<=$B$4,"일치(반올림오차 이내)","불일치") -> 일치(반올림오차 이내)
A9: 수출 건수 | B9: =IFERROR(VALUE(SUBSTITUTE(TRIM('수출입 총괄'!C6),",","")),"") -> 21702845 | C9: =SUM(데이터_총괄!E3:E21) -> 21702845 | D9: =B9-C9 -> 0 | E9: =IF(ABS(D9)<=$D$4,"일치(반올림오차 이내)","불일치") -> 일치(반올림오차 이내)
A10: 수출 중량(톤) | B10: =IFERROR(VALUE(SUBSTITUTE(TRIM('수출입 총괄'!D6),",","")),"") -> 3.0841275e+08 | C10: =SUM(데이터_총괄!F3:F21) -> 3.0841275e+08 | D10: =B10-C10 -> -0.19999999 | E10: =IF(ABS(D10)<=$B$4,"일치(반올림오차 이내)","불일치") -> 일치(반올림오차 이내)
A11: 수출 금액(천$) | B11: =IFERROR(VALUE(SUBSTITUTE(TRIM('수출입 총괄'!E6),",","")),"") -> 1304392880 | C11: =SUM(데이터_총괄!G3:G21) -> 1304392880 | D11: =B11-C11 -> 0 | E11: =IF(ABS(D11)<=$D$4,"일치(반올림오차 이내)","불일치") -> 일치(반올림오차 이내)
A12: 수입 건수 | B12: =IFERROR(VALUE(SUBSTITUTE(TRIM('수출입 총괄'!F6),",","")),"") -> 88995973 | C12: =SUM(데이터_총괄!H3:H21) -> 88995973 | D12: =B12-C12 -> 0 | E12: =IF(ABS(D12)<=$D$4,"일치(반올림오차 이내)","불일치") -> 일치(반올림오차 이내)
A13: 수입 중량(톤) | B13: =IFERROR(VALUE(SUBSTITUTE(TRIM('수출입 총괄'!G6),",","")),"") -> 8.5838164e+08 | C13: =SUM(데이터_총괄!I3:I21) -> 8.5838164e+08 | D13: =B13-C13 -> -0.10000002 | E13: =IF(ABS(D13)<=$B$4,"일치(반올림오차 이내)","불일치") -> 일치(반올림오차 이내)
A14: 수입 금액(천$) | B14: =IFERROR(VALUE(SUBSTITUTE(TRIM('수출입 총괄'!H6),",","")),"") -> 1059198512 | C14: =SUM(데이터_총괄!J3:J21) -> 1059198513 | D14: =B14-C14 -> -1 | E14: =IF(ABS(D14)<=$D$4,"일치(반올림오차 이내)","불일치") -> 일치(반올림오차 이내)
A15: 무역수지(천$) | B15: =IFERROR(VALUE(SUBSTITUTE(TRIM('수출입 총괄'!I6),",","")),"") -> 245194368 | C15: =SUM(데이터_총괄!K3:K21) -> 245194366 | D15: =B15-C15 -> 2 | E15: =IF(ABS(D15)<=$D$4,"일치(반올림오차 이내)","불일치") -> 일치(반올림오차 이내)
A17: [검증 2] 무역수지 항등식 : 수출금액 − 수입금액 = 무역수지
A18: 기간 | B18: 수출금액 | C18: 수입금액 | D18: 계산값 | E18: 원본 무역수지 | F18: 차이 | G18: 판정
A19: =데이터_총괄!A3 -> 2025.01 | B19: =데이터_총괄!G3 -> 49176984 | C19: =데이터_총괄!J3 -> 51172292 | D19: =B19-C19 -> -1995308 | E19: =데이터_총괄!K3 -> -1995308 | F19: =D19-E19 -> 0 | G19: =IF(ABS(F19)<=$D$4,"일치","불일치") -> 일치
A20: =데이터_총괄!A4 -> 2025.02 | B20: =데이터_총괄!G4 -> 52292301 | C20: =데이터_총괄!J4 -> 48328741 | D20: =B20-C20 -> 3963560 | E20: =데이터_총괄!K4 -> 3963560 | F20: =D20-E20 -> 0 | G20: =IF(ABS(F20)<=$D$4,"일치","불일치") -> 일치
A21: =데이터_총괄!A5 -> 2025.03 | B21: =데이터_총괄!G5 -> 58064562 | C21: =데이터_총괄!J5 -> 53341032 | D21: =B21-C21 -> 4723530 | E21: =데이터_총괄!K5 -> 4723530 | F21: =D21-E21 -> 0 | G21: =IF(ABS(F21)<=$D$4,"일치","불일치") -> 일치
A22: =데이터_총괄!A6 -> 2025.04 | B22: =데이터_총괄!G6 -> 58035745 | C22: =데이터_총괄!J6 -> 53232716 | D22: =B22-C22 -> 4803029 | E22: =데이터_총괄!K6 -> 4803029 | F22: =D22-E22 -> 0 | G22: =IF(ABS(F22)<=$D$4,"일치","불일치") -> 일치
A23: =데이터_총괄!A7 -> 2025.05 | B23: =데이터_총괄!G7 -> 57261063 | C23: =데이터_총괄!J7 -> 50345116 | D23: =B23-C23 -> 6915947 | E23: =데이터_총괄!K7 -> 6915946 | F23: =D23-E23 -> 1 | G23: =IF(ABS(F23)<=$D$4,"일치","불일치") -> 일치
A24: =데이터_총괄!A8 -> 2025.06 | B24: =데이터_총괄!G8 -> 59833797 | C24: =데이터_총괄!J8 -> 50825746 | D24: =B24-C24 -> 9008051 | E24: =데이터_총괄!K8 -> 9008051 | F24: =D24-E24 -> 0 | G24: =IF(ABS(F24)<=$D$4,"일치","불일치") -> 일치
A25: =데이터_총괄!A9 -> 2025.07 | B25: =데이터_총괄!G9 -> 60724322 | C25: =데이터_총괄!J9 -> 54210371 | D25: =B25-C25 -> 6513951 | E25: =데이터_총괄!K9 -> 6513951 | F25: =D25-E25 -> 0 | G25: =IF(ABS(F25)<=$D$4,"일치","불일치") -> 일치
A26: =데이터_총괄!A10 -> 2025.08 | B26: =데이터_총괄!G10 -> 58259332 | C26: =데이터_총괄!J10 -> 51856624 | D26: =B26-C26 -> 6402708 | E26: =데이터_총괄!K10 -> 6402708 | F26: =D26-E26 -> 0 | G26: =IF(ABS(F26)<=$D$4,"일치","불일치") -> 일치
A27: =데이터_총괄!A11 -> 2025.09 | B27: =데이터_총괄!G11 -> 65904118 | C27: =데이터_총괄!J11 -> 56419614 | D27: =B27-C27 -> 9484504 | E27: =데이터_총괄!K11 -> 9484504 | F27: =D27-E27 -> 0 | G27: =IF(ABS(F27)<=$D$4,"일치","불일치") -> 일치
A28: =데이터_총괄!A12 -> 2025.10 | B28: =데이터_총괄!G12 -> 59511578 | C28: =데이터_총괄!J12 -> 53510827 | D28: =B28-C28 -> 6000751 | E28: =데이터_총괄!K12 -> 6000751 | F28: =D28-E28 -> 0 | G28: =IF(ABS(F28)<=$D$4,"일치","불일치") -> 일치
A29: =데이터_총괄!A13 -> 2025.11 | B29: =데이터_총괄!G13 -> 60752618 | C29: =데이터_총괄!J13 -> 51284605 | D29: =B29-C29 -> 9468013 | E29: =데이터_총괄!K13 -> 9468013 | F29: =D29-E29 -> 0 | G29: =IF(ABS(F29)<=$D$4,"일치","불일치") -> 일치
A30: =데이터_총괄!A14 -> 2025.12 | B30: =데이터_총괄!G14 -> 69513624 | C30: =데이터_총괄!J14 -> 57367684 | D30: =B30-C30 -> 12145940 | E30: =데이터_총괄!K14 -> 12145941 | F30: =D30-E30 -> -1 | G30: =IF(ABS(F30)<=$D$4,"일치","불일치") -> 일치
... A37: =데이터_총괄!A21 -> 2026.07 | B37: =데이터_총괄!G21 -> 98959099 | C37: =데이터_총괄!J21 -> 68567473 | D37: =B37-C37 -> 30391626 | E37: =데이터_총괄!K21 -> 30391625 | F37: =D37-E37 -> 1 | G37: =IF(ABS(F37)<=$D$4,"일치","불일치") -> 일치
A39: [검증 3] 「성질별」 대분류 4개 합 vs 「총괄」 수출 (월별)
A40: 기간 | B40: 성질별 금액 합 | C40: 총괄 수출금액 | D40: 차이 | E40: 판정 | F40: 성질별 중량 합 | G40: 총괄 수출중량 | H40: 차이 | I40: 판정
A41: =데이터_총괄!A3 -> 2025.01 | B41: =데이터_성질별!F3+데이터_성질별!F4+데이터_성질별!F5+데이터_성질별!F17 -> 49176984 | C41: =데이터_총괄!G3 -> 49176984 | D41: =B41-C41 -> 0 | E41: =IF(ABS(D41)<=$D$4,"일치","불일치") -> 일치 | F41: =데이터_성질별!E3+데이터_성질별!E4+데이터_성질별!E5+데이터_성질별!E17 -> 14986302 | G41: =데이터_총괄!F3 -> 14986302 | H41: =F41-G41 -> 0 | I41: =IF(ABS(H41)<=$B$4,"일치","불일치") -> 일치
A42: =데이터_총괄!A4 -> 2025.02 | B42: =데이터_성질별!F24+데이터_성질별!F25+데이터_성질별!F26+데이터_성질별!F38 -> 52292301 | C42: =데이터_총괄!G4 -> 52292301 | D42: =B42-C42 -> 0 | E42: =IF(ABS(D42)<=$D$4,"일치","불일치") -> 일치 | F42: =데이터_성질별!E24+데이터_성질별!E25+데이터_성질별!E26+데이터_성질별!E38 -> 16151895 | G42: =데이터_총괄!F4 -> 16151895 | H42: =F42-G42 -> -0.1 | I42: =IF(ABS(H42)<=$B$4,"일치","불일치") -> 일치
A43: =데이터_총괄!A5 -> 2025.03 | B43: =데이터_성질별!F45+데이터_성질별!F46+데이터_성질별!F47+데이터_성질별!F59 -> 58064561 | C43: =데이터_총괄!G5 -> 58064562 | D43: =B43-C43 -> -1 | E43: =IF(ABS(D43)<=$D$4,"일치","불일치") -> 일치 | F43: =데이터_성질별!E45+데이터_성질별!E46+데이터_성질별!E47+데이터_성질별!E59 -> 15702060 | G43: =데이터_총괄!F5 -> 15702060 | H43: =F43-G43 -> -0.1 | I43: =IF(ABS(H43)<=$B$4,"일치","불일치") -> 일치
A44: =데이터_총괄!A6 -> 2025.04 | B44: =데이터_성질별!F66+데이터_성질별!F67+데이터_성질별!F68+데이터_성질별!F80 -> 58035745 | C44: =데이터_총괄!G6 -> 58035745 | D44: =B44-C44 -> 0 | E44: =IF(ABS(D44)<=$D$4,"일치","불일치") -> 일치 | F44: =데이터_성질별!E66+데이터_성질별!E67+데이터_성질별!E68+데이터_성질별!E80 -> 17527805 | G44: =데이터_총괄!F6 -> 17527805 | H44: =F44-G44 -> 0 | I44: =IF(ABS(H44)<=$B$4,"일치","불일치") -> 일치
A45: =데이터_총괄!A7 -> 2025.05 | B45: =데이터_성질별!F87+데이터_성질별!F88+데이터_성질별!F89+데이터_성질별!F101 -> 57261063 | C45: =데이터_총괄!G7 -> 57261063 | D45: =B45-C45 -> 0 | E45: =IF(ABS(D45)<=$D$4,"일치","불일치") -> 일치 | F45: =데이터_성질별!E87+데이터_성질별!E88+데이터_성질별!E89+데이터_성질별!E101 -> 16573463 | G45: =데이터_총괄!F7 -> 16573463 | H45: =F45-G45 -> 0 | I45: =IF(ABS(H45)<=$B$4,"일치","불일치") -> 일치
A46: =데이터_총괄!A8 -> 2025.06 | B46: =데이터_성질별!F108+데이터_성질별!F109+데이터_성질별!F110+데이터_성질별!F122 -> 59833797 | C46: =데이터_총괄!G8 -> 59833797 | D46: =B46-C46 -> 0 | E46: =IF(ABS(D46)<=$D$4,"일치","불일치") -> 일치 | F46: =데이터_성질별!E108+데이터_성질별!E109+데이터_성질별!E110+데이터_성질별!E122 -> 16221157 | G46: =데이터_총괄!F8 -> 16221157 | H46: =F46-G46 -> 0.1 | I46: =IF(ABS(H46)<=$B$4,"일치","불일치") -> 일치
A47: =데이터_총괄!A9 -> 2025.07 | B47: =데이터_성질별!F129+데이터_성질별!F130+데이터_성질별!F131+데이터_성질별!F143 -> 60724322 | C47: =데이터_총괄!G9 -> 60724322 | D47: =B47-C47 -> 0 | E47: =IF(ABS(D47)<=$D$4,"일치","불일치") -> 일치 | F47: =데이터_성질별!E129+데이터_성질별!E130+데이터_성질별!E131+데이터_성질별!E143 -> 17580838 | G47: =데이터_총괄!F9 -> 17580838 | H47: =F47-G47 -> 0 | I47: =IF(ABS(H47)<=$B$4,"일치","불일치") -> 일치
A48: =데이터_총괄!A10 -> 2025.08 | B48: =데이터_성질별!F150+데이터_성질별!F151+데이터_성질별!F152+데이터_성질별!F164 -> 58259333 | C48: =데이터_총괄!G10 -> 58259332 | D48: =B48-C48 -> 1 | E48: =IF(ABS(D48)<=$D$4,"일치","불일치") -> 일치 | F48: =데이터_성질별!E150+데이터_성질별!E151+데이터_성질별!E152+데이터_성질별!E164 -> 17118674 | G48: =데이터_총괄!F10 -> 17118674 | H48: =F48-G48 -> 0 | I48: =IF(ABS(H48)<=$B$4,"일치","불일치") -> 일치
A49: =데이터_총괄!A11 -> 2025.09 | B49: =데이터_성질별!F171+데이터_성질별!F172+데이터_성질별!F173+데이터_성질별!F185 -> 65904118 | C49: =데이터_총괄!G11 -> 65904118 | D49: =B49-C49 -> 0 | E49: =IF(ABS(D49)<=$D$4,"일치","불일치") -> 일치 | F49: =데이터_성질별!E171+데이터_성질별!E172+데이터_성질별!E173+데이터_성질별!E185 -> 18076703 | G49: =데이터_총괄!F11 -> 18076703 | H49: =F49-G49 -> 0 | I49: =IF(ABS(H49)<=$B$4,"일치","불일치") -> 일치
...

Sheet 분석2_월별추이
A1: ② 월별 추이 (2025.01 ~ 2026.07, 19개월)
A2: 「데이터_총괄」을 참조합니다. 일평균 = 금액÷조업일수(영업일 보정), 단가 = 금액÷중량, 순상품교역조건 = 수출단가÷수입단가.
A3: 전년동월비는 12개월 전 값이 있는 2026.01부터 계산됩니다. 12개월 이동합은 최근 12개월 누계로, 계절성을 제거한 추세선입니다.
A5: 기간 | B5: 조업일수 | C5: 수출 건수 | D5: 수출 중량(톤) | E5: 수출 금액(천$) | F5: 수입 금액(천$) | G5: 무역수지(천$) | H5: 수출 전월비 | I5: 수입 전월비 | J5: 수출 전년동월비 | K5: 수입 전년동월비 | L5: 수지 전년동월증감 | M5: 일평균 수출(천$) | N5: 일평균 전월비 | O5: 수출단가(천$/톤) | P5: 수입단가(천$/톤) | Q5: 순상품교역조건 | R5: 수출 12개월 이동합 | S5: 수지 12개월 이동합
A6: =데이터_총괄!A3 -> 2025.01 | B6: =데이터_총괄!D3 -> 20 | C6: =데이터_총괄!E3 -> 924441 | D6: =데이터_총괄!F3 -> 14986302 | E6: =데이터_총괄!G3 -> 49176984 | F6: =데이터_총괄!J3 -> 51172292 | G6: =데이터_총괄!K3 -> -1995308 | M6: =E6/B6 -> 2458849.2 | O6: =E6/D6 -> 3.2814623 | P6: =F6/데이터_총괄!I3 -> 1.0677057 | Q6: =O6/P6 -> 3.0733771
A7: =데이터_총괄!A4 -> 2025.02 | B7: =데이터_총괄!D4 -> 22 | C7: =데이터_총괄!E4 -> 1014431 | D7: =데이터_총괄!F4 -> 16151895 | E7: =데이터_총괄!G4 -> 52292301 | F7: =데이터_총괄!J4 -> 48328741 | G7: =데이터_총괄!K4 -> 3963560 | H7: =E7/E6-1 -> 0.063349086 | I7: =F7/F6-1 -> -0.055568177 | M7: =E7/B7 -> 2376922.8 | N7: =M7/M6-1 -> -0.033319013 | O7: =E7/D7 -> 3.2375335 | P7: =F7/데이터_총괄!I4 -> 1.163561 | Q7: =O7/P7 -> 2.7824354
A8: =데이터_총괄!A5 -> 2025.03 | B8: =데이터_총괄!D5 -> 22 | C8: =데이터_총괄!E5 -> 1236266 | D8: =데이터_총괄!F5 -> 15702060 | E8: =데이터_총괄!G5 -> 58064562 | F8: =데이터_총괄!J5 -> 53341032 | G8: =데이터_총괄!K5 -> 4723530 | H8: =E8/E7-1 -> 0.11038453 | I8: =F8/F7-1 -> 0.10371243 | M8: =E8/B8 -> 2639298.3 | N8: =M8/M7-1 -> 0.11038453 | O8: =E8/D8 -> 3.6978946 | P8: =F8/데이터_총괄!I5 -> 1.2712276 | Q8: =O8/P8 -> 2.9089162
A9: =데이터_총괄!A6 -> 2025.04 | B9: =데이터_총괄!D6 -> 24 | C9: =데이터_총괄!E6 -> 1088160 | D9: =데이터_총괄!F6 -> 17527805 | E9: =데이터_총괄!G6 -> 58035745 | F9: =데이터_총괄!J6 -> 53232716 | G9: =데이터_총괄!K6 -> 4803029 | H9: =E9/E8-1 -> -0.00049629239 | I9: =F9/F8-1 -> -0.0020306319 | M9: =E9/B9 -> 2418156 | N9: =M9/M8-1 -> -0.083788268 | O9: =E9/D9 -> 3.3110675 | P9: =F9/데이터_총괄!I6 -> 1.1762413 | Q9: =O9/P9 -> 2.8149561
A10: =데이터_총괄!A7 -> 2025.05 | B10: =데이터_총괄!D7 -> 21.5 | C10: =데이터_총괄!E7 -> 1034785 | D10: =데이터_총괄!F7 -> 16573463 | E10: =데이터_총괄!G7 -> 57261063 | F10: =데이터_총괄!J7 -> 50345116 | G10: =데이터_총괄!K7 -> 6915946 | H10: =E10/E9-1 -> -0.01334836 | I10: =F10/F9-1 -> -0.054244837 | M10: =E10/B10 -> 2663305.3 | N10: =M10/M9-1 -> 0.10137858 | O10: =E10/D10 -> 3.4549848 | P10: =F10/데이터_총괄!I7 -> 1.1699875 | Q10: =O10/P10 -> 2.9530101
A11: =데이터_총괄!A8 -> 2025.06 | B11: =데이터_총괄!D8 -> 21 | C11: =데이터_총괄!E8 -> 1328545 | D11: =데이터_총괄!F8 -> 16221157 | E11: =데이터_총괄!G8 -> 59833797 | F11: =데이터_총괄!J8 -> 50825746 | G11: =데이터_총괄!K8 -> 9008051 | H11: =E11/E10-1 -> 0.044929903 | I11: =F11/F10-1 -> 0.0095467056 | M11: =E11/B11 -> 2849228.4 | N11: =M11/M10-1 -> 0.069809186 | O11: =E11/D11 -> 3.688627 | P11: =F11/데이터_총괄!I8 -> 1.1894938 | Q11: =O11/P11 -> 3.1010055
A12: =데이터_총괄!A9 -> 2025.07 | B12: =데이터_총괄!D9 -> 25 | C12: =데이터_총괄!E9 -> 1177196 | D12: =데이터_총괄!F9 -> 17580838 | E12: =데이터_총괄!G9 -> 60724322 | F12: =데이터_총괄!J9 -> 54210371 | G12: =데이터_총괄!K9 -> 6513951 | H12: =E12/E11-1 -> 0.014883311 | I12: =F12/F11-1 -> 0.066592726 | M12: =E12/B12 -> 2428972.9 | N12: =M12/M11-1 -> -0.14749802 | O12: =E12/D12 -> 3.4540061 | P12: =F12/데이터_총괄!I9 -> 1.1403055 | Q12: =O12/P12 -> 3.0290181
A13: =데이터_총괄!A10 -> 2025.08 | B13: =데이터_총괄!D10 -> 22.5 | C13: =데이터_총괄!E10 -> 1058881 | D13: =데이터_총괄!F10 -> 17118674 | E13: =데이터_총괄!G10 -> 58259332 | F13: =데이터_총괄!J10 -> 51856624 | G13: =데이터_총괄!K10 -> 6402708 | H13: =E13/E12-1 -> -0.040593125 | I13: =F13/F12-1 -> -0.043418758 | M13: =E13/B13 -> 2589303.6 | N13: =M13/M12-1 -> 0.066007639 | O13: =E13/D13 -> 3.403262 | P13: =F13/데이터_총괄!I10 -> 1.0660892 | Q13: =O13/P13 -> 3.1922865
A14: =데이터_총괄!A11 -> 2025.09 | B14: =데이터_총괄!D11 -> 24 | C14: =데이터_총괄!E11 -> 1451822 | D14: =데이터_총괄!F11 -> 18076703 | E14: =데이터_총괄!G11 -> 65904118 | F14: =데이터_총괄!J11 -> 56419614 | G14: =데이터_총괄!K11 -> 9484504 | H14: =E14/E13-1 -> 0.13121994 | I14: =F14/F13-1 -> 0.087992423 | M14: =E14/B14 -> 2746004.9 | N14: =M14/M13-1 -> 0.060518693 | O14: =E14/D14 -> 3.6458041 | P14: =F14/데이터_총괄!I11 -> 1.1933502 | Q14: =O14/P14 -> 3.0550999
A15: =데이터_총괄!A12 -> 2025.10 | B15: =데이터_총괄!D12 -> 20 | C15: =데이터_총괄!E12 -> 1040165 | D15: =데이터_총괄!F12 -> 16017318 | E15: =데이터_총괄!G12 -> 59511578 | F15: =데이터_총괄!J12 -> 53510827 | G15: =데이터_총괄!K12 -> 6000751 | H15: =E15/E14-1 -> -0.096997581 | I15: =F15/F14-1 -> -0.051556308 | M15: =E15/B15 -> 2975578.9 | N15: =M15/M14-1 -> 0.083602903 | O15: =E15/D15 -> 3.7154521 | P15: =F15/데이터_총괄!I12 -> 1.1247467 | Q15: =O15/P15 -> 3.303368
A16: =데이터_총괄!A13 -> 2025.11 | B16: =데이터_총괄!D13 -> 22.5 | C16: =데이터_총괄!E13 -> 1152460 | D16: =데이터_총괄!F13 -> 14605096 | E16: =데이터_총괄!G13 -> 60752618 | F16: =데이터_총괄!J13 -> 51284605 | G16: =데이터_총괄!K13 -> 9468013 | H16: =E16/E15-1 -> 0.020853757 | I16: =F16/F15-1 -> -0.041603207 | M16: =E16/B16 -> 2700116.4 | N16: =M16/M15-1 -> -0.092574438 | O16: =E16/D16 -> 4.1596862 | P16: =F16/데이터_총괄!I13 -> 1.1775207 | Q16: =O16/P16 -> 3.5325801
A17: =데이터_총괄!A14 -> 2025.12 | B17: =데이터_총괄!D14 -> 24 | C17: =데이터_총괄!E14 -> 1275309 | D17: =데이터_총괄!F14 -> 17977896 | E17: =데이터_총괄!G14 -> 69513624 | F17: =데이터_총괄!J14 -> 57367684 | G17: =데이터_총괄!K14 -> 12145941 | H17: =E17/E16-1 -> 0.14420788 | I17: =F17/F16-1 -> 0.11861413 | M17: =E17/B17 -> 2896401 | N17: =M17/M16-1 -> 0.072694884 | O17: =E17/D17 -> 3.8666162 | P17: =F17/데이터_총괄!I14 -> 1.2074762 | Q17: =O17/P17 -> 3.2022298 | R17: =SUM(E6:E17) -> 709330044 | S17: =SUM(G6:G17) -> 77434676
A18: =데이터_총괄!A15 -> 2026.01 | B18: =데이터_총괄!D15 -> 23.5 | C18: =데이터_총괄!E15 -> 1027989 | D18: =데이터_총괄!F15 -> 16739948 | E18: =데이터_총괄!G15 -> 65843937 | F18: =데이터_총괄!J15 -> 57143469 | G18: =데이터_총괄!K15 -> 8700468 | H18: =E18/E17-1 -> -0.052790903 | I18: =F18/F17-1 -> -0.0039083851 | J18: =E18/E6-1 -> 0.33891775 | K18: =F18/F6-1 -> 0.1166877 | L18: =G18-G6 -> 10695776 | M18: =E18/B18 -> 2801869.7 | N18: =M18/M17-1 -> -0.032637518 | O18: =E18/D18 -> 3.9333418 | P18: =F18/데이터_총괄!I15 -> 1.142524 | Q18: =O18/P18 -> 3.4426778 | R18: =SUM(E7:E18) -> 725996997 | S18: =SUM(G7:G18) -> 88130452
A19: =데이터_총괄!A16 -> 2026.02 | B19: =데이터_총괄!D16 -> 19 | C19: =데이터_총괄!E16 -> 970132 | D19: =데이터_총괄!F16 -> 15601518 | E19: =데이터_총괄!G16 -> 67642547 | F19: =데이터_총괄!J16 -> 51933913 | G19: =데이터_총괄!K16 -> 15708634 | H19: =E19/E18-1 -> 0.027316258 | I19: =F19/F18-1 -> -0.091166254 | J19: =E19/E7-1 -> 0.29354696 | K19: =F19/F7-1 -> 0.074596853 | L19: =G19-G7 -> 11745074 | M19: =E19/B19 -> 3560134.1 | N19: =M19/M18-1 -> 0.270628 | O19: =E19/D19 -> 4.3356389 | P19: =F19/데이터_총괄!I16 -> 1.1993065 | Q19: =O19/P19 -> 3.6151217 | R19: =SUM(E8:E19) -> 741347243 | S19: =SUM(G8:G19) -> 99875526
A20: =데이터_총괄!A17 -> 2026.03 | B20: =데이터_총괄!D17 -> 23 | C20: =데이터_총괄!E17 -> 1439801 | D20: =데이터_총괄!F17 -> 16180252 | E20: =데이터_총괄!G17 -> 87333128 | F20: =데이터_총괄!J17 -> 60753446 | G20: =데이터_총괄!K17 -> 26579682 | H20: =E20/E19-1 -> 0.29109757 | I20: =F20/F19-1 -> 0.16982223 | J20: =E20/E8-1 -> 0.50406935 | K20: =F20/F8-1 -> 0.1389627 | L20: =G20-G8 -> 21856152 | M20: =E20/B20 -> 3797092.5 | N20: =M20/M19-1 -> 0.066558861 | O20: =E20/D20 -> 5.3975135 | P20: =F20/데이터_총괄!I17 -> 1.3818464 | Q20: =O20/P20 -> 3.9060156 | R20: =SUM(E9:E20) -> 770615809 | S20: =SUM(G9:G20) -> 121731678
A21: =데이터_총괄!A18 -> 2026.04 | B21: =데이터_총괄!D18 -> 24 | C21: =데이터_총괄!E18 -> 1130727 | D21: =데이터_총괄!F18 -> 14413704 | E21: =데이터_총괄!G18 -> 85751883 | F21: =데이터_총괄!J18 -> 62104908 | G21: =데이터_총괄!K18 -> 23646975 | H21: =E21/E20-1 -> -0.018105901 | I21: =F21/F20-1 -> 0.022245026 | J21: =E21/E9-1 -> 0.47757013 | K21: =F21/F9-1 -> 0.16666803 | L21: =G21-G9 -> 18843946 | M21: =E21/B21 -> 3572995.1 | N21: =M21/M20-1 -> -0.059018155 | O21: =E21/D21 -> 5.94933 | P21: =F21/데이터_총괄!I18 -> 1.4787418 | Q21: =O21/P21 -> 4.0232379 | R21: =SUM(E10:E21) -> 798331947 | S21: =SUM(G10:G21) -> 140575624
A22: =데이터_총괄!A19 -> 2026.05 | B22: =데이터_총괄!D19 -> 20.5 | C22: =데이터_총괄!E19 -> 993936 | D22: =데이터_총괄!F19 -> 13589511 | E22: =데이터_총괄!G19 -> 87576083 | F22: =데이터_총괄!J19 -> 60748350 | G22: =데이터_총괄!K19 -> 26827733 | H22: =E22/E21-1 -> 0.021273002 | I22: =F22/F21-1 -> -0.021843008 | J22: =E22/E10-1 -> 0.5294177 | K22: =F22/F10-1 -> 0.2066384 | L22: =G22-G10 -> 19911787 | M22: =E22/B22 -> 4272004 | N22: =M22/M21-1 -> 0.19563669 | O22: =E22/D22 -> 6.444388 | P22: =F22/데이터_총괄!I19 -> 1.5291253 | Q22: =O22/P22 -> 4.2144276 | R22: =SUM(E11:E22) -> 828646967 | S22: =SUM(G11:G22) -> 160487411
A23: =데이터_총괄!A20 -> 2026.06 | B23: =데이터_총괄!D20 -> 22.5 | C23: =데이터_총괄!E20 -> 1245865 | D23: =데이터_총괄!F20 -> 15687926 | E23: =데이터_총괄!G20 -> 101956159 | F23: =데이터_총괄!J20 -> 66051586 | G23: =데이터_총괄!K20 -> 35904573 | H23: =E23/E22-1 -> 0.16420095 | I23: =F23/F22-1 -> 0.087298437 | J23: =E23/E11-1 -> 0.70398945 | K23: =F23/F11-1 -> 0.29956943 | L23: =G23-G11 -> 26896522 | M23: =E23/B23 -> 4531384.8 | N23: =M23/M22-1 -> 0.060716421 | O23: =E23/D23 -> 6.4990209 | P23: =F23/데이터_총괄!I20 -> 1.5118563 | Q23: =O23/P23 -> 4.2987027 | R23: =SUM(E12:E23) -> 870769329 | S23: =SUM(G12:G23) -> 187383933
