Workbook

Sheet 수출입 총괄
A1: 수출입 총괄
A3: 검색조건 조회기간: 202601 ~ 202607 , 통계기준: 수리일, 중량단위: 톤
I4: 단위:건, 톤(TON), 천 달러
A5: 기간 | B5: 조업일수 | C5: 수출 건수 | D5: 수출 중량 | E5: 수출 금액 | F5: 수입 건수 | G5: 수입중량 | H5: 수입금액 | I5: 무역수지
A6: 총계 | B6: 156.5 | C6: 7920384 | D6: 1.0987354e+08 | E6: 595062835 | F6: 34460197 | G6: 3.1384305e+08 | H6: 427303144 | I6: 167759691
A7: 2026.01 | B7: 23.5 | C7: 1027989 | D7: 16739948 | E7: 65843937 | F7: 4936713 | G7: 50015116 | H7: 57143469 | I7: 8700468
A8: 2026.02 | B8: 19 | C8: 970132 | D8: 15601518 | E8: 67642547 | F8: 4102805 | G8: 43303287 | H8: 51933913 | I8: 15708634
A9: 2026.03 | B9: 23 | C9: 1439801 | D9: 16180252 | E9: 87333128 | F9: 5237532 | G9: 43965413 | H9: 60753446 | I9: 26579682
A10: 2026.04 | B10: 24 | C10: 1130727 | D10: 14413704 | E10: 85751883 | F10: 5105811 | G10: 41998481 | H10: 62104908 | I10: 23646975
A11: 2026.05 | B11: 20.5 | C11: 993936 | D11: 13589511 | E11: 87576083 | F11: 4874306 | G11: 39727515 | H11: 60748350 | I11: 26827733
A12: 2026.06 | B12: 22.5 | C12: 1245865 | D12: 15687926 | E12: 101956159 | F12: 5044182 | G12: 43689062 | H12: 66051586 | I12: 35904573
A13: 2026.07 | B13: 24 | C13: 1111934 | D13: 17660681 | E13: 98959099 | F13: 5158848 | G13: 51144176 | H13: 68567473 | I13: 30391625

Sheet 수출입 실적(성질별)
A1: 수출입실적(성질별)
A3: 검색조건통계항목:성질별,성질명:수출,전체,세부성질유무:무,조회기간:202601~202607,통계기준:수리일,중량단위:톤
D4: 단위:톤(TON),천달러
A5: 기간 | B5: 성질명 | C5: 중량 | D5: 금액
A6: 총계 | C6: 1.0987354e+08 | D6: 595062835
A7: 2026.01 | B7: 1.식료및직접소비재 | C7: 305634.2 | D7: 1018552
A8: 2026.01 | B8: 2.원료및연료 | C8: 6781530.7 | D8: 4654223
A9: 2026.01 | B9: 3.경공업품 | C9: 818424.6 | D9: 3082056
A10: 2026.01 | B10: 가.섬유원료 | C10: 52997.6 | D10: 81834
A11: 2026.01 | B11: 나.섬유사 | C11: 15913.6 | D11: 59575
A12: 2026.01 | B12: 다.직물 | C12: 28445.2 | D12: 275298
A13: 2026.01 | B13: 라.기타섬유제품 | C13: 20395.8 | D13: 159996
A14: 2026.01 | B14: 마.의류 | C14: 5256 | D14: 145729
A15: 2026.01 | B15: 바.목제품 | C15: 16632.3 | D15: 94526
A16: 2026.01 | B16: 사.가죽,고무및신발류 | C16: 71925.9 | D16: 401578
A17: 2026.01 | B17: 아.귀금속및보석류 | C17: 289.6 | D17: 701882
A18: 2026.01 | B18: 자.기타비금속광물제품 | C18: 247902 | D18: 181453
... A153: 2026.07 | B153: 바.기타 | C153: 89360.5 | D153: 2725433

Sheet 수출입 실적(신성질별)
A1: 수출입 실적(신성질별)
A3: 검색조건통계항목 : 신성질별, 신성질명 : 전체, 세부성질 유무 : 무, 조회기간 : 202601 ~ 202607 , 통계기준 : 수리일, 중량단위 : 톤
A5: 기간 | B5: 신성질명 | C5: 수출 중량 | D5: 수출 금액
A6: 총계 | C6: 1.0987354e+08 | D6: 595062835
A7: 2026.01 | B7: 1.소비재 | C7: 853755.8 | D7: 7671931
A8: 2026.01 | B8: 가.직접소비재 | C8: 266496 | D8: 974471
A9: 2026.01 | B9: 나.내구소비재 | C9: 433897.1 | D9: 5005260
A10: 2026.01 | B10: 다.비내구소비재 | C10: 150326.8 | D10: 1688959
A11: 2026.01 | B11: 라.간이세율적용분 | C11: 3036 | D11: 3241
A12: 2026.01 | B12: 2.원자재 | C12: 14117543 | D12: 16383039
A13: 2026.01 | B13: 가.동식물성 연·원료 | C13: 328095 | D13: 417054
A14: 2026.01 | B14: 나.섬유류 | C14: 113458.2 | D14: 546437
A15: 2026.01 | B15: 다.광산물 | C15: 6633846.6 | D15: 4965073
A16: 2026.01 | B16: 라.철강 및 금속제품 | C16: 2721273.1 | D16: 3502462
A17: 2026.01 | B17: 마.화학공업제품 | C17: 4318942.3 | D17: 6944019
A18: 2026.01 | B18: 바.기타 원자재 | C18: 1927.9 | D18: 7994
... A125: 2026.07 | B125: 라.IT부품 | C125: 33481.3 | D125: 42761535

Sheet 분석1_정합성검증
A1: ① 합계 정합성 검증 — 개별항목의 합 vs 총합
A2: 원본 3개 시트(수출입 총괄 / 성질별 / 신성질별)의 모든 값을 수식으로 직접 참조하여 검증합니다. 원본 시트는 수정하지 않았습니다.
A3: 허용오차: 원본이 소수 첫째자리(중량)·정수(금액)로 반올림되어 제공되므로, 아래 허용오차 이내의 차이는 반올림 오차로 판정합니다. (노란색 셀 = 사용자 입력값)
A4: 허용오차(중량, 톤) | B4: 1 | C4: 허용오차(금액, 천달러) | D4: 5
A6: [검증 1] 「수출입 총괄」 총계행 vs 2026.01~07 월별 합계
A7: 항목 | B7: 총계행(원본) | C7: 월별 합계 | D7: 차이 | E7: 판정
A8: 조업일수 | B8: ='수출입 총괄'!B6 -> 156.5 | C8: =SUM('수출입 총괄'!B7:B13) -> 156.5 | D8: =B8-C8 -> 0 | E8: =IF(ABS(D8)<=$B$4,"일치(반올림오차 이내)","불일치") -> 일치(반올림오차 이내)
A9: 수출 건수 | B9: ='수출입 총괄'!C6 -> 7920384 | C9: =SUM('수출입 총괄'!C7:C13) -> 7920384 | D9: =B9-C9 -> 0 | E9: =IF(ABS(D9)<=$D$4,"일치(반올림오차 이내)","불일치") -> 일치(반올림오차 이내)
A10: 수출 중량(톤) | B10: ='수출입 총괄'!D6 -> 1.0987354e+08 | C10: =SUM('수출입 총괄'!D7:D13) -> 1.0987354e+08 | D10: =B10-C10 -> -0.10000001 | E10: =IF(ABS(D10)<=$B$4,"일치(반올림오차 이내)","불일치") -> 일치(반올림오차 이내)
A11: 수출 금액(천$) | B11: ='수출입 총괄'!E6 -> 595062835 | C11: =SUM('수출입 총괄'!E7:E13) -> 595062836 | D11: =B11-C11 -> -1 | E11: =IF(ABS(D11)<=$D$4,"일치(반올림오차 이내)","불일치") -> 일치(반올림오차 이내)
A12: 수입 건수 | B12: ='수출입 총괄'!F6 -> 34460197 | C12: =SUM('수출입 총괄'!F7:F13) -> 34460197 | D12: =B12-C12 -> 0 | E12: =IF(ABS(D12)<=$D$4,"일치(반올림오차 이내)","불일치") -> 일치(반올림오차 이내)
A13: 수입 중량(톤) | B13: ='수출입 총괄'!G6 -> 3.1384305e+08 | C13: =SUM('수출입 총괄'!G7:G13) -> 3.1384305e+08 | D13: =B13-C13 -> 0 | E13: =IF(ABS(D13)<=$B$4,"일치(반올림오차 이내)","불일치") -> 일치(반올림오차 이내)
A14: 수입 금액(천$) | B14: ='수출입 총괄'!H6 -> 427303144 | C14: =SUM('수출입 총괄'!H7:H13) -> 427303145 | D14: =B14-C14 -> -1 | E14: =IF(ABS(D14)<=$D$4,"일치(반올림오차 이내)","불일치") -> 일치(반올림오차 이내)
A15: 무역수지(천$) | B15: ='수출입 총괄'!I6 -> 167759691 | C15: =SUM('수출입 총괄'!I7:I13) -> 167759690 | D15: =B15-C15 -> 1 | E15: =IF(ABS(D15)<=$D$4,"일치(반올림오차 이내)","불일치") -> 일치(반올림오차 이내)
A17: [검증 2] 무역수지 항등식 : 수출금액 − 수입금액 = 무역수지
A18: 기간 | B18: 수출금액 | C18: 수입금액 | D18: 계산값(수출−수입) | E18: 원본 무역수지 | F18: 차이 | G18: 판정
A19: 총계 | B19: ='수출입 총괄'!E6 -> 595062835 | C19: ='수출입 총괄'!H6 -> 427303144 | D19: =B19-C19 -> 167759691 | E19: ='수출입 총괄'!I6 -> 167759691 | F19: =D19-E19 -> 0 | G19: =IF(ABS(F19)<=$D$4,"일치(반올림오차 이내)","불일치") -> 일치(반올림오차 이내)
A20: 2026.01 | B20: ='수출입 총괄'!E7 -> 65843937 | C20: ='수출입 총괄'!H7 -> 57143469 | D20: =B20-C20 -> 8700468 | E20: ='수출입 총괄'!I7 -> 8700468 | F20: =D20-E20 -> 0 | G20: =IF(ABS(F20)<=$D$4,"일치(반올림오차 이내)","불일치") -> 일치(반올림오차 이내)
A21: 2026.02 | B21: ='수출입 총괄'!E8 -> 67642547 | C21: ='수출입 총괄'!H8 -> 51933913 | D21: =B21-C21 -> 15708634 | E21: ='수출입 총괄'!I8 -> 15708634 | F21: =D21-E21 -> 0 | G21: =IF(ABS(F21)<=$D$4,"일치(반올림오차 이내)","불일치") -> 일치(반올림오차 이내)
A22: 2026.03 | B22: ='수출입 총괄'!E9 -> 87333128 | C22: ='수출입 총괄'!H9 -> 60753446 | D22: =B22-C22 -> 26579682 | E22: ='수출입 총괄'!I9 -> 26579682 | F22: =D22-E22 -> 0 | G22: =IF(ABS(F22)<=$D$4,"일치(반올림오차 이내)","불일치") -> 일치(반올림오차 이내)
A23: 2026.04 | B23: ='수출입 총괄'!E10 -> 85751883 | C23: ='수출입 총괄'!H10 -> 62104908 | D23: =B23-C23 -> 23646975 | E23: ='수출입 총괄'!I10 -> 23646975 | F23: =D23-E23 -> 0 | G23: =IF(ABS(F23)<=$D$4,"일치(반올림오차 이내)","불일치") -> 일치(반올림오차 이내)
A24: 2026.05 | B24: ='수출입 총괄'!E11 -> 87576083 | C24: ='수출입 총괄'!H11 -> 60748350 | D24: =B24-C24 -> 26827733 | E24: ='수출입 총괄'!I11 -> 26827733 | F24: =D24-E24 -> 0 | G24: =IF(ABS(F24)<=$D$4,"일치(반올림오차 이내)","불일치") -> 일치(반올림오차 이내)
A25: 2026.06 | B25: ='수출입 총괄'!E12 -> 101956159 | C25: ='수출입 총괄'!H12 -> 66051586 | D25: =B25-C25 -> 35904573 | E25: ='수출입 총괄'!I12 -> 35904573 | F25: =D25-E25 -> 0 | G25: =IF(ABS(F25)<=$D$4,"일치(반올림오차 이내)","불일치") -> 일치(반올림오차 이내)
A26: 2026.07 | B26: ='수출입 총괄'!E13 -> 98959099 | C26: ='수출입 총괄'!H13 -> 68567473 | D26: =B26-C26 -> 30391626 | E26: ='수출입 총괄'!I13 -> 30391625 | F26: =D26-E26 -> 1 | G26: =IF(ABS(F26)<=$D$4,"일치(반올림오차 이내)","불일치") -> 일치(반올림오차 이내)
A28: [검증 3] 「성질별」 대분류 4개 합 vs 「총괄」 수출 실적
A29: 기간 | B29: 성질별 금액 합 | C29: 총괄 수출금액 | D29: 차이 | E29: 판정 | F29: 성질별 중량 합 | G29: 총괄 수출중량 | H29: 차이 | I29: 판정
A30: 2026.01 | B30: ='수출입 실적(성질별)'!D7+'수출입 실적(성질별)'!D8+'수출입 실적(성질별)'!D9+'수출입 실적(성질별)'!D21 -> 65843937 | C30: ='수출입 총괄'!E7 -> 65843937 | D30: =B30-C30 -> 0 | E30: =IF(ABS(D30)<=$D$4,"일치","불일치") -> 일치 | F30: ='수출입 실적(성질별)'!C7+'수출입 실적(성질별)'!C8+'수출입 실적(성질별)'!C9+'수출입 실적(성질별)'!C21 -> 16739948 | G30: ='수출입 총괄'!D7 -> 16739948 | H30: =F30-G30 -> 0 | I30: =IF(ABS(H30)<=$B$4,"일치","불일치") -> 일치
A31: 2026.02 | B31: ='수출입 실적(성질별)'!D28+'수출입 실적(성질별)'!D29+'수출입 실적(성질별)'!D30+'수출입 실적(성질별)'!D42 -> 67642547 | C31: ='수출입 총괄'!E8 -> 67642547 | D31: =B31-C31 -> 0 | E31: =IF(ABS(D31)<=$D$4,"일치","불일치") -> 일치 | F31: ='수출입 실적(성질별)'!C28+'수출입 실적(성질별)'!C29+'수출입 실적(성질별)'!C30+'수출입 실적(성질별)'!C42 -> 15601518 | G31: ='수출입 총괄'!D8 -> 15601518 | H31: =F31-G31 -> 0.1 | I31: =IF(ABS(H31)<=$B$4,"일치","불일치") -> 일치
A32: 2026.03 | B32: ='수출입 실적(성질별)'!D49+'수출입 실적(성질별)'!D50+'수출입 실적(성질별)'!D51+'수출입 실적(성질별)'!D63 -> 87333128 | C32: ='수출입 총괄'!E9 -> 87333128 | D32: =B32-C32 -> 0 | E32: =IF(ABS(D32)<=$D$4,"일치","불일치") -> 일치 | F32: ='수출입 실적(성질별)'!C49+'수출입 실적(성질별)'!C50+'수출입 실적(성질별)'!C51+'수출입 실적(성질별)'!C63 -> 16180252 | G32: ='수출입 총괄'!D9 -> 16180252 | H32: =F32-G32 -> 0 | I32: =IF(ABS(H32)<=$B$4,"일치","불일치") -> 일치
A33: 2026.04 | B33: ='수출입 실적(성질별)'!D70+'수출입 실적(성질별)'!D71+'수출입 실적(성질별)'!D72+'수출입 실적(성질별)'!D84 -> 85751883 | C33: ='수출입 총괄'!E10 -> 85751883 | D33: =B33-C33 -> 0 | E33: =IF(ABS(D33)<=$D$4,"일치","불일치") -> 일치 | F33: ='수출입 실적(성질별)'!C70+'수출입 실적(성질별)'!C71+'수출입 실적(성질별)'!C72+'수출입 실적(성질별)'!C84 -> 14413704 | G33: ='수출입 총괄'!D10 -> 14413704 | H33: =F33-G33 -> 0 | I33: =IF(ABS(H33)<=$B$4,"일치","불일치") -> 일치
A34: 2026.05 | B34: ='수출입 실적(성질별)'!D91+'수출입 실적(성질별)'!D92+'수출입 실적(성질별)'!D93+'수출입 실적(성질별)'!D105 -> 87576084 | C34: ='수출입 총괄'!E11 -> 87576083 | D34: =B34-C34 -> 1 | E34: =IF(ABS(D34)<=$D$4,"일치","불일치") -> 일치 | F34: ='수출입 실적(성질별)'!C91+'수출입 실적(성질별)'!C92+'수출입 실적(성질별)'!C93+'수출입 실적(성질별)'!C105 -> 13589511 | G34: ='수출입 총괄'!D11 -> 13589511 | H34: =F34-G34 -> 0.1 | I34: =IF(ABS(H34)<=$B$4,"일치","불일치") -> 일치
A35: 2026.06 | B35: ='수출입 실적(성질별)'!D112+'수출입 실적(성질별)'!D113+'수출입 실적(성질별)'!D114+'수출입 실적(성질별)'!D126 -> 101956158 | C35: ='수출입 총괄'!E12 -> 101956159 | D35: =B35-C35 -> -1 | E35: =IF(ABS(D35)<=$D$4,"일치","불일치") -> 일치 | F35: ='수출입 실적(성질별)'!C112+'수출입 실적(성질별)'!C113+'수출입 실적(성질별)'!C114+'수출입 실적(성질별)'!C126 -> 15687926 | G35: ='수출입 총괄'!D12 -> 15687926 | H35: =F35-G35 -> -0.1 | I35: =IF(ABS(H35)<=$B$4,"일치","불일치") -> 일치
A36: 2026.07 | B36: ='수출입 실적(성질별)'!D133+'수출입 실적(성질별)'!D134+'수출입 실적(성질별)'!D135+'수출입 실적(성질별)'!D147 -> 98959100 | C36: ='수출입 총괄'!E13 -> 98959099 | D36: =B36-C36 -> 1 | E36: =IF(ABS(D36)<=$D$4,"일치","불일치") -> 일치 | F36: ='수출입 실적(성질별)'!C133+'수출입 실적(성질별)'!C134+'수출입 실적(성질별)'!C135+'수출입 실적(성질별)'!C147 -> 17660681 | G36: ='수출입 총괄'!D13 -> 17660681 | H36: =F36-G36 -> 0 | I36: =IF(ABS(H36)<=$B$4,"일치","불일치") -> 일치
A37: 7개월 누계 | B37: =SUM(B30:B36) -> 595062837 | C37: ='수출입 실적(성질별)'!D6 -> 595062835 | D37: =B37-C37 -> 2 | E37: =IF(ABS(D37)<=$D$4*7,"일치(누계 반올림오차)","불일치") -> 일치(누계 반올림오차) | F37: =SUM(F30:F36) -> 1.0987354e+08 | G37: ='수출입 실적(성질별)'!C6 -> 1.0987354e+08 | H37: =F37-G37 -> 0.2 | I37: =IF(ABS(H37)<=$B$4*7,"일치(누계 반올림오차)","불일치") -> 일치(누계 반올림오차)
A38: C열·G열의 총계 비교값은 「성질별」 시트 6행(총계행)입니다. 즉 대분류 4개 × 7개월의 합이 시트 자체 총계와 일치하는지를 봅니다.
A40: [검증 4] 「성질별」 중분류 합 vs 대분류 (경공업품 / 중화학공업품)
A41: 기간 | B41: 3.경공업품(대) | C41: 중분류 가~카 합 | D41: 차이 | E41: 판정 | F41: 4.중화학공업품(대) | G41: 중분류 가~바 합 | H41: 차이 | I41: 판정
A42: 2026.01 | B42: ='수출입 실적(성질별)'!D9 -> 3082056 | C42: =SUM('수출입 실적(성질별)'!D10:D20) -> 3082056 | D42: =B42-C42 -> 0 | E42: =IF(ABS(D42)<=$D$4,"일치","불일치") -> 일치 | F42: ='수출입 실적(성질별)'!D21 -> 57089106 | G42: =SUM('수출입 실적(성질별)'!D22:D27) -> 57089105 | H42: =F42-G42 -> 1 | I42: =IF(ABS(H42)<=$D$4,"일치","불일치") -> 일치
A43: 2026.02 | B43: ='수출입 실적(성질별)'!D30 -> 3096567 | C43: =SUM('수출입 실적(성질별)'!D31:D41) -> 3096566 | D43: =B43-C43 -> 1 | E43: =IF(ABS(D43)<=$D$4,"일치","불일치") -> 일치 | F43: ='수출입 실적(성질별)'!D42 -> 58704727 | G43: =SUM('수출입 실적(성질별)'!D43:D48) -> 58704727 | H43: =F43-G43 -> 0 | I43: =IF(ABS(H43)<=$D$4,"일치","불일치") -> 일치
A44: 2026.03 | B44: ='수출입 실적(성질별)'!D51 -> 4111292 | C44: =SUM('수출입 실적(성질별)'!D52:D62) -> 4111293 | D44: =B44-C44 -> -1 | E44: =IF(ABS(D44)<=$D$4,"일치","불일치") -> 일치 | F44: ='수출입 실적(성질별)'!D63 -> 74771554 | G44: =SUM('수출입 실적(성질별)'!D64:D69) -> 74771555 | H44: =F44-G44 -> -1 | I44: =IF(ABS(H44)<=$D$4,"일치","불일치") -> 일치
...

Sheet 분석2_월별추이
A1: ② 월별 추이 — 총괄 지표 · 조업일수 보정 · 단가
A2: 「수출입 총괄」 시트를 수식으로 참조합니다. 단가 = 금액(천달러) ÷ 중량(톤), 일평균 = 금액 ÷ 조업일수(월별 영업일 차이 보정).
A3: 순상품교역조건 = 수출단가 ÷ 수입단가. 값이 높을수록 같은 물량을 팔아 더 많은 수입 물량을 살 수 있음을 뜻합니다.
A5: 기간 | B5: 조업일수 | C5: 수출 건수 | D5: 수출 중량(톤) | E5: 수출 금액(천$) | F5: 수입 금액(천$) | G5: 무역수지(천$) | H5: 수출 전월비 | I5: 수입 전월비 | J5: 수지 전월증감(천$) | K5: 일평균 수출(천$) | L5: 일평균 수출 전월비 | M5: 수출단가(천$/톤) | N5: 수입단가(천$/톤) | O5: 순상품교역조건 | P5: 누적 수출(천$) | Q5: 누적 수지(천$)
A6: 2026.01 | B6: ='수출입 총괄'!B7 -> 23.5 | C6: ='수출입 총괄'!C7 -> 1027989 | D6: ='수출입 총괄'!D7 -> 16739948 | E6: ='수출입 총괄'!E7 -> 65843937 | F6: ='수출입 총괄'!H7 -> 57143469 | G6: ='수출입 총괄'!I7 -> 8700468 | K6: =E6/B6 -> 2801869.7 | M6: =E6/D6 -> 3.9333418 | N6: =F6/'수출입 총괄'!G7 -> 1.142524 | O6: =M6/N6 -> 3.4426778 | P6: =SUM($E$6:E6) -> 65843937 | Q6: =SUM($G$6:G6) -> 8700468
A7: 2026.02 | B7: ='수출입 총괄'!B8 -> 19 | C7: ='수출입 총괄'!C8 -> 970132 | D7: ='수출입 총괄'!D8 -> 15601518 | E7: ='수출입 총괄'!E8 -> 67642547 | F7: ='수출입 총괄'!H8 -> 51933913 | G7: ='수출입 총괄'!I8 -> 15708634 | H7: =E7/E6-1 -> 0.027316258 | I7: =F7/F6-1 -> -0.091166254 | J7: =G7-G6 -> 7008166 | K7: =E7/B7 -> 3560134.1 | L7: =K7/K6-1 -> 0.270628 | M7: =E7/D7 -> 4.3356389 | N7: =F7/'수출입 총괄'!G8 -> 1.1993065 | O7: =M7/N7 -> 3.6151217 | P7: =SUM($E$6:E7) -> 133486484 | Q7: =SUM($G$6:G7) -> 24409102
A8: 2026.03 | B8: ='수출입 총괄'!B9 -> 23 | C8: ='수출입 총괄'!C9 -> 1439801 | D8: ='수출입 총괄'!D9 -> 16180252 | E8: ='수출입 총괄'!E9 -> 87333128 | F8: ='수출입 총괄'!H9 -> 60753446 | G8: ='수출입 총괄'!I9 -> 26579682 | H8: =E8/E7-1 -> 0.29109757 | I8: =F8/F7-1 -> 0.16982223 | J8: =G8-G7 -> 10871048 | K8: =E8/B8 -> 3797092.5 | L8: =K8/K7-1 -> 0.066558861 | M8: =E8/D8 -> 5.3975135 | N8: =F8/'수출입 총괄'!G9 -> 1.3818464 | O8: =M8/N8 -> 3.9060156 | P8: =SUM($E$6:E8) -> 220819612 | Q8: =SUM($G$6:G8) -> 50988784
A9: 2026.04 | B9: ='수출입 총괄'!B10 -> 24 | C9: ='수출입 총괄'!C10 -> 1130727 | D9: ='수출입 총괄'!D10 -> 14413704 | E9: ='수출입 총괄'!E10 -> 85751883 | F9: ='수출입 총괄'!H10 -> 62104908 | G9: ='수출입 총괄'!I10 -> 23646975 | H9: =E9/E8-1 -> -0.018105901 | I9: =F9/F8-1 -> 0.022245026 | J9: =G9-G8 -> -2932707 | K9: =E9/B9 -> 3572995.1 | L9: =K9/K8-1 -> -0.059018155 | M9: =E9/D9 -> 5.94933 | N9: =F9/'수출입 총괄'!G10 -> 1.4787418 | O9: =M9/N9 -> 4.0232379 | P9: =SUM($E$6:E9) -> 306571495 | Q9: =SUM($G$6:G9) -> 74635759
A10: 2026.05 | B10: ='수출입 총괄'!B11 -> 20.5 | C10: ='수출입 총괄'!C11 -> 993936 | D10: ='수출입 총괄'!D11 -> 13589511 | E10: ='수출입 총괄'!E11 -> 87576083 | F10: ='수출입 총괄'!H11 -> 60748350 | G10: ='수출입 총괄'!I11 -> 26827733 | H10: =E10/E9-1 -> 0.021273002 | I10: =F10/F9-1 -> -0.021843008 | J10: =G10-G9 -> 3180758 | K10: =E10/B10 -> 4272004 | L10: =K10/K9-1 -> 0.19563669 | M10: =E10/D10 -> 6.444388 | N10: =F10/'수출입 총괄'!G11 -> 1.5291253 | O10: =M10/N10 -> 4.2144276 | P10: =SUM($E$6:E10) -> 394147578 | Q10: =SUM($G$6:G10) -> 101463492
A11: 2026.06 | B11: ='수출입 총괄'!B12 -> 22.5 | C11: ='수출입 총괄'!C12 -> 1245865 | D11: ='수출입 총괄'!D12 -> 15687926 | E11: ='수출입 총괄'!E12 -> 101956159 | F11: ='수출입 총괄'!H12 -> 66051586 | G11: ='수출입 총괄'!I12 -> 35904573 | H11: =E11/E10-1 -> 0.16420095 | I11: =F11/F10-1 -> 0.087298437 | J11: =G11-G10 -> 9076840 | K11: =E11/B11 -> 4531384.8 | L11: =K11/K10-1 -> 0.060716421 | M11: =E11/D11 -> 6.4990209 | N11: =F11/'수출입 총괄'!G12 -> 1.5118563 | O11: =M11/N11 -> 4.2987027 | P11: =SUM($E$6:E11) -> 496103737 | Q11: =SUM($G$6:G11) -> 137368065
A12: 2026.07 | B12: ='수출입 총괄'!B13 -> 24 | C12: ='수출입 총괄'!C13 -> 1111934 | D12: ='수출입 총괄'!D13 -> 17660681 | E12: ='수출입 총괄'!E13 -> 98959099 | F12: ='수출입 총괄'!H13 -> 68567473 | G12: ='수출입 총괄'!I13 -> 30391625 | H12: =E12/E11-1 -> -0.029395576 | I12: =F12/F11-1 -> 0.038089729 | J12: =G12-G11 -> -5512948 | K12: =E12/B12 -> 4123295.8 | L12: =K12/K11-1 -> -0.090058352 | M12: =E12/D12 -> 5.603357 | N12: =F12/'수출입 총괄'!G13 -> 1.3406702 | O12: =M12/N12 -> 4.1795193 | P12: =SUM($E$6:E12) -> 595062836 | Q12: =SUM($G$6:G12) -> 167759690
A13: 7개월 누계/평균 | B13: =SUM(B6:B12) -> 156.5 | C13: =SUM(C6:C12) -> 7920384 | D13: =SUM(D6:D12) -> 1.0987354e+08 | E13: =SUM(E6:E12) -> 595062836 | F13: =SUM(F6:F12) -> 427303145 | G13: =SUM(G6:G12) -> 167759690 | H13: =E12/E6-1 -> 0.50293411 | I13: =F12/F6-1 -> 0.19991793 | J13: =G12-G6 -> 21691157 | K13: =E13/B13 -> 3802318.4 | L13: =K12/K6-1 -> 0.47162298 | M13: =E13/D13 -> 5.4158885 | N13: =F13/SUM('수출입 총괄'!G7:G13) -> 1.3615186 | O13: =M13/N13 -> 3.9778293 | P13: =E13 -> 595062836 | Q13: =G13 -> 167759690
A14: 누계/평균 행의 전월비(H·I·L열)는 1월 대비 7월 증감률(=기간 전체 변화)입니다.

Sheet 분석3_품목별증감
A1: ③ 품목별 증감 분석 — 전월비 · 기간내 증감 · 기여도
A2: 모든 수치는 수출 금액(천달러) 기준이며 원본 시트를 수식으로 참조합니다. 기여도 = 해당 품목의 1월→7월 증감액 ÷ 전체 수출의 1월→7월 증감액.
A3: "최대/최소 월증감률"은 2~7월 6개 구간의 전월비 중 최대·최소값으로, 값이 클수록 월별 변동이 심한(불규칙한) 품목입니다.
A5: [A] 성질별 (수출 금액, 천달러)
A6: 구분 | B6: 품목 | C6: 2026.01 | D6: 2026.02 | E6: 2026.03 | F6: 2026.04 | G6: 2026.05 | H6: 2026.06 | I6: 2026.07 | J6: 7월 전월비 | K6: 7월 전월증감액 | L6: 1월→7월 증감률 | M6: 1월→7월 증감액 | N6: 7개월 누계 | O6: 누계 비중 | P6: 기여도 | Q6: 최대 월증감률 | R6: 최소 월증감률
A7: 대분류 | B7: 1.식료및직접소비재 | C7: ='수출입 실적(성질별)'!D7 -> 1018552 | D7: ='수출입 실적(성질별)'!D28 -> 926368 | E7: ='수출입 실적(성질별)'!D49 -> 1169585 | F7: ='수출입 실적(성질별)'!D70 -> 1206533 | G7: ='수출입 실적(성질별)'!D91 -> 1061105 | H7: ='수출입 실적(성질별)'!D112 -> 1152581 | I7: ='수출입 실적(성질별)'!D133 -> 1081841 | J7: =I7/H7-1 -> -0.061375296 | K7: =I7-H7 -> -70740 | L7: =I7/C7-1 -> 0.062136248 | M7: =I7-C7 -> 63289 | N7: =SUM(C7:I7) -> 7616565 | O7: =N7/'수출입 실적(성질별)'!$D$6 -> 0.012799598 | P7: =IFERROR(M7/('수출입 총괄'!E13-'수출입 총괄'!E7),"-") -> 0.0019111789 | Q7: =MAX(D7/C7-1,E7/D7-1,F7/E7-1,G7/F7-1,H7/G7-1,I7/H7-1) -> 0.26254901 | R7: =MIN(D7/C7-1,E7/D7-1,F7/E7-1,G7/F7-1,H7/G7-1,I7/H7-1) -> -0.12053379
A8: 대분류 | B8: 2.원료및연료 | C8: ='수출입 실적(성질별)'!D8 -> 4654223 | D8: ='수출입 실적(성질별)'!D29 -> 4914885 | E8: ='수출입 실적(성질별)'!D50 -> 7280697 | F8: ='수출입 실적(성질별)'!D71 -> 6331952 | G8: ='수출입 실적(성질별)'!D92 -> 6401394 | H8: ='수출입 실적(성질별)'!D113 -> 6608418 | I8: ='수출입 실적(성질별)'!D134 -> 6896402 | J8: =I8/H8-1 -> 0.043578357 | K8: =I8-H8 -> 287984 | L8: =I8/C8-1 -> 0.48175152 | M8: =I8-C8 -> 2242179 | N8: =SUM(C8:I8) -> 43087971 | O8: =N8/'수출입 실적(성질별)'!$D$6 -> 0.072409111 | P8: =IFERROR(M8/('수출입 총괄'!E13-'수출입 총괄'!E7),"-") -> 0.067708532 | Q8: =MAX(D8/C8-1,E8/D8-1,F8/E8-1,G8/F8-1,H8/G8-1,I8/H8-1) -> 0.48135653 | R8: =MIN(D8/C8-1,E8/D8-1,F8/E8-1,G8/F8-1,H8/G8-1,I8/H8-1) -> -0.13030964
A9: 대분류 | B9: 3.경공업품 | C9: ='수출입 실적(성질별)'!D9 -> 3082056 | D9: ='수출입 실적(성질별)'!D30 -> 3096567 | E9: ='수출입 실적(성질별)'!D51 -> 4111292 | F9: ='수출입 실적(성질별)'!D72 -> 3895477 | G9: ='수출입 실적(성질별)'!D93 -> 3869333 | H9: ='수출입 실적(성질별)'!D114 -> 4060373 | I9: ='수출입 실적(성질별)'!D135 -> 3778039 | J9: =I9/H9-1 -> -0.069534006 | K9: =I9-H9 -> -282334 | L9: =I9/C9-1 -> 0.22581777 | M9: =I9-C9 -> 695983 | N9: =SUM(C9:I9) -> 25893137 | O9: =N9/'수출입 실적(성질별)'!$D$6 -> 0.043513282 | P9: =IFERROR(M9/('수출입 총괄'!E13-'수출입 총괄'!E7),"-") -> 0.02101705 | Q9: =MAX(D9/C9-1,E9/D9-1,F9/E9-1,G9/F9-1,H9/G9-1,I9/H9-1) -> 0.32769354 | R9: =MIN(D9/C9-1,E9/D9-1,F9/E9-1,G9/F9-1,H9/G9-1,I9/H9-1) -> -0.069534006
A10: 중분류 | B10: 가.섬유원료 | C10: ='수출입 실적(성질별)'!D10 -> 81834 | D10: ='수출입 실적(성질별)'!D31 -> 73506 | E10: ='수출입 실적(성질별)'!D52 -> 91453 | F10: ='수출입 실적(성질별)'!D73 -> 90653 | G10: ='수출입 실적(성질별)'!D94 -> 76424 | H10: ='수출입 실적(성질별)'!D115 -> 79180 | I10: ='수출입 실적(성질별)'!D136 -> 77156 | J10: =I10/H10-1 -> -0.025562011 | K10: =I10-H10 -> -2024 | L10: =I10/C10-1 -> -0.057164504 | M10: =I10-C10 -> -4678 | N10: =SUM(C10:I10) -> 570206 | O10: =N10/'수출입 실적(성질별)'!$D$6 -> 0.00095822822 | P10: =IFERROR(M10/('수출입 총괄'!E13-'수출입 총괄'!E7),"-") -> -0.0001412646 | Q10: =MAX(D10/C10-1,E10/D10-1,F10/E10-1,G10/F10-1,H10/G10-1,I10/H10-1) -> 0.24415694 | R10: =MIN(D10/C10-1,E10/D10-1,F10/E10-1,G10/F10-1,H10/G10-1,I10/H10-1) -> -0.15696116
A11: 중분류 | B11: 나.섬유사 | C11: ='수출입 실적(성질별)'!D11 -> 59575 | D11: ='수출입 실적(성질별)'!D32 -> 55539 | E11: ='수출입 실적(성질별)'!D53 -> 66796 | F11: ='수출입 실적(성질별)'!D74 -> 74276 | G11: ='수출입 실적(성질별)'!D95 -> 63203 | H11: ='수출입 실적(성질별)'!D116 -> 65475 | I11: ='수출입 실적(성질별)'!D137 -> 66017 | J11: =I11/H11-1 -> 0.0082779687 | K11: =I11-H11 -> 542 | L11: =I11/C11-1 -> 0.10813261 | M11: =I11-C11 -> 6442 | N11: =SUM(C11:I11) -> 450881 | O11: =N11/'수출입 실적(성질별)'!$D$6 -> 0.00075770318 | P11: =IFERROR(M11/('수출입 총괄'!E13-'수출입 총괄'!E7),"-") -> 0.00019453325 | Q11: =MAX(D11/C11-1,E11/D11-1,F11/E11-1,G11/F11-1,H11/G11-1,I11/H11-1) -> 0.2026864 | R11: =MIN(D11/C11-1,E11/D11-1,F11/E11-1,G11/F11-1,H11/G11-1,I11/H11-1) -> -0.14907911
A12: 중분류 | B12: 다.직물 | C12: ='수출입 실적(성질별)'!D12 -> 275298 | D12: ='수출입 실적(성질별)'!D33 -> 221534 | E12: ='수출입 실적(성질별)'!D54 -> 271710 | F12: ='수출입 실적(성질별)'!D75 -> 311911 | G12: ='수출입 실적(성질별)'!D96 -> 254533 | H12: ='수출입 실적(성질별)'!D117 -> 282353 | I12: ='수출입 실적(성질별)'!D138 -> 298501 | J12: =I12/H12-1 -> 0.057190821 | K12: =I12-H12 -> 16148 | L12: =I12/C12-1 -> 0.084283213 | M12: =I12-C12 -> 23203 | N12: =SUM(C12:I12) -> 1915840 | O12: =N12/'수출입 실적(성질별)'!$D$6 -> 0.0032195592 | P12: =IFERROR(M12/('수출입 총괄'!E13-'수출입 총괄'!E7),"-") -> 0.00070067602 | Q12: =MAX(D12/C12-1,E12/D12-1,F12/E12-1,G12/F12-1,H12/G12-1,I12/H12-1) -> 0.22649345 | R12: =MIN(D12/C12-1,E12/D12-1,F12/E12-1,G12/F12-1,H12/G12-1,I12/H12-1) -> -0.19529383
A13: 중분류 | B13: 라.기타섬유제품 | C13: ='수출입 실적(성질별)'!D13 -> 159996 | D13: ='수출입 실적(성질별)'!D34 -> 142303 | E13: ='수출입 실적(성질별)'!D55 -> 178529 | F13: ='수출입 실적(성질별)'!D76 -> 195708 | G13: ='수출입 실적(성질별)'!D97 -> 156237 | H13: ='수출입 실적(성질별)'!D118 -> 182081 | I13: ='수출입 실적(성질별)'!D139 -> 184656 | J13: =I13/H13-1 -> 0.014142058 | K13: =I13-H13 -> 2575 | L13: =I13/C13-1 -> 0.15412885 | M13: =I13-C13 -> 24660 | N13: =SUM(C13:I13) -> 1199510 | O13: =N13/'수출입 실적(성질별)'!$D$6 -> 0.0020157703 | P13: =IFERROR(M13/('수출입 총괄'!E13-'수출입 총괄'!E7),"-") -> 0.000744674 | Q13: =MAX(D13/C13-1,E13/D13-1,F13/E13-1,G13/F13-1,H13/G13-1,I13/H13-1) -> 0.25456947 | R13: =MIN(D13/C13-1,E13/D13-1,F13/E13-1,G13/F13-1,H13/G13-1,I13/H13-1) -> -0.20168312
A14: 중분류 | B14: 마.의류 | C14: ='수출입 실적(성질별)'!D14 -> 145729 | D14: ='수출입 실적(성질별)'!D35 -> 128724 | E14: ='수출입 실적(성질별)'!D56 -> 178394 | F14: ='수출입 실적(성질별)'!D77 -> 217836 | G14: ='수출입 실적(성질별)'!D98 -> 162835 | H14: ='수출입 실적(성질별)'!D119 -> 191947 | I14: ='수출입 실적(성질별)'!D140 -> 162057 | J14: =I14/H14-1 -> -0.15572007 | K14: =I14-H14 -> -29890 | L14: =I14/C14-1 -> 0.11204359 | M14: =I14-C14 -> 16328 | N14: =SUM(C14:I14) -> 1187522 | O14: =N14/'수출입 실적(성질별)'!$D$6 -> 0.0019956245 | P14: =IFERROR(M14/('수출입 총괄'!E13-'수출입 총괄'!E7),"-") -> 0.00049306719 | Q14: =MAX(D14/C14-1,E14/D14-1,F14/E14-1,G14/F14-1,H14/G14-1,I14/H14-1) -> 0.38586433 | R14: =MIN(D14/C14-1,E14/D14-1,F14/E14-1,G14/F14-1,H14/G14-1,I14/H14-1) -> -0.25248811
A15: 중분류 | B15: 바.목제품 | C15: ='수출입 실적(성질별)'!D15 -> 94526 | D15: ='수출입 실적(성질별)'!D36 -> 80045 | E15: ='수출입 실적(성질별)'!D57 -> 99911 | F15: ='수출입 실적(성질별)'!D78 -> 109054 | G15: ='수출입 실적(성질별)'!D99 -> 87103 | H15: ='수출입 실적(성질별)'!D120 -> 95170 | I15: ='수출입 실적(성질별)'!D141 -> 111673 | J15: =I15/H15-1 -> 0.17340548 | K15: =I15-H15 -> 16503 | L15: =I15/C15-1 -> 0.18139983 | M15: =I15-C15 -> 17147 | N15: =SUM(C15:I15) -> 677482 | O15: =N15/'수출입 실적(성질별)'!$D$6 -> 0.001138505 | P15: =IFERROR(M15/('수출입 총괄'!E13-'수출입 총괄'!E7),"-") -> 0.00051779907 | Q15: =MAX(D15/C15-1,E15/D15-1,F15/E15-1,G15/F15-1,H15/G15-1,I15/H15-1) -> 0.2481854 | R15: =MIN(D15/C15-1,E15/D15-1,F15/E15-1,G15/F15-1,H15/G15-1,I15/H15-1) -> -0.2012856
A16: 중분류 | B16: 사.가죽,고무및신발류 | C16: ='수출입 실적(성질별)'!D16 -> 401578 | D16: ='수출입 실적(성질별)'!D37 -> 344400 | E16: ='수출입 실적(성질별)'!D58 -> 411282 | F16: ='수출입 실적(성질별)'!D79 -> 441930 | G16: ='수출입 실적(성질별)'!D100 -> 448961 | H16: ='수출입 실적(성질별)'!D121 -> 485126 | I16: ='수출입 실적(성질별)'!D142 -> 485169 | J16: =I16/H16-1 -> 8.8636767e-05 | K16: =I16-H16 -> 43 | L16: =I16/C16-1 -> 0.20815632 | M16: =I16-C16 -> 83591 | N16: =SUM(C16:I16) -> 3018446 | O16: =N16/'수출입 실적(성질별)'!$D$6 -> 0.0050724828 | P16: =IFERROR(M16/('수출입 총괄'!E13-'수출입 총괄'!E7),"-") -> 0.0025242516 | Q16: =MAX(D16/C16-1,E16/D16-1,F16/E16-1,G16/F16-1,H16/G16-1,I16/H16-1) -> 0.19419861 | R16: =MIN(D16/C16-1,E16/D16-1,F16/E16-1,G16/F16-1,H16/G16-1,I16/H16-1) -> -0.1423833
A17: 중분류 | B17: 아.귀금속및보석류 | C17: ='수출입 실적(성질별)'!D17 -> 701882 | D17: ='수출입 실적(성질별)'!D38 -> 995740 | E17: ='수출입 실적(성질별)'!D59 -> 1538992 | F17: ='수출입 실적(성질별)'!D80 -> 1162460 | G17: ='수출입 실적(성질별)'!D101 -> 1476718 | H17: ='수출입 실적(성질별)'!D122 -> 1382987 | I17: ='수출입 실적(성질별)'!D143 -> 1011215 | J17: =I17/H17-1 -> -0.26881815 | K17: =I17-H17 -> -371772 | L17: =I17/C17-1 -> 0.44071938 | M17: =I17-C17 -> 309333 | N17: =SUM(C17:I17) -> 8269994 | O17: =N17/'수출입 실적(성질별)'!$D$6 -> 0.013897682 | P17: =IFERROR(M17/('수출입 총괄'!E13-'수출입 총괄'!E7),"-") -> 0.009341129 | Q17: =MAX(D17/C17-1,E17/D17-1,F17/E17-1,G17/F17-1,H17/G17-1,I17/H17-1) -> 0.54557615 | R17: =MIN(D17/C17-1,E17/D17-1,F17/E17-1,G17/F17-1,H17/G17-1,I17/H17-1) -> -0.26881815
A18: 중분류 | B18: 자.기타비금속광물제품 | C18: ='수출입 실적(성질별)'!D18 -> 181453 | D18: ='수출입 실적(성질별)'!D39 -> 159026 | E18: ='수출입 실적(성질별)'!D60 -> 187937 | F18: ='수출입 실적(성질별)'!D81 -> 189118 | G18: ='수출입 실적(성질별)'!D102 -> 180349 | H18: ='수출입 실적(성질별)'!D123 -> 204808 | I18: ='수출입 실적(성질별)'!D144 -> 199569 | J18: =I18/H18-1 -> -0.025580055 | K18: =I18-H18 -> -5239 | L18: =I18/C18-1 -> 0.099838526 | M18: =I18-C18 -> 18116 | N18: =SUM(C18:I18) -> 1302260 | O18: =N18/'수출입 실적(성질별)'!$D$6 -> 0.0021884412 | P18: =IFERROR(M18/('수출입 총괄'!E13-'수출입 총괄'!E7),"-") -> 0.00054706059 | Q18: =MAX(D18/C18-1,E18/D18-1,F18/E18-1,G18/F18-1,H18/G18-1,I18/H18-1) -> 0.18180046 | R18: =MIN(D18/C18-1,E18/D18-1,F18/E18-1,G18/F18-1,H18/G18-1,I18/H18-1) -> -0.12359674
A19: 중분류 | B19: 차.완구,운동용구및악기 | C19: ='수출입 실적(성질별)'!D19 -> 54068 | D19: ='수출입 실적(성질별)'!D40 -> 57507 | E19: ='수출입 실적(성질별)'!D61 -> 63099 | F19: ='수출입 실적(성질별)'!D82 -> 63109 | G19: ='수출입 실적(성질별)'!D103 -> 61502 | H19: ='수출입 실적(성질별)'!D124 -> 71410 | I19: ='수출입 실적(성질별)'!D145 -> 68493 | J19: =I19/H19-1 -> -0.040848621 | K19: =I19-H19 -> -2917 | L19: =I19/C19-1 -> 0.26679367 | M19: =I19-C19 -> 14425 | N19: =SUM(C19:I19) -> 439188 | O19: =N19/'수출입 실적(성질별)'!$D$6 -> 0.00073805315 | P19: =IFERROR(M19/('수출입 총괄'!E13-'수출입 총괄'!E7),"-") -> 0.00043560107 | Q19: =MAX(D19/C19-1,E19/D19-1,F19/E19-1,G19/F19-1,H19/G19-1,I19/H19-1) -> 0.16110045 | R19: =MIN(D19/C19-1,E19/D19-1,F19/E19-1,G19/F19-1,H19/G19-1,I19/H19-1) -> -0.040848621
A20: 중분류 | B20: 카.기타 | C20: ='수출입 실적(성질별)'!D20 -> 926117 | D20: ='수출입 실적(성질별)'!D41 -> 838242 | E20: ='수출입 실적(성질별)'!D62 -> 1023190 | F20: ='수출입 실적(성질별)'!D83 -> 1039421 | G20: ='수출입 실적(성질별)'!D104 -> 901466 | H20: ='수출입 실적(성질별)'!D125 -> 1019834 | I20: ='수출입 실적(성질별)'!D146 -> 1113531 | J20: =I20/H20-1 -> 0.091874756 | K20: =I20-H20 -> 93697 | L20: =I20/C20-1 -> 0.20236536 | M20: =I20-C20 -> 187414 | N20: =SUM(C20:I20) -> 6861801 | O20: =N20/'수출입 실적(성질별)'!$D$6 -> 0.011531221 | P20: =IFERROR(M20/('수출입 총괄'!E13-'수출입 총괄'!E7),"-") -> 0.005659462 | Q20: =MAX(D20/C20-1,E20/D20-1,F20/E20-1,G20/F20-1,H20/G20-1,I20/H20-1) -> 0.22063795 | R20: =MIN(D20/C20-1,E20/D20-1,F20/E20-1,G20/F20-1,H20/G20-1,I20/H20-1) -> -0.13272293
A21: 대분류 | B21: 4.중화학공업품 | C21: ='수출입 실적(성질별)'!D21 -> 57089106 | D21: ='수출입 실적(성질별)'!D42 -> 58704727 | E21: ='수출입 실적(성질별)'!D63 -> 74771554 | F21: ='수출입 실적(성질별)'!D84 -> 74317921 | G21: ='수출입 실적(성질별)'!D105 -> 76244252 | H21: ='수출입 실적(성질별)'!D126 -> 90134786 | I21: ='수출입 실적(성질별)'!D147 -> 87202818 | J21: =I21/H21-1 -> -0.032528707 | K21: =I21-H21 -> -2931968 | L21: =I21/C21-1 -> 0.52748614 | M21: =I21-C21 -> 30113712 | N21: =SUM(C21:I21) -> 518465164 | O21: =N21/'수출입 실적(성질별)'!$D$6 -> 0.87127801 | P21: =IFERROR(M21/('수출입 총괄'!E13-'수출입 총괄'!E7),"-") -> 0.90936327 | Q21: =MAX(D21/C21-1,E21/D21-1,F21/E21-1,G21/F21-1,H21/G21-1,I21/H21-1) -> 0.27368881 | R21: =MIN(D21/C21-1,E21/D21-1,F21/E21-1,G21/F21-1,H21/G21-1,I21/H21-1) -> -0.032528707
A22: 중분류 | B22: 가.화공품 | C22: ='수출입 실적(성질별)'!D22 -> 6584897 | D22: ='수출입 실적(성질별)'!D43 -> 6279361 | E22: ='수출입 실적(성질별)'!D64 -> 7361871 | F22: ='수출입 실적(성질별)'!D85 -> 7717531 | G22: ='수출입 실적(성질별)'!D106 -> 6994558 | H22: ='수출입 실적(성질별)'!D127 -> 7870038 | I22: ='수출입 실적(성질별)'!D148 -> 7980842 | J22: =I22/H22-1 -> 0.01407922 | K22: =I22-H22 -> 110804 | L22: =I22/C22-1 -> 0.21199193 | M22: =I22-C22 -> 1395945 | N22: =SUM(C22:I22) -> 50789098 | O22: =N22/'수출입 실적(성질별)'!$D$6 -> 0.085350815 | P22: =IFERROR(M22/('수출입 총괄'!E13-'수출입 총괄'!E7),"-") -> 0.042154256 | Q22: =MAX(D22/C22-1,E22/D22-1,F22/E22-1,G22/F22-1,H22/G22-1,I22/H22-1) -> 0.17239174 | R22: =MIN(D22/C22-1,E22/D22-1,F22/E22-1,G22/F22-1,H22/G22-1,I22/H22-1) -> -0.093679313
A23: 중분류 | B23: 나.철강제품 | C23: ='수출입 실적(성질별)'!D23 -> 4072186 | D23: ='수출입 실적(성질별)'!D44 -> 3678524 | E23: ='수출입 실적(성질별)'!D65 -> 4107993 | F23: ='수출입 실적(성질별)'!D86 -> 4322292 | G23: ='수출입 실적(성질별)'!D107 -> 4041314 | H23: ='수출입 실적(성질별)'!D128 -> 4351286 | I23: ='수출입 실적(성질별)'!D149 -> 4661963 | J23: =I23/H23-1 -> 0.071398892 | K23: =I23-H23 -> 310677 | L23: =I23/C23-1 -> 0.14483057 | M23: =I23-C23 -> 589777 | N23: =SUM(C23:I23) -> 29235558 | O23: =N23/'수출입 실적(성질별)'!$D$6 -> 0.049130203 | P23: =IFERROR(M23/('수출입 총괄'!E13-'수출입 총괄'!E7),"-") -> 0.017809878 | Q23: =MAX(D23/C23-1,E23/D23-1,F23/E23-1,G23/F23-1,H23/G23-1,I23/H23-1) -> 0.11675036 | R23: =MIN(D23/C23-1,E23/D23-1,F23/E23-1,G23/F23-1,H23/G23-1,I23/H23-1) -> -0.096670928
A24: 중분류 | B24: 다.기계류와정밀기기 | C24: ='수출입 실적(성질별)'!D24 -> 5421604 | D24: ='수출입 실적(성질별)'!D45 -> 4904769 | E24: ='수출입 실적(성질별)'!D66 -> 6033664 | F24: ='수출입 실적(성질별)'!D87 -> 6269944 | G24: ='수출입 실적(성질별)'!D108 -> 5585218 | H24: ='수출입 실적(성질별)'!D129 -> 6547312 | I24: ='수출입 실적(성질별)'!D150 -> 6861427 | J24: =I24/H24-1 -> 0.047976177 | K24: =I24-H24 -> 314115 | L24: =I24/C24-1 -> 0.26557141 | M24: =I24-C24 -> 1439823 | N24: =SUM(C24:I24) -> 41623938 | O24: =N24/'수출입 실적(성질별)'!$D$6 -> 0.069948811 | P24: =IFERROR(M24/('수출입 총괄'!E13-'수출입 총괄'!E7),"-") -> 0.043479268 | Q24: =MAX(D24/C24-1,E24/D24-1,F24/E24-1,G24/F24-1,H24/G24-1,I24/H24-1) -> 0.23016273 | R24: =MIN(D24/C24-1,E24/D24-1,F24/E24-1,G24/F24-1,H24/G24-1,I24/H24-1) -> -0.10920767
A25: 중분류 | B25: 라.전기,전자제품 | C25: ='수출입 실적(성질별)'!D25 -> 28840619 | D25: ='수출입 실적(성질별)'!D46 -> 33394046 | E25: ='수출입 실적(성질별)'!D67 -> 43273534 | F25: ='수출입 실적(성질별)'!D88 -> 42506536 | G25: ='수출입 실적(성질별)'!D109 -> 47618590 | H25: ='수출입 실적(성질별)'!D130 -> 57127600 | I25: ='수출입 실적(성질별)'!D151 -> 53312084 | J25: =I25/H25-1 -> -0.066789363 | K25: =I25-H25 -> -3815516 | L25: =I25/C25-1 -> 0.84850693 | M25: =I25-C25 -> 24471465 | N25: =SUM(C25:I25) -> 306073009 | O25: =N25/'수출입 실적(성질별)'!$D$6 -> 0.5143541 | P25: =IFERROR(M25/('수출입 총괄'!E13-'수출입 총괄'!E7),"-") -> 0.73898068 | Q25: =MAX(D25/C25-1,E25/D25-1,F25/E25-1,G25/F25-1,H25/G25-1,I25/H25-1) -> 0.29584579 | R25: =MIN(D25/C25-1,E25/D25-1,F25/E25-1,G25/F25-1,H25/G25-1,I25/H25-1) -> -0.066789363
A26: 중분류 | B26: 마.수송장비 | C26: ='수출입 실적(성질별)'!D26 -> 10361778 | D26: ='수출입 실적(성질별)'!D47 -> 8608748 | E26: ='수출입 실적(성질별)'!D68 -> 11782023 | F26: ='수출입 실적(성질별)'!D89 -> 11192081 | G26: ='수출입 실적(성질별)'!D110 -> 10090952 | H26: ='수출입 실적(성질별)'!D131 -> 11460161 | I26: ='수출입 실적(성질별)'!D152 -> 11661068 | J26: =I26/H26-1 -> 0.017530906 | K26: =I26-H26 -> 200907 | L26: =I26/C26-1 -> 0.12539257 | M26: =I26-C26 -> 1299290 | N26: =SUM(C26:I26) -> 75156811 | O26: =N26/'수출입 실적(성질별)'!$D$6 -> 0.12630063 | P26: =IFERROR(M26/('수출입 총괄'!E13-'수출입 총괄'!E7),"-") -> 0.039235502 | Q26: =MAX(D26/C26-1,E26/D26-1,F26/E26-1,G26/F26-1,H26/G26-1,I26/H26-1) -> 0.36861051 | R26: =MIN(D26/C26-1,E26/D26-1,F26/E26-1,G26/F26-1,H26/G26-1,I26/H26-1) -> -0.16918235
A27: 중분류 | B27: 바.기타 | C27: ='수출입 실적(성질별)'!D27 -> 1808021 | D27: ='수출입 실적(성질별)'!D48 -> 1839279 | E27: ='수출입 실적(성질별)'!D69 -> 2212470 | F27: ='수출입 실적(성질별)'!D90 -> 2309537 | G27: ='수출입 실적(성질별)'!D111 -> 1913620 | H27: ='수출입 실적(성질별)'!D132 -> 2778389 | I27: ='수출입 실적(성질별)'!D153 -> 2725433 | J27: =I27/H27-1 -> -0.019059966 | K27: =I27-H27 -> -52956 | L27: =I27/C27-1 -> 0.50741225 | M27: =I27-C27 -> 917412 | N27: =SUM(C27:I27) -> 15586749 | O27: =N27/'수출입 실적(성질별)'!$D$6 -> 0.026193451 | P27: =IFERROR(M27/('수출입 총괄'!E13-'수출입 총괄'!E7),"-") -> 0.027703684 | Q27: =MAX(D27/C27-1,E27/D27-1,F27/E27-1,G27/F27-1,H27/G27-1,I27/H27-1) -> 0.45190215 | R27: =MIN(D27/C27-1,E27/D27-1,F27/E27-1,G27/F27-1,H27/G27-1,I27/H27-1) -> -0.171427
B28: 합계(대분류 계) | C28: =C7+C8+C9+C21 -> 65843937 | D28: =D7+D8+D9+D21 -> 67642547 | E28: =E7+E8+E9+E21 -> 87333128 | F28: =F7+F8+F9+F21 -> 85751883 | G28: =G7+G8+G9+G21 -> 87576084 | H28: =H7+H8+H9+H21 -> 101956158 | I28: =I7+I8+I9+I21 -> 98959100 | J28: =I28/H28-1 -> -0.029395556 | K28: =I28-H28 -> -2997058 | L28: =I28/C28-1 -> 0.50293413 | M28: =I28-C28 -> 33115163 | N28: =SUM(C28:I28) -> 595062837 | O28: =N28/'수출입 실적(성질별)'!$D$6 -> 1 | P28: =M28/('수출입 총괄'!E13-'수출입 총괄'!E7) -> 1
A31: [B] 신성질별 (수출 금액, 천달러)
A32: 구분 | B32: 품목 | C32: 2026.01 | D32: 2026.02 | E32: 2026.03 | F32: 2026.04 | G32: 2026.05 | H32: 2026.06 | I32: 2026.07 | J32: 7월 전월비 | K32: 7월 전월증감액 | L32: 1월→7월 증감률 | M32: 1월→7월 증감액 | N32: 7개월 누계 | O32: 누계 비중 | P32: 기여도 | Q32: 최대 월증감률 | R32: 최소 월증감률
A33: 대분류 | B33: 1.소비재 | C33: ='수출입 실적(신성질별)'!D7 -> 7671931 | D33: ='수출입 실적(신성질별)'!D24 -> 6598332 | E33: ='수출입 실적(신성질별)'!D41 -> 8402972 | F33: ='수출입 실적(신성질별)'!D58 -> 8692026 | G33: ='수출입 실적(신성질별)'!D75 -> 7818478 | H33: ='수출입 실적(신성질별)'!D92 -> 8762452 | I33: ='수출입 실적(신성질별)'!D109 -> 8749031 | J33: =I33/H33-1 -> -0.0015316489 | K33: =I33-H33 -> -13421 | L33: =I33/C33-1 -> 0.1403949 | M33: =I33-C33 -> 1077100 | N33: =SUM(C33:I33) -> 56695222 | O33: =N33/'수출입 실적(신성질별)'!$D$6 -> 0.095276026 | P33: =IFERROR(M33/('수출입 총괄'!E13-'수출입 총괄'!E7),"-") -> 0.032525886 | Q33: =MAX(D33/C33-1,E33/D33-1,F33/E33-1,G33/F33-1,H33/G33-1,I33/H33-1) -> 0.27349942 | R33: =MIN(D33/C33-1,E33/D33-1,F33/E33-1,G33/F33-1,H33/G33-1,I33/H33-1) -> -0.13993856
A34: 중분류 | B34: 가.직접소비재 | C34: ='수출입 실적(신성질별)'!D8 -> 974471 | D34: ='수출입 실적(신성질별)'!D25 -> 884224 | E34: ='수출입 실적(신성질별)'!D42 -> 1097568 | F34: ='수출입 실적(신성질별)'!D59 -> 1142829 | G34: ='수출입 실적(신성질별)'!D76 -> 974774 | H34: ='수출입 실적(신성질별)'!D93 -> 1070206 | I34: ='수출입 실적(신성질별)'!D110 -> 1020785 | J34: =I34/H34-1 -> -0.04617896 | K34: =I34-H34 -> -49421 | L34: =I34/C34-1 -> 0.047527325 | M34: =I34-C34 -> 46314 | N34: =SUM(C34:I34) -> 7164857 | O34: =N34/'수출입 실적(신성질별)'!$D$6 -> 0.012040505 | P34: =IFERROR(M34/('수출입 총괄'!E13-'수출입 총괄'!E7),"-") -> 0.0013985739 | Q34: =MAX(D34/C34-1,E34/D34-1,F34/E34-1,G34/F34-1,H34/G34-1,I34/H34-1) -> 0.24127823 | R34: =MIN(D34/C34-1,E34/D34-1,F34/E34-1,G34/F34-1,H34/G34-1,I34/H34-1) -> -0.14705175
A35: 중분류 | B35: 나.내구소비재 | C35: ='수출입 실적(신성질별)'!D9 -> 5005260 | D35: ='수출입 실적(신성질별)'!D26 -> 4228150 | E35: ='수출입 실적(신성질별)'!D43 -> 5399350 | F35: ='수출입 실적(신성질별)'!D60 -> 5383793 | G35: ='수출입 실적(신성질별)'!D77 -> 4926332 | H35: ='수출입 실적(신성질별)'!D94 -> 5522573 | I35: ='수출입 실적(신성질별)'!D111 -> 5560337 | J35: =I35/H35-1 -> 0.0068381169 | K35: =I35-H35 -> 37764 | L35: =I35/C35-1 -> 0.11089873 | M35: =I35-C35 -> 555077 | N35: =SUM(C35:I35) -> 36025795 | O35: =N35/'수출입 실적(신성질별)'!$D$6 -> 0.060541161 | P35: =IFERROR(M35/('수출입 총괄'!E13-'수출입 총괄'!E7),"-") -> 0.01676202 | Q35: =MAX(D35/C35-1,E35/D35-1,F35/E35-1,G35/F35-1,H35/G35-1,I35/H35-1) -> 0.27700058 | R35: =MIN(D35/C35-1,E35/D35-1,F35/E35-1,G35/F35-1,H35/G35-1,I35/H35-1) -> -0.15525867
A36: 중분류 | B36: 다.비내구소비재 | C36: ='수출입 실적(신성질별)'!D10 -> 1688959 | D36: ='수출입 실적(신성질별)'!D27 -> 1482909 | E36: ='수출입 실적(신성질별)'!D44 -> 1902412 | F36: ='수출입 실적(신성질별)'!D61 -> 2162912 | G36: ='수출입 실적(신성질별)'!D78 -> 1914940 | H36: ='수출입 실적(신성질별)'!D95 -> 2166222 | I36: ='수출입 실적(신성질별)'!D112 -> 2163797 | J36: =I36/H36-1 -> -0.0011194605 | K36: =I36-H36 -> -2425 | L36: =I36/C36-1 -> 0.28114241 | M36: =I36-C36 -> 474838 | N36: =SUM(C36:I36) -> 13482151 | O36: =N36/'수출입 실적(신성질별)'!$D$6 -> 0.022656685 | P36: =IFERROR(M36/('수출입 총괄'!E13-'수출입 총괄'!E7),"-") -> 0.014338991 | Q36: =MAX(D36/C36-1,E36/D36-1,F36/E36-1,G36/F36-1,H36/G36-1,I36/H36-1) -> 0.28289194 | R36: =MIN(D36/C36-1,E36/D36-1,F36/E36-1,G36/F36-1,H36/G36-1,I36/H36-1) -> -0.12199822
A37: 중분류 | B37: 라.간이세율적용분 | C37: ='수출입 실적(신성질별)'!D11 -> 3241 | D37: ='수출입 실적(신성질별)'!D28 -> 3050 | E37: ='수출입 실적(신성질별)'!D45 -> 3641 | F37: ='수출입 실적(신성질별)'!D62 -> 2491 | G37: ='수출입 실적(신성질별)'!D79 -> 2432 | H37: ='수출입 실적(신성질별)'!D96 -> 3451 | I37: ='수출입 실적(신성질별)'!D113 -> 4113 | J37: =I37/H37-1 -> 0.19182846 | K37: =I37-H37 -> 662 | L37: =I37/C37-1 -> 0.26905276 | M37: =I37-C37 -> 872 | N37: =SUM(C37:I37) -> 22419 | O37: =N37/'수출입 실적(신성질별)'!$D$6 -> 3.7675013e-05 | P37: =IFERROR(M37/('수출입 총괄'!E13-'수출입 총괄'!E7),"-") -> 2.6332349e-05 | Q37: =MAX(D37/C37-1,E37/D37-1,F37/E37-1,G37/F37-1,H37/G37-1,I37/H37-1) -> 0.41899671 | R37: =MIN(D37/C37-1,E37/D37-1,F37/E37-1,G37/F37-1,H37/G37-1,I37/H37-1) -> -0.31584729
A38: 대분류 | B38: 2.원자재 | C38: ='수출입 실적(신성질별)'!D12 -> 16383039 | D38: ='수출입 실적(신성질별)'!D29 -> 16305033 | E38: ='수출입 실적(신성질별)'!D46 -> 20857696 | F38: ='수출입 실적(신성질별)'!D63 -> 20089347 | G38: ='수출입 실적(신성질별)'!D80 -> 19373529 | H38: ='수출입 실적(신성질별)'!D97 -> 20737509 | I38: ='수출입 실적(신성질별)'!D114 -> 20962899 | J38: =I38/H38-1 -> 0.010868711 | K38: =I38-H38 -> 225390 | L38: =I38/C38-1 -> 0.27954887 | M38: =I38-C38 -> 4579860 | N38: =SUM(C38:I38) -> 134709052 | O38: =N38/'수출입 실적(신성질별)'!$D$6 -> 0.22637786 | P38: =IFERROR(M38/('수출입 총괄'!E13-'수출입 총괄'!E7),"-") -> 0.138301 | Q38: =MAX(D38/C38-1,E38/D38-1,F38/E38-1,G38/F38-1,H38/G38-1,I38/H38-1) -> 0.27921826 | R38: =MIN(D38/C38-1,E38/D38-1,F38/E38-1,G38/F38-1,H38/G38-1,I38/H38-1) -> -0.036837674
A39: 중분류 | B39: 가.동식물성 연·원료 | C39: ='수출입 실적(신성질별)'!D13 -> 417054 | D39: ='수출입 실적(신성질별)'!D30 -> 362450 | E39: ='수출입 실적(신성질별)'!D47 -> 474814 | F39: ='수출입 실적(신성질별)'!D64 -> 483456 | G39: ='수출입 실적(신성질별)'!D81 -> 441975 | H39: ='수출입 실적(신성질별)'!D98 -> 479072 | I39: ='수출입 실적(신성질별)'!D115 -> 483744 | J39: =I39/H39-1 -> 0.0097521876 | K39: =I39-H39 -> 4672 | L39: =I39/C39-1 -> 0.15990735 | M39: =I39-C39 -> 66690 | N39: =SUM(C39:I39) -> 3142565 | O39: =N39/'수출입 실적(신성질별)'!$D$6 -> 0.0052810641 | P39: =IFERROR(M39/('수출입 총괄'!E13-'수출입 총괄'!E7),"-") -> 0.0020138811 | Q39: =MAX(D39/C39-1,E39/D39-1,F39/E39-1,G39/F39-1,H39/G39-1,I39/H39-1) -> 0.31001242 | R39: =MIN(D39/C39-1,E39/D39-1,F39/E39-1,G39/F39-1,H39/G39-1,I39/H39-1) -> -0.13092789
A40: 중분류 | B40: 나.섬유류 | C40: ='수출입 실적(신성질별)'!D14 -> 546437 | D40: ='수출입 실적(신성질별)'!D31 -> 468104 | E40: ='수출입 실적(신성질별)'!D48 -> 574999 | F40: ='수출입 실적(신성질별)'!D65 -> 634737 | G40: ='수출입 실적(신성질별)'!D82 -> 524092 | H40: ='수출입 실적(신성질별)'!D99 -> 577982 | I40: ='수출입 실적(신성질별)'!D116 -> 593803 | J40: =I40/H40-1 -> 0.027372825 | K40: =I40-H40 -> 15821 | L40: =I40/C40-1 -> 0.086681539 | M40: =I40-C40 -> 47366 | N40: =SUM(C40:I40) -> 3920154 | O40: =N40/'수출입 실적(신성질별)'!$D$6 -> 0.0065877984 | P40: =IFERROR(M40/('수출입 총괄'!E13-'수출입 총괄'!E7),"-") -> 0.0014303418 | Q40: =MAX(D40/C40-1,E40/D40-1,F40/E40-1,G40/F40-1,H40/G40-1,I40/H40-1) -> 0.22835737 | R40: =MIN(D40/C40-1,E40/D40-1,F40/E40-1,G40/F40-1,H40/G40-1,I40/H40-1) -> -0.17431629
A41: 중분류 | B41: 다.광산물 | C41: ='수출입 실적(신성질별)'!D15 -> 4965073 | D41: ='수출입 실적(신성질별)'!D32 -> 5569123 | E41: ='수출입 실적(신성질별)'!D49 -> 8406373 | F41: ='수출입 실적(신성질별)'!D66 -> 6735380 | G41: ='수출입 실적(신성질별)'!D83 -> 7223537 | H41: ='수출입 실적(신성질별)'!D100 -> 7332370 | I41: ='수출입 실적(신성질별)'!D117 -> 7297526 | J41: =I41/H41-1 -> -0.0047520788 | K41: =I41-H41 -> -34844 | L41: =I41/C41-1 -> 0.46977215 | M41: =I41-C41 -> 2332453 | N41: =SUM(C41:I41) -> 47529382 | O41: =N41/'수출입 실적(신성질별)'!$D$6 -> 0.079872879 | P41: =IFERROR(M41/('수출입 총괄'!E13-'수출입 총괄'!E7),"-") -> 0.070434594 | Q41: =MAX(D41/C41-1,E41/D41-1,F41/E41-1,G41/F41-1,H41/G41-1,I41/H41-1) -> 0.50946083 | R41: =MIN(D41/C41-1,E41/D41-1,F41/E41-1,G41/F41-1,H41/G41-1,I41/H41-1) -> -0.19877693
A42: 중분류 | B42: 라.철강 및 금속제품 | C42: ='수출입 실적(신성질별)'!D16 -> 3502462 | D42: ='수출입 실적(신성질별)'!D33 -> 3259378 | E42: ='수출입 실적(신성질별)'!D50 -> 3576759 | F42: ='수출입 실적(신성질별)'!D67 -> 4020760 | G42: ='수출입 실적(신성질별)'!D84 -> 3767266 | H42: ='수출입 실적(신성질별)'!D101 -> 4036403 | I42: ='수출입 실적(신성질별)'!D118 -> 4137091 | J42: =I42/H42-1 -> 0.024944982 | K42: =I42-H42 -> 100688 | L42: =I42/C42-1 -> 0.18119511 | M42: =I42-C42 -> 634629 | N42: =SUM(C42:I42) -> 26300119 | O42: =N42/'수출입 실적(신성질별)'!$D$6 -> 0.044197213 | P42: =IFERROR(M42/('수출입 총괄'!E13-'수출입 총괄'!E7),"-") -> 0.019164303 | Q42: =MAX(D42/C42-1,E42/D42-1,F42/E42-1,G42/F42-1,H42/G42-1,I42/H42-1) -> 0.12413501 | R42: =MIN(D42/C42-1,E42/D42-1,F42/E42-1,G42/F42-1,H42/G42-1,I42/H42-1) -> -0.069403751
A43: 중분류 | B43: 마.화학공업제품 | C43: ='수출입 실적(신성질별)'!D17 -> 6944019 | D43: ='수출입 실적(신성질별)'!D34 -> 6639199 | E43: ='수출입 실적(신성질별)'!D51 -> 7799370 | F43: ='수출입 실적(신성질별)'!D68 -> 8205105 | G43: ='수출입 실적(신성질별)'!D85 -> 7407806 | H43: ='수출입 실적(신성질별)'!D102 -> 8299470 | I43: ='수출입 실적(신성질별)'!D119 -> 8437709 | J43: =I43/H43-1 -> 0.016656365 | K43: =I43-H43 -> 138239 | L43: =I43/C43-1 -> 0.21510454 | M43: =I43-C43 -> 1493690 | N43: =SUM(C43:I43) -> 53732678 | O43: =N43/'수출입 실적(신성질별)'!$D$6 -> 0.090297486 | P43: =IFERROR(M43/('수출입 총괄'!E13-'수출입 총괄'!E7),"-") -> 0.045105925 | Q43: =MAX(D43/C43-1,E43/D43-1,F43/E43-1,G43/F43-1,H43/G43-1,I43/H43-1) -> 0.17474563 | R43: =MIN(D43/C43-1,E43/D43-1,F43/E43-1,G43/F43-1,H43/G43-1,I43/H43-1) -> -0.09717109
...

Sheet 분석4_그래프
A1: ④ 그래프 — 분석2·분석3 데이터를 그대로 참조
A2: 아래 보조 데이터표는 그래프 전용이며 모두 수식(분석2·분석3 참조)입니다. 원본 값이 바뀌면 표와 그래프가 함께 갱신됩니다.
A4: 보조표 1. 2026.01 = 100 지수 (물량·금액·단가의 방향 비교)
A5: 지표 | B5: 2026.01 | C5: 2026.02 | D5: 2026.03 | E5: 2026.04 | F5: 2026.05 | G5: 2026.06 | H5: 2026.07
A6: 수출 금액 지수 | B6: =분석2_월별추이!E6/분석2_월별추이!$E$6*100 -> 100 | C6: =분석2_월별추이!E7/분석2_월별추이!$E$6*100 -> 102.73163 | D6: =분석2_월별추이!E8/분석2_월별추이!$E$6*100 -> 132.63655 | E6: =분석2_월별추이!E9/분석2_월별추이!$E$6*100 -> 130.23505 | F6: =분석2_월별추이!E10/분석2_월별추이!$E$6*100 -> 133.00554 | G6: =분석2_월별추이!E11/분석2_월별추이!$E$6*100 -> 154.84517 | H6: =분석2_월별추이!E12/분석2_월별추이!$E$6*100 -> 150.29341
A7: 수출 중량 지수 | B7: =분석2_월별추이!D6/분석2_월별추이!$D$6*100 -> 100 | C7: =분석2_월별추이!D7/분석2_월별추이!$D$6*100 -> 93.199322 | D7: =분석2_월별추이!D8/분석2_월별추이!$D$6*100 -> 96.656526 | E7: =분석2_월별추이!D9/분석2_월별추이!$D$6*100 -> 86.103639 | F7: =분석2_월별추이!D10/분석2_월별추이!$D$6*100 -> 81.180129 | G7: =분석2_월별추이!D11/분석2_월별추이!$D$6*100 -> 93.715501 | H7: =분석2_월별추이!D12/분석2_월별추이!$D$6*100 -> 105.50021
A8: 수출 단가 지수 | B8: =분석2_월별추이!M6/분석2_월별추이!$M$6*100 -> 100 | C8: =분석2_월별추이!M7/분석2_월별추이!$M$6*100 -> 110.22787 | D8: =분석2_월별추이!M8/분석2_월별추이!$M$6*100 -> 137.22462 | E8: =분석2_월별추이!M9/분석2_월별추이!$M$6*100 -> 151.25383 | F8: =분석2_월별추이!M10/분석2_월별추이!$M$6*100 -> 163.84002 | G8: =분석2_월별추이!M11/분석2_월별추이!$M$6*100 -> 165.22899 | H8: =분석2_월별추이!M12/분석2_월별추이!$M$6*100 -> 142.45792
A9: 수입 금액 지수 | B9: =분석2_월별추이!F6/분석2_월별추이!$F$6*100 -> 100 | C9: =분석2_월별추이!F7/분석2_월별추이!$F$6*100 -> 90.883375 | D9: =분석2_월별추이!F8/분석2_월별추이!$F$6*100 -> 106.31739 | E9: =분석2_월별추이!F9/분석2_월별추이!$F$6*100 -> 108.68243 | F9: =분석2_월별추이!F10/분석2_월별추이!$F$6*100 -> 106.30847 | G9: =분석2_월별추이!F11/분석2_월별추이!$F$6*100 -> 115.58904 | H9: =분석2_월별추이!F12/분석2_월별추이!$F$6*100 -> 119.99179
A11: 보조표 2. 신성질별 중분류 — 1월 대비 7월 증감액 (천달러, 증감액 순)
A12: 품목 | B12: 1월→7월 증감액 | C12: 1월→7월 증감률
A13: 라.IT부품 | B13: =분석3_품목별증감!M49 -> 20644951 | C13: =분석3_품목별증감!L49 -> 0.9334602
A14: 다.IT제품 | B14: =분석3_품목별증감!M48 -> 3235033 | C14: =분석3_품목별증감!L48 -> 0.67429533
A15: 다.광산물 | B15: =분석3_품목별증감!M41 -> 2332453 | C15: =분석3_품목별증감!L41 -> 0.46977215
A16: 나.기계류 | B16: =분석3_품목별증감!M47 -> 2241912 | C16: =분석3_품목별증감!L47 -> 0.27354474
A17: 마.화학공업제품 | B17: =분석3_품목별증감!M43 -> 1493690 | C17: =분석3_품목별증감!L43 -> 0.21510454
A18: 가.수송장비 | B18: =분석3_품목별증감!M46 -> 1336305 | C18: =분석3_품목별증감!L46 -> 0.20007696
A19: 라.철강 및 금속제품 | B19: =분석3_품목별증감!M42 -> 634629 | C19: =분석3_품목별증감!L42 -> 0.18119511
A20: 나.내구소비재 | B20: =분석3_품목별증감!M35 -> 555077 | C20: =분석3_품목별증감!L35 -> 0.11089873
A21: 다.비내구소비재 | B21: =분석3_품목별증감!M36 -> 474838 | C21: =분석3_품목별증감!L36 -> 0.28114241
A22: 가.동식물성 연·원료 | B22: =분석3_품목별증감!M39 -> 66690 | C22: =분석3_품목별증감!L39 -> 0.15990735
A23: 나.섬유류 | B23: =분석3_품목별증감!M40 -> 47366 | C23: =분석3_품목별증감!L40 -> 0.086681539
A24: 가.직접소비재 | B24: =분석3_품목별증감!M34 -> 46314 | C24: =분석3_품목별증감!L34 -> 0.047527325
A25: 바.기타 원자재 | B25: =분석3_품목별증감!M44 -> 5032 | C25: =분석3_품목별증감!L44 -> 0.6294721
A26: 라.간이세율적용분 | B26: =분석3_품목별증감!M37 -> 872 | C26: =분석3_품목별증감!L37 -> 0.26905276
A27: 정렬 순서는 파일 작성 시점의 값 기준으로 고정되어 있습니다(수식 자동 재정렬 아님).

Sheet 분석5_전년대비(입력)
A1: ⑤ 전년 동월/동기 대비 분석 (전년도 값 입력 시 자동 계산)
A2: ★ 중요 : 업로드하신 원본 파일에는 2026.01~07 자료만 들어 있고 2025년 자료가 없습니다. 따라서 전년 대비(YoY) 수치는 파일만으로는 산출할 수 없어, 값을 임의로 만들어 넣지 않았습니다.
A3: 노란색 셀에 관세청 수출입무역통계의 2025년 동월 값을 붙여넣으면 전년동월비가 자동으로 계산되고, 아래 요약도 자동 갱신됩니다.
A5: [1] 월별 총괄 — 전년 동월 대비 (노란색 = 입력 셀, 단위: 천달러)
A6: 기간 | B6: 2026년 수출 | C6: 2025년 수출(입력) | D6: 전년동월비 | E6: 2026년 수입 | F6: 2025년 수입(입력) | G6: 전년동월비 | H6: 2026년 수지 | I6: 2025년 수지(자동) | J6: 수지 증감
A7: 2026.01 | B7: =분석2_월별추이!E6 -> 65843937 | D7: =IF(C7="","",B7/C7-1) | E7: =분석2_월별추이!F6 -> 57143469 | G7: =IF(F7="","",E7/F7-1) | H7: =B7-E7 -> 8700468 | I7: =IF(OR(C7="",F7=""),"",C7-F7) | J7: =IF(I7="","",H7-I7)
A8: 2026.02 | B8: =분석2_월별추이!E7 -> 67642547 | D8: =IF(C8="","",B8/C8-1) | E8: =분석2_월별추이!F7 -> 51933913 | G8: =IF(F8="","",E8/F8-1) | H8: =B8-E8 -> 15708634 | I8: =IF(OR(C8="",F8=""),"",C8-F8) | J8: =IF(I8="","",H8-I8)
A9: 2026.03 | B9: =분석2_월별추이!E8 -> 87333128 | D9: =IF(C9="","",B9/C9-1) | E9: =분석2_월별추이!F8 -> 60753446 | G9: =IF(F9="","",E9/F9-1) | H9: =B9-E9 -> 26579682 | I9: =IF(OR(C9="",F9=""),"",C9-F9) | J9: =IF(I9="","",H9-I9)
A10: 2026.04 | B10: =분석2_월별추이!E9 -> 85751883 | D10: =IF(C10="","",B10/C10-1) | E10: =분석2_월별추이!F9 -> 62104908 | G10: =IF(F10="","",E10/F10-1) | H10: =B10-E10 -> 23646975 | I10: =IF(OR(C10="",F10=""),"",C10-F10) | J10: =IF(I10="","",H10-I10)
A11: 2026.05 | B11: =분석2_월별추이!E10 -> 87576083 | D11: =IF(C11="","",B11/C11-1) | E11: =분석2_월별추이!F10 -> 60748350 | G11: =IF(F11="","",E11/F11-1) | H11: =B11-E11 -> 26827733 | I11: =IF(OR(C11="",F11=""),"",C11-F11) | J11: =IF(I11="","",H11-I11)
A12: 2026.06 | B12: =분석2_월별추이!E11 -> 101956159 | D12: =IF(C12="","",B12/C12-1) | E12: =분석2_월별추이!F11 -> 66051586 | G12: =IF(F12="","",E12/F12-1) | H12: =B12-E12 -> 35904573 | I12: =IF(OR(C12="",F12=""),"",C12-F12) | J12: =IF(I12="","",H12-I12)
A13: 2026.07 | B13: =분석2_월별추이!E12 -> 98959099 | D13: =IF(C13="","",B13/C13-1) | E13: =분석2_월별추이!F12 -> 68567473 | G13: =IF(F13="","",E13/F13-1) | H13: =B13-E13 -> 30391626 | I13: =IF(OR(C13="",F13=""),"",C13-F13) | J13: =IF(I13="","",H13-I13)
A14: 7개월 누계 | B14: =SUM(B7:B13) -> 595062836 | C14: =SUM(C7:C13) -> 0 | D14: =IF(C14=0,"",B14/C14-1) | E14: =SUM(E7:E13) -> 427303145 | F14: =SUM(F7:F13) -> 0 | G14: =IF(F14=0,"",E14/F14-1) | H14: =SUM(H7:H13) -> 167759691 | I14: =SUM(I7:I13) -> 0 | J14: =IF(I14=0,"",H14-I14)
A16: [2] 대분류 7개월 누계 — 전년 동기 대비 (노란색 = 입력 셀, 단위: 천달러)
A17: 구분 | B17: 품목 | C17: 2026년 누계 | D17: 2025년 누계(입력) | E17: 전년동기비 | F17: 증감액
A18: 성질별 | B18: 1.식료및직접소비재 | C18: =분석3_품목별증감!N7 -> 7616565 | E18: =IF(D18="","",C18/D18-1) | F18: =IF(D18="","",C18-D18)
A19: 성질별 | B19: 2.원료및연료 | C19: =분석3_품목별증감!N8 -> 43087971 | E19: =IF(D19="","",C19/D19-1) | F19: =IF(D19="","",C19-D19)
A20: 성질별 | B20: 3.경공업품 | C20: =분석3_품목별증감!N9 -> 25893137 | E20: =IF(D20="","",C20/D20-1) | F20: =IF(D20="","",C20-D20)
A21: 성질별 | B21: 4.중화학공업품 | C21: =분석3_품목별증감!N21 -> 518465164 | E21: =IF(D21="","",C21/D21-1) | F21: =IF(D21="","",C21-D21)
A22: 신성질별 | B22: 1.소비재 | C22: =분석3_품목별증감!N33 -> 56695222 | E22: =IF(D22="","",C22/D22-1) | F22: =IF(D22="","",C22-D22)
A23: 신성질별 | B23: 2.원자재 | C23: =분석3_품목별증감!N38 -> 134709052 | E23: =IF(D23="","",C23/D23-1) | F23: =IF(D23="","",C23-D23)
A24: 신성질별 | B24: 3.자본재 | C24: =분석3_품목별증감!N45 -> 403658562 | E24: =IF(D24="","",C24/D24-1) | F24: =IF(D24="","",C24-D24)
A25: 출처 표기 예시 : 관세청 수출입무역통계(unipass.customs.go.kr) — 성질별/신성질별 수출입실적, 2025.01~07, 수리일 기준. 값을 입력할 때 통계 기준(수리일)과 중량단위(톤)를 원본과 동일하게 맞추셔야 비교가 성립합니다.
A27: [참고] 전년 자료가 없어도 확인 가능한 대안 지표
A28: 연초 대비(1월→7월) 증감률 | B28: 분석3_품목별증감 L열 — 계절성은 걷어내지 못하지만 기간 내 추세는 볼 수 있습니다.
A29: 조업일수 보정 일평균 | B29: 분석2_월별추이 K·L열 — 2월(19일)처럼 영업일이 짧은 달의 착시를 제거합니다.
A30: 단가(금액/중량) | B30: 분석2_월별추이 M·N열 — 물량 효과와 가격 효과를 분리합니다.
A31: 구성비 변화 | B31: 분석3_품목별증감 O열 — 어떤 품목이 포트폴리오에서 커졌는지 봅니다.

Sheet 분석6_해설
A1: ⑥ 분석 결과 해설 — 숫자가 말하는 것
A2: 아래 [핵심 수치] 표는 모두 수식이며 원본이 바뀌면 자동 갱신됩니다. 본문 서술의 숫자는 2026.01~07 자료 기준입니다.
A4: [핵심 수치] (단위: 천달러, 톤)
A5: 지표 | B5: 2026.01 | C5: 2026.07 | D5: 기간 최고 | E5: 7개월 누계 | F5: 1월→7월 변화
A6: 수출 금액 | B6: =분석2_월별추이!E6 -> 65843937 | C6: =분석2_월별추이!E12 -> 98959099 | D6: =MAX(분석2_월별추이!E6:E12) -> 101956159 | E6: =분석2_월별추이!E13 -> 595062836 | F6: =C6/B6-1 -> 0.50293411
A7: 수입 금액 | B7: =분석2_월별추이!F6 -> 57143469 | C7: =분석2_월별추이!F12 -> 68567473 | D7: =MAX(분석2_월별추이!F6:F12) -> 68567473 | E7: =분석2_월별추이!F13 -> 427303145 | F7: =C7/B7-1 -> 0.19991793
A8: 무역수지 | B8: =분석2_월별추이!G6 -> 8700468 | C8: =분석2_월별추이!G12 -> 30391625 | D8: =MAX(분석2_월별추이!G6:G12) -> 35904573 | E8: =분석2_월별추이!G13 -> 167759690 | F8: =C8/B8-1 -> 2.4931023
A9: 수출 중량(톤) | B9: =분석2_월별추이!D6 -> 16739948 | C9: =분석2_월별추이!D12 -> 17660681 | D9: =MAX(분석2_월별추이!D6:D12) -> 17660681 | E9: =분석2_월별추이!D13 -> 1.0987354e+08 | F9: =C9/B9-1 -> 0.055002137
A10: 수출 단가(천$/톤) | B10: =분석2_월별추이!M6 -> 3.9333418 | C10: =분석2_월별추이!M12 -> 5.603357 | D10: =MAX(분석2_월별추이!M6:M12) -> 6.4990209 | E10: =분석2_월별추이!M13 -> 5.4158885 | F10: =C10/B10-1 -> 0.42457921
A11: 수입 단가(천$/톤) | B11: =분석2_월별추이!N6 -> 1.142524 | C11: =분석2_월별추이!N12 -> 1.3406702 | D11: =MAX(분석2_월별추이!N6:N12) -> 1.5291253 | E11: =분석2_월별추이!N13 -> 1.3615186 | F11: =C11/B11-1 -> 0.17342852
A12: 순상품교역조건 | B12: =분석2_월별추이!O6 -> 3.4426778 | C12: =분석2_월별추이!O12 -> 4.1795193 | D12: =MAX(분석2_월별추이!O6:O12) -> 4.2987027 | E12: =분석2_월별추이!O13 -> 3.9778293 | F12: =C12/B12-1 -> 0.21403153
A13: 일평균 수출 | B13: =분석2_월별추이!K6 -> 2801869.7 | C13: =분석2_월별추이!K12 -> 4123295.8 | D13: =MAX(분석2_월별추이!K6:K12) -> 4531384.8 | E13: =분석2_월별추이!K13 -> 3802318.4 | F13: =C13/B13-1 -> 0.47162298
A15: [증가 기여도 상위] 1월 대비 7월 수출 증가분을 누가 만들었나
A16: 품목(신성질별 중분류) | B16: 1월 | C16: 7월 | D16: 증감액 | E16: 증감률 | F16: 전체 증가분 대비 기여도
A17: 라.IT부품 | B17: =분석3_품목별증감!C49 -> 22116584 | C17: =분석3_품목별증감!I49 -> 42761535 | D17: =분석3_품목별증감!M49 -> 20644951 | E17: =분석3_품목별증감!L49 -> 0.9334602 | F17: =분석3_품목별증감!P49 -> 0.62342896
A18: 다.IT제품 | B18: =분석3_품목별증감!C48 -> 4797650 | C18: =분석3_품목별증감!I48 -> 8032683 | D18: =분석3_품목별증감!M48 -> 3235033 | E18: =분석3_품목별증감!L48 -> 0.67429533 | F18: =분석3_품목별증감!P48 -> 0.097690387
A19: 다.광산물 | B19: =분석3_품목별증감!C41 -> 4965073 | C19: =분석3_품목별증감!I41 -> 7297526 | D19: =분석3_품목별증감!M41 -> 2332453 | E19: =분석3_품목별증감!L41 -> 0.46977215 | F19: =분석3_품목별증감!P41 -> 0.070434594
A20: 나.기계류 | B20: =분석3_품목별증감!C47 -> 8195778 | C20: =분석3_품목별증감!I47 -> 10437690 | D20: =분석3_품목별증감!M47 -> 2241912 | E20: =분석3_품목별증감!L47 -> 0.27354474 | F20: =분석3_품목별증감!P47 -> 0.067700469
A21: 마.화학공업제품 | B21: =분석3_품목별증감!C43 -> 6944019 | C21: =분석3_품목별증감!I43 -> 8437709 | D21: =분석3_품목별증감!M43 -> 1493690 | E21: =분석3_품목별증감!L43 -> 0.21510454 | F21: =분석3_품목별증감!P43 -> 0.045105925
A22: 가.수송장비 | B22: =분석3_품목별증감!C46 -> 6678955 | C22: =분석3_품목별증감!I46 -> 8015260 | D22: =분석3_품목별증감!M46 -> 1336305 | E22: =분석3_품목별증감!L46 -> 0.20007696 | F22: =분석3_품목별증감!P46 -> 0.040353268
A24: 1. 무엇을 어떻게 분석했나
A25: · 원본 3개 시트(수출입 총괄 / 성질별 / 신성질별)는 2026.01~07, 수리일 기준, 단위는 건·톤(TON)·천달러입니다.
A26: · 성질별·신성질별 시트는 검색조건이 [성질명: 수출]이므로 수출 실적만 담고 있습니다. 수입은 총괄 시트에만 총액으로 존재하며, 그래서 품목별 수입·품목별 무역수지는 이 파일만으로는 계산할 수 없습니다.
A27: · 원본 3개 시트는 값 하나도 수정하지 않았고, 분석1~분석6 시트를 새로 추가해 모두 수식으로 원본을 참조하도록 만들었습니다.
A29: 2. 합계 정합성 — 결론: 데이터는 신뢰할 수 있습니다
A30: · 검증 항목(분석1 시트): ① 총괄 총계행 vs 월별 합계(8개 지표) ② 무역수지 항등식(수출−수입=수지) ③ 성질별 대분류 4개 합 vs 총괄 수출 ④ 성질별 중분류 합 vs 대분류 ⑤ 신성질별 대분류 3개 합 vs 총괄 수출 ⑥ 신성질별 중분류 합 vs 대분류 ⑦ 3개 시트 총계 교차검증.
A31: · 모든 항목이 일치했습니다. 관측된 최대 편차는 금액 ±2천달러, 중량 ±0.2톤입니다. 7개월 수출 총액이 5,950.6억 달러이므로 총액의 1억분의 1에도 못 미치는 차이이며, 원본이 소수 첫째자리(중량)·정수(금액)로 반올림되어 제공되기 때문에 생기는 반올림 누적 오차입니다. 데이터 오류가 아닙니다.
A32: · 의미: 성질별과 신성질별은 같은 원자료를 다른 기준으로 나눈 두 개의 뷰이고, 어느 쪽으로 집계해도 총괄과 같은 총액이 나옵니다. 따라서 두 분류를 교차해 해석해도 무방합니다(예: 신성질별 IT부품 급증 = 성질별 전기·전자제품 급증).
A33: · 유일한 눈에 띄는 점: 2026.07의 무역수지는 수출−수입 계산값과 원본 표기값이 1천달러 차이 납니다. 역시 반올림 차이입니다.
A35: 3. 총괄 추이 — 수출 확대와 흑자 폭 확대, 그러나 7월은 실질 둔화
A36: · 수출은 1월 658.4억 달러에서 6월 1,019.6억 달러까지 올라간 뒤 7월 989.6억 달러로 꺾였습니다(전월비 −2.9%). 7개월 누계는 5,950.6억 달러입니다.
A37: · 무역수지는 7개월 내내 흑자였고 1월 87.0억 달러에서 6월 359.0억 달러로 4배 이상 커졌다가 7월 303.9억 달러로 줄었습니다. 누계 흑자는 1,677.6억 달러입니다.
... A66: 작성: 원본 파일(2026.01~07 수출입 실적)만을 근거로 산출. 외부 자료를 추가로 참조하지 않았으며, 전년 비교치는 자료 부재로 산출하지 않았습니다.
